Workbook
Name _aop182: #REF!
Name Adresa: #REF!
Name Beg_Bal: '[1]Amortization Table'!$C$19:$C$378
Name Cum_Int: #REF!
Name Data: #REF!
Name dd: Scheduled_Payment+Extra_Payment
Name Direktor: #REF!
Name Djelatnost: #REF!
Name e: #REF!
Name End_Bal: '[1]Amortization Table'!$I$19:$I$378
Name Extra_Pay: '[1]Amortization Table'!$E$19:$E$378
Name ff: #REF!
Name ffd: #REF!
Name Firma: #REF!
Name Full_Print: '[1]Amortization Table'!$A$1:$J$378
Name gg: #REF!
Name Graf: #REF!
Name Header_Row: ROW('[1]Amortization Table'!$18:$18)
Name Int: '[1]Amortization Table'!$H$19:$H$378
Name Interest_Rate: '[1]Amortization Table'!$D$7
Name jj: #REF!
Name l: #REF!
Name Last_Row: IF('4 Projection 3Y'!Values_Entered,[0]!Header_Row+'4 Projection 3Y'!Number_of_Payments,[0]!Header_Row)
Name Last_Row: IF(Values_Entered,Header_Row+Number_of_Payments,Header_Row)
Name Loan_Amount: '[1]Amortization Table'!$D$6
Name Loan_Start: '[1]Amortization Table'!$D$10
Name Loan_Years: '[1]Amortization Table'!$D$8
Name Lookups17: #REF!
Name Lookups18: #REF!
Name nakož: #REF!
Name Num_Pmt_Per_Year: '[1]Amortization Table'!$D$9
Name Number_of_Payments: MATCH(0.01,[0]!End_Bal,-1)+1
Name Number_of_Payments: MATCH(0.01,End_Bal,-1)+1
Name Obaveze: #REF!
Name Pay_Date: #REF!
Name Pay_Num: '[1]Amortization Table'!$A$19:$A$378
Name Payment_Date: DATE(YEAR([2]!Loan_Start),MONTH([2]!Loan_Start)+Payment_Number,DAY([2]!Loan_Start))
Name Payment_Date: DATE(YEAR(Loan_Start),MONTH(Loan_Start)+Payment_Number,DAY(Loan_Start))
Name Princ: '[1]Amortization Table'!$G$19:$G$378
Name Print_Area_Reset: OFFSET([0]!Full_Print,0,0,'4 Projection 3Y'!Last_Row)
Name Print_Area_Reset: OFFSET(Full_Print,0,0,Last_Row)
Name Sched_Pay: '[1]Amortization Table'!$D$19:$D$378
Name Scheduled_Extra_Payments: '[1]Amortization Table'!$D$11
Name Scheduled_Interest_Rate: #REF!
Name Scheduled_Monthly_Payment: '[1]Amortization Table'!$H$6
Name Sjedište: #REF!
Name Sredstva: #REF!
Name ss: OFFSET(Full_Print,0,0,Last_Row)
Name Total_Interest: #REF!
Name Total_Pay: '[1]Amortization Table'!$F$19:$F$378
Name Total_Payment: Scheduled_Payment+Extra_Payment
Name Total_Payment: Scheduled_Payment+Extra_Payment
Name Values_Entered: IF([0]!Loan_Amount*[0]!Interest_Rate*[0]!Loan_Years*[0]!Loan_Start>0,1,0)
Name Values_Entered: IF(Loan_Amount*Interest_Rate*Loan_Years*Loan_Start>0,1,0)
Name VećinskiVlasnik: #REF!

Sheet 1 Business Model Canvas
C2: Business Model Canvas --> | D2: https://carab.us/ibph0
C4: Instructions: | D4: Please use the link above to learn more about the Business Model Canvas (BMC). Then, for your project, give a brief description of the BMC for your business idea using the form below.
C6: Value proposition: | D6: "The first intelligent sleep system that delivers clinical-grade insights through effortless comfort, eliminating the trade-off between data and rest."
C8: Customer segments: | D8: Primary – Urban professionals aged 28-55 in Dubai/Abu Dhabi with household income >AED 30,000/month Secondary – Health-conscious individuals, biohackers, quantified-self enthusiasts Tertiary – Corporate wellness programs for employee performance Geographic – UAE (Year 1-2), KSA expansion (Year 2-3) Psychographic – Tech-savvy early adopters who value data-driven wellness and quality design
C10: Channels: | D10: Direct-to-Consumer (D2C) – Official website with e-commerce platform Premium Retail – "SomniTech Sleep Bars" in Virgin Megastore, The White Company, and other luxury bedding retailers Corporate – B2B partnerships with HR departments for employee wellness programs Social Media – Instagram, LinkedIn, and TikTok content marketing Influencer – Partnerships with sleep experts, wellness coaches, and tech reviewers
C12: Customer relationships: | D12: 30-Night Sleep Transformation Trial – Risk-free home trial with full refund SomniApp – Ongoing engagement through sleep scores, trends, and coaching Community Building – Social media community of "SomniSleepers" sharing experiences Customer Support – Dedicated WhatsApp and email support Loyalty Program – Discounts on future products and accessories Sleep Clinic Partnerships – Third-party validation and referrals
C14: Revenue streams: | D14: Product Sales – SomniTech pillow (AED 899 per unit) - two variants: Contour (medium-firm) and Adaptive (adjustable loft) B2B Corporate Sales – Bulk discounts for corporate wellness programs Future Accessories – Replacement covers, travel battery packs KSA Expansion – Additional revenue from Saudi market from Month 18 onward Projected Year 1 Revenue – ~AED 3.5M, Year 3: ~AED 22.7M
C16: Key resources: | D16: Intellectual Property – Patents pending for SilentSense analytics system and ActiveTemp thermal management Proprietary Technology – Sensor fusion algorithms, sleep data interpretation engine Founding Team – Cross-functional expertise (CEO/CMO, CTO, COO) Manufacturing Partnership – Contract manufacturer with quality assurance Data Assets – Anonymized sleep data for continuous algorithm improvement Brand – "SomniTech" trademark and reputation for quality
C18: Key partners: | D18: Manufacturing Partner – Electronics assembly and pillow fabrication (Asia-based) Retail Partners – Virgin Megastore, The White Company, and other UAE premium retailers Sleep Clinics – Validation studies and clinical credibility Logistics Providers – Fulfillment and delivery partners (like Aramex, Fetchr) Influencer Network – Sleep experts, wellness coaches, tech reviewers Corporate HR Departments – Employee wellness program partners Dubai SME / Government – Potential R&D grants and funding support
C20: Key activities: | D20: R&D – Continuous improvement of SilentSense sensors and ActiveTemp technology Software Development – SomniApp updates, AI sleep coaching algorithms Marketing and Sales – Digital campaigns, influencer partnerships, retail activations Supply Chain Management – Quality control, inventory management, logistics Customer Support – Post-purchase assistance, warranty management Data Analysis – Sleep pattern research and algorithm refinement IP Management – Patent filings and protection
C22: Cost structure: | D22: Initial Investment (AED 4.5M) – R&D, tooling, initial inventory, software, patents, salaries Direct Materials (~AED 81/unit avg.) – Sensors, ActiveTemp modules, foam, fabric Direct Labor (~AED 30/unit avg.) – Assembly and quality control staff Manufacturing Overhead (~AED 25/unit avg.) – Rent, utilities, indirect labor Administrative Costs (~AED 64K/month avg.) – Management salaries, office rent, admin staff Selling Costs (~AED 97K/month avg.) – Marketing, social media, influencer payments, shipping R&D Investment – Continuous product development (~AED 600K over 3 years) KSA Market Entry – ~AED 250K in Year 2

Sheet 2 Investment
A1: Description
A2: R&D & Prototyping | B2: 200000
A3: Tooling & Production Moulds | B3: 150000
A4: Software Development (SomniApp) | B4: 120000
A5: Patent Filing (UAE Provisional) | B5: 50000
A6: Office & Lab Space (6 months) | B6: 60000
A7: Salaries (Founders + 2 staff - 6 months) | B7: 120000
A8: Marketing & Brand Launch | B8: 30000
A9: Regulatory & Compliance | B9: 20000
A10: Other
A11: Other
A12: Other
A13: Other
A14: Other
A15: Other
A16: Other
A17: Other
A18: Other
A19: Other
A20: Total investment | B20: =SUM(B2:B19) -> 750000

Sheet 3 Product financial details
A1: Product/service 1 | B1: 1 | C1: 2 | D1: 3 | E1: 4 | F1: 5 | G1: 6 | H1: 7 | I1: 8 | J1: 9 | K1: 10 | L1: 11 | M1: 12 | N1: 13 | O1: 14 | P1: 15 | Q1: 16 | R1: 17 | S1: 18 | T1: 19 | U1: 20 | V1: 21 | W1: 22 | X1: 23 | Y1: 24 | Z1: 25 | AA1: 26 | AB1: 27 | AC1: 28 | AD1: 29 | AE1: 30 | AF1: 31 | AG1: 32 | AH1: 33 | AI1: 34 | AJ1: 35 | AK1: 36 | AM1: Average | AN1: %
A2: Quantity | B2: 0 | C2: 0 | D2: 50 | E2: 60 | F2: 70 | G2: 80 | H2: 90 | I2: 100 | J2: 110 | K2: 120 | L2: 130 | M2: 140 | N2: 150 | O2: 160 | P2: 170 | Q2: 180 | R2: 190 | S2: 200 | T2: 210 | U2: 220 | V2: 230 | W2: 240 | X2: 250 | Y2: 260 | Z2: 270 | AA2: 280 | AB2: 290 | AC2: 300 | AD2: 310 | AE2: 320 | AF2: 330 | AG2: 340 | AH2: 350 | AI2: 360 | AJ2: 370 | AK2: 380 | AM2: =AVERAGE(D2:AK2) -> 215
A3: Selling price (per unit) | B3: 899 | C3: 899 | D3: 899 | E3: 899 | F3: 899 | G3: 899 | H3: 899 | I3: 899 | J3: 899 | K3: 899 | L3: 899 | M3: 899 | N3: 899 | O3: 899 | P3: 899 | Q3: 899 | R3: 899 | S3: 899 | T3: 899 | U3: 899 | V3: 899 | W3: 899 | X3: 899 | Y3: 899 | Z3: 899 | AA3: 899 | AB3: 899 | AC3: 899 | AD3: 899 | AE3: 899 | AF3: 899 | AG3: 899 | AH3: 899 | AI3: 899 | AJ3: 899 | AK3: 899 | AM3: =AVERAGE(D3:AK3) -> 899
A4: Direct materials (per unit) | B4: 125 | C4: 125 | D4: 120 | E4: 118 | F4: 115 | G4: 112 | H4: 110 | I4: 108 | J4: 105 | K4: 103 | L4: 100 | M4: 98 | N4: 95 | O4: 93 | P4: 90 | Q4: 88 | R4: 85 | S4: 83 | T4: 80 | U4: 78 | V4: 75 | W4: 73 | X4: 70 | Y4: 68 | Z4: 65 | AA4: 63 | AB4: 60 | AC4: 58 | AD4: 55 | AE4: 53 | AF4: 50 | AG4: 48 | AH4: 45 | AI4: 43 | AJ4: 40 | AK4: 38 | AM4: =AVERAGE(D4:AK4) -> 78.970588 | AN4: =AM4/$AM$3 -> 0.087842701
A5: Direct labor (per unit) | B5: =IF(B2=0,0,B13/B2) -> 0 | C5: =IF(C2=0,0,C13/C2) -> 0 | D5: =IF(D2=0,0,D13/D2) -> 140 | E5: =IF(E2=0,0,E13/E2) -> 116.66667 | F5: =IF(F2=0,0,F13/F2) -> 100 | G5: =IF(G2=0,0,G13/G2) -> 87.5 | H5: =IF(H2=0,0,H13/H2) -> 77.777778 | I5: =IF(I2=0,0,I13/I2) -> 70 | ... AK5: =IF(AK2=0,0,AK13/AK2) -> 42.105263 | AM5: =AVERAGE(D5:AK5) -> 54.084271 | AN5: =AM5/$AM$3 -> 0.060160479
A6: Overhead manufacturing costs (per unit) | B6: =IF(B2=0,0,B23/B2) -> 0 | C6: =IF(C2=0,0,C23/C2) -> 0 | D6: =IF(D2=0,0,D23/D2) -> 320 | E6: =IF(E2=0,0,E23/E2) -> 266.66667 | F6: =IF(F2=0,0,F23/F2) -> 232.85714 | G6: =IF(G2=0,0,G23/G2) -> 207.5 | H6: =IF(H2=0,0,H23/H2) -> 184.44444 | I6: =IF(I2=0,0,I23/I2) -> 168 | ... AK6: =IF(AK2=0,0,AK23/AK2) -> 72.368421 | AM6: =AVERAGE(D6:AK6) -> 118.62691 | AN6: =AM6/$AM$3 -> 0.13195429
A7: Product costs (per unit) | B7: =SUM(B4:B6) -> 125 | C7: =SUM(C4:C6) -> 125 | D7: =SUM(D4:D6) -> 580 | E7: =SUM(E4:E6) -> 501.33333 | F7: =SUM(F4:F6) -> 447.85714 | G7: =SUM(G4:G6) -> 407 | H7: =SUM(H4:H6) -> 372.22222 | I7: =SUM(I4:I6) -> 346 | ... AK7: =SUM(AK4:AK6) -> 152.47368 | AM7: =AVERAGE(D7:AK7) -> 251.68177 | AN7: =AM7/$AM$3 -> 0.27995747
A8: Gross margin (per unit) | B8: =B3-B7 -> 774 | C8: =C3-C7 -> 774 | D8: =D3-D7 -> 319 | E8: =E3-E7 -> 397.66667 | F8: =F3-F7 -> 451.14286 | G8: =G3-G7 -> 492 | H8: =H3-H7 -> 526.77778 | I8: =I3-I7 -> 553 | ... AK8: =AK3-AK7 -> 746.52632 | AM8: =AVERAGE(D8:AK8) -> 647.31823 | AN8: =AM8/$AM$3 -> 0.72004253
A11: Number of employees | B11: 0 | C11: 0 | D11: 1 | E11: 1 | F11: 1 | G11: 1 | H11: 1 | I11: 1 | J11: 1 | K11: 1 | L11: 1 | M11: 1 | N11: 1 | O11: 1 | P11: 1 | Q11: 1 | R11: 1 | S11: 1 | T11: 1 | U11: 1 | V11: 1 | W11: 1 | X11: 1 | Y11: 2 | Z11: 2 | AA11: 2 | AB11: 2 | AC11: 2 | AD11: 2 | AE11: 2 | AF11: 2 | AG11: 2 | AH11: 2 | AI11: 2 | AJ11: 2 | AK11: 2 | AM11: =AVERAGE(D11:AK11) -> 1.3823529
A12: Average salary | B12: 7000 | C12: 7000 | D12: 7000 | E12: 7000 | F12: 7000 | G12: 7000 | H12: 7000 | I12: 7000 | J12: 7000 | K12: 7000 | L12: 7000 | M12: 7000 | N12: 7000 | O12: 7000 | P12: 7000 | Q12: 7000 | R12: 7000 | S12: 7000 | T12: 7000 | U12: 7000 | V12: 7000 | W12: 7000 | X12: 7000 | Y12: 7500 | Z12: 7500 | AA12: 7500 | AB12: 7500 | AC12: 7500 | AD12: 7500 | AE12: 7500 | AF12: 7500 | AG12: 7500 | AH12: 7500 | AI12: 8000 | AJ12: 8000 | AK12: 8000 | AM12: =AVERAGE(D12:AK12) -> 7235.2941
A13: Direct labor | B13: =B11*B12 -> 0 | C13: =C11*C12 -> 0 | D13: =D11*D12 -> 7000 | E13: =E11*E12 -> 7000 | F13: =F11*F12 -> 7000 | G13: =G11*G12 -> 7000 | H13: =H11*H12 -> 7000 | I13: =I11*I12 -> 7000 | ... AK13: =AK11*AK12 -> 16000 | AM13: =AVERAGE(D13:AK13) -> 10147.059
A15: Rent (per year) | B15: 60000 | C15: 60000 | D15: 60000 | E15: 60000 | F15: 60000 | G15: 60000 | H15: 60000 | I15: 60000 | J15: 60000 | K15: 60000 | L15: 60000 | M15: 60000 | N15: 60000 | O15: 60000 | P15: 60000 | Q15: 60000 | R15: 60000 | S15: 60000 | T15: 60000 | U15: 60000 | V15: 60000 | W15: 60000 | X15: 60000 | Y15: 72000 | Z15: 72000 | AA15: 72000 | AB15: 72000 | AC15: 72000 | AD15: 72000 | AE15: 72000 | AF15: 72000 | AG15: 72000 | AH15: 72000 | AI15: 84000 | AJ15: 84000 | AK15: 84000 | AM15: =AVERAGE(D15:AK15) -> 65647.059
A16: Rent (per month) | B16: =B15/12 -> 5000 | C16: =C15/12 -> 5000 | D16: =D15/12 -> 5000 | E16: =E15/12 -> 5000 | F16: =F15/12 -> 5000 | G16: =G15/12 -> 5000 | H16: =H15/12 -> 5000 | I16: =I15/12 -> 5000 | ... AK16: =AK15/12 -> 7000 | AM16: =AVERAGE(D16:AK16) -> 5470.5882
A17: Number of employees | B17: 0 | C17: 0 | D17: 1 | E17: 1 | F17: 1 | G17: 1 | H17: 1 | I17: 1 | J17: 1 | K17: 1 | L17: 1 | M17: 1 | N17: 1 | O17: 1 | P17: 1 | Q17: 1 | R17: 1 | S17: 1 | T17: 1 | U17: 1 | V17: 1 | W17: 1 | X17: 1 | Y17: 1 | Z17: 1 | AA17: 1 | AB17: 1 | AC17: 1 | AD17: 1 | AE17: 1 | AF17: 1 | AG17: 1 | AH17: 1 | AI17: 1 | AJ17: 1 | AK17: 1 | AM17: =AVERAGE(D17:AK17) -> 1
A18: Average salary (per month) | B18: 4500 | C18: 4500 | D18: 4500 | E18: 4500 | F18: 4500 | G18: 4500 | H18: 4500 | I18: 4500 | J18: 4500 | K18: 4500 | L18: 4500 | M18: 4500 | N18: 4500 | O18: 4500 | P18: 4500 | Q18: 4500 | R18: 4500 | S18: 4500 | T18: 4500 | U18: 4500 | V18: 4500 | W18: 4500 | X18: 4500 | Y18: 4500 | Z18: 4500 | AA18: 4500 | AB18: 4500 | AC18: 4500 | AD18: 4500 | AE18: 4500 | AF18: 4500 | AG18: 4500 | AH18: 4500 | AI18: 4500 | AJ18: 4500 | AK18: 4500 | AM18: =AVERAGE(D18:AK18) -> 4500
A19: Indirect labor (per month) | B19: =B17*B18 -> 0 | C19: =C17*C18 -> 0 | D19: =D17*D18 -> 4500 | E19: =E17*E18 -> 4500 | F19: =F17*F18 -> 4500 | G19: =G17*G18 -> 4500 | H19: =H17*H18 -> 4500 | I19: =I17*I18 -> 4500 | ... AK19: =AK17*AK18 -> 4500 | AM19: =AVERAGE(D19:AK19) -> 4500
A20: Indirect materials (per month) | B20: 1500 | C20: 1500 | D20: 1500 | E20: 1500 | F20: 1800 | G20: 1800 | H20: 1800 | I20: 2000 | J20: 2000 | K20: 2200 | L20: 2200 | M20: 2200 | N20: 2500 | O20: 2500 | P20: 2500 | Q20: 2800 | R20: 2800 | S20: 2800 | T20: 3000 | U20: 3000 | V20: 3200 | W20: 3200 | X20: 3200 | Y20: 3500 | Z20: 3500 | AA20: 3500 | AB20: 3800 | AC20: 3800 | AD20: 3800 | AE20: 4000 | AF20: 4000 | AG20: 4000 | AH20: 4200 | AI20: 4500 | AJ20: 4500 | AK20: 4500 | AM20: =AVERAGE(D20:AK20) -> 3002.9412
A21: Utilities (per month) | B21: 3000 | C21: 3000 | D21: 3500 | E21: 3500 | F21: 3500 | G21: 3800 | H21: 3800 | I21: 3800 | J21: 4000 | K21: 4000 | L21: 4000 | M21: 4200 | N21: 4200 | O21: 4200 | P21: 4500 | Q21: 4500 | R21: 4500 | S21: 4800 | T21: 4800 | U21: 4800 | V21: 5000 | W21: 5000 | X21: 5000 | Y21: 5500 | Z21: 5500 | AA21: 5500 | AB21: 6000 | AC21: 6000 | AD21: 6000 | AE21: 6500 | AF21: 6500 | AG21: 6500 | AH21: 7000 | AI21: 7500 | AJ21: 7500 | AK21: 7500 | AM21: =AVERAGE(D21:AK21) -> 5085.2941
A22: Other overhead costs (per month) | B22: 1500 | C22: 1500 | D22: 1500 | E22: 1500 | F22: 1500 | G22: 1500 | H22: 1500 | I22: 1500 | J22: 1800 | K22: 1800 | L22: 1800 | M22: 1800 | N22: 2000 | O22: 2000 | P22: 2000 | Q22: 2200 | R22: 2200 | S22: 2200 | T22: 2500 | U22: 2500 | V22: 2500 | W22: 2800 | X22: 2800 | Y22: 3000 | Z22: 3000 | AA22: 3000 | AB22: 3200 | AC22: 3200 | AD22: 3200 | AE22: 3500 | AF22: 3500 | AG22: 3500 | AH22: 3800 | AI22: 4000 | AJ22: 4000 | AK22: 4000 | AM22: =AVERAGE(D22:AK22) -> 2552.9412
A23: Overhead manufacturing costs (per month) | B23: =B16+B19+B20+B21+B22 -> 11000 | C23: =C16+C19+C20+C21+C22 -> 11000 | D23: =D16+D19+D20+D21+D22 -> 16000 | E23: =E16+E19+E20+E21+E22 -> 16000 | F23: =F16+F19+F20+F21+F22 -> 16300 | G23: =G16+G19+G20+G21+G22 -> 16600 | H23: =H16+H19+H20+H21+H22 -> 16600 | I23: =I16+I19+I20+I21+I22 -> 16800 | ... AK23: =AK16+AK19+AK20+AK21+AK22 -> 27500 | AM23: =AVERAGE(D23:AK23) -> 20611.765
A25: Number of employees | B25: 2 | C25: 2 | D25: 2 | E25: 2 | F25: 2 | G25: 2 | H25: 2 | I25: 2 | J25: 2 | K25: 2 | L25: 2 | M25: 2 | N25: 2 | O25: 2 | P25: 2 | Q25: 2 | R25: 2 | S25: 2 | T25: 2 | U25: 2 | V25: 2 | W25: 2 | X25: 2 | Y25: 2 | Z25: 2 | AA25: 2 | AB25: 2 | AC25: 2 | AD25: 2 | AE25: 2 | AF25: 2 | AG25: 2 | AH25: 2 | AI25: 2 | AJ25: 2 | AK25: 2 | AM25: =AVERAGE(D25:AK25) -> 2
A26: Average salary | B26: 6000 | C26: 6000 | D26: 6000 | E26: 6000 | F26: 6000 | G26: 6000 | H26: 6000 | I26: 6000 | J26: 6000 | K26: 6000 | L26: 6000 | M26: 6000 | N26: 6000 | O26: 6000 | P26: 6000 | Q26: 6000 | R26: 6000 | S26: 6000 | T26: 6000 | U26: 6000 | V26: 6000 | W26: 6000 | X26: 6000 | Y26: 6000 | Z26: 6000 | AA26: 6000 | AB26: 6000 | AC26: 6000 | AD26: 6000 | AE26: 6000 | AF26: 6000 | AG26: 6000 | AH26: 6000 | AI26: 6000 | AJ26: 6000 | AK26: 6000 | AM26: =AVERAGE(D26:AK26) -> 6000
A27: Admin labor (per month) | B27: =B25*B26 -> 12000 | C27: =C25*C26 -> 12000 | D27: =D25*D26 -> 12000 | E27: =E25*E26 -> 12000 | F27: =F25*F26 -> 12000 | G27: =G25*G26 -> 12000 | H27: =H25*H26 -> 12000 | I27: =I25*I26 -> 12000 | ... AK27: =AK25*AK26 -> 12000 | AM27: =AVERAGE(D27:AK27) -> 12000
A28: Administrative rent per year | B28: 24000 | C28: 24000 | D28: 24000 | E28: 24000 | F28: 24000 | G28: 24000 | H28: 24000 | I28: 24000 | J28: 24000 | K28: 24000 | L28: 24000 | M28: 24000 | N28: 24000 | O28: 24000 | P28: 24000 | Q28: 24000 | R28: 24000 | S28: 24000 | T28: 24000 | U28: 24000 | V28: 24000 | W28: 24000 | X28: 24000 | Y28: 24000 | Z28: 24000 | AA28: 24000 | AB28: 24000 | AC28: 24000 | AD28: 24000 | AE28: 24000 | AF28: 24000 | AG28: 24000 | AH28: 24000 | AI28: 24000 | AJ28: 24000 | AK28: 24000 | AM28: =AVERAGE(D28:AK28) -> 24000
A29: Administrative rent (per month) | B29: =B28/12 -> 2000 | C29: =C28/12 -> 2000 | D29: =D28/12 -> 2000 | E29: =E28/12 -> 2000 | F29: =F28/12 -> 2000 | G29: =G28/12 -> 2000 | H29: =H28/12 -> 2000 | I29: =I28/12 -> 2000 | ... AK29: =AK28/12 -> 2000 | AM29: =AVERAGE(D29:AK29) -> 2000
A30: Other admin costs (per month) | B30: 1500 | C30: 1500 | D30: 1500 | E30: 1500 | F30: 1500 | G30: 1500 | H30: 1500 | I30: 1500 | J30: 1500 | K30: 1500 | L30: 1500 | M30: 1500 | N30: 1500 | O30: 1500 | P30: 1500 | Q30: 1500 | R30: 1500 | S30: 1500 | T30: 1500 | U30: 1500 | V30: 1500 | W30: 1500 | X30: 1500 | Y30: 1500 | Z30: 1500 | AA30: 1500 | AB30: 1500 | AC30: 1500 | AD30: 1500 | AE30: 1500 | AF30: 1500 | AG30: 1500 | AH30: 1500 | AI30: 1500 | AJ30: 1500 | AK30: 1500 | AM30: =AVERAGE(D30:AK30) -> 1500
A31: Administrative costs (per month) | B31: =B27+B29+B30 -> 15500 | C31: =C27+C29+C30 -> 15500 | D31: =D27+D29+D30 -> 15500 | E31: =E27+E29+E30 -> 15500 | F31: =F27+F29+F30 -> 15500 | G31: =G27+G29+G30 -> 15500 | H31: =H27+H29+H30 -> 15500 | I31: =I27+I29+I30 -> 15500 | ... AK31: =AK27+AK29+AK30 -> 15500 | AM31: =AVERAGE(D31:AK31) -> 15500
A33: Marketing (per month) | B33: 10000 | C33: 8000 | D33: 6000 | E33: 6000 | F33: 6000 | G33: 6000 | H33: 6000 | I33: 6000 | J33: 6000 | K33: 6000 | L33: 6000 | M33: 6000 | N33: 8000 | O33: 8000 | P33: 8000 | Q33: 8000 | R33: 8000 | S33: 8000 | T33: 8000 | U33: 8000 | V33: 8000 | W33: 8000 | X33: 8000 | Y33: 10000 | Z33: 10000 | AA33: 10000 | AB33: 10000 | AC33: 10000 | AD33: 10000 | AE33: 10000 | AF33: 10000 | AG33: 10000 | AH33: 10000 | AI33: 12000 | AJ33: 12000 | AK33: 12000 | AM33: =AVERAGE(D33:AK33) -> 8352.9412
A34: Social Media (per month) | B34: 3000 | C34: 3000 | D34: 3000 | E34: 3000 | F34: 3000 | G34: 3000 | H34: 3000 | I34: 3000 | J34: 3000 | K34: 3000 | L34: 3000 | M34: 3000 | N34: 3500 | O34: 3500 | P34: 3500 | Q34: 3500 | R34: 3500 | S34: 3500 | T34: 3500 | U34: 3500 | V34: 3500 | W34: 3500 | X34: 3500 | Y34: 4000 | Z34: 4000 | AA34: 4000 | AB34: 4000 | AC34: 4000 | AD34: 4000 | AE34: 4000 | AF34: 4000 | AG34: 4000 | AH34: 4000 | AI34: 5000 | AJ34: 5000 | AK34: 5000 | AM34: =AVERAGE(D34:AK34) -> 3632.3529
A35: Promo materials (per month) | B35: 1500 | C35: 1500 | D35: 1500 | E35: 1500 | F35: 1500 | G35: 1500 | H35: 1500 | I35: 1500 | J35: 1500 | K35: 1500 | L35: 1500 | M35: 1500 | N35: 1500 | O35: 1500 | P35: 1500 | Q35: 1500 | R35: 1500 | S35: 1500 | T35: 1500 | U35: 1500 | V35: 1500 | W35: 1500 | X35: 1500 | Y35: 2000 | Z35: 2000 | AA35: 2000 | AB35: 2000 | AC35: 2000 | AD35: 2000 | AE35: 2000 | AF35: 2000 | AG35: 2000 | AH35: 2000 | AI35: 2500 | AJ35: 2500 | AK35: 2500 | AM35: =AVERAGE(D35:AK35) -> 1735.2941
A36: Cost per delivery | B36: 20 | C36: 20 | D36: 19 | E36: 18 | F36: 17 | G36: 16 | H36: 15 | I36: 14 | J36: 13 | K36: 12 | L36: 11 | M36: 10 | N36: 10 | O36: 9 | P36: 9 | Q36: 8 | R36: 8 | S36: 8 | T36: 7 | U36: 7 | V36: 7 | W36: 6 | X36: 6 | Y36: 6 | Z36: 5 | AA36: 5 | AB36: 5 | AC36: 5 | AD36: 5 | AE36: 4 | AF36: 4 | AG36: 4 | AH36: 4 | AI36: 4 | AJ36: 3 | AK36: 3 | AM36: =AVERAGE(D36:AK36) -> 8.4411765
A37: Delivery (per month) | B37: ='3 Product financial details'!B2*B36 -> 0 | C37: ='3 Product financial details'!C2*C36 -> 0 | D37: ='3 Product financial details'!D2*D36 -> 950 | E37: ='3 Product financial details'!E2*E36 -> 1080 | F37: ='3 Product financial details'!F2*F36 -> 1190 | G37: ='3 Product financial details'!G2*G36 -> 1280 | H37: ='3 Product financial details'!H2*H36 -> 1350 | I37: ='3 Product financial details'!I2*I36 -> 1400 | ... AK37: ='3 Product financial details'!AK2*AK36 -> 1140 | AM37: =AVERAGE(D37:AK37) -> 1394.1176
A38: Selling costs (per month) | B38: =SUM(B33:B37) -> 14520 | C38: =SUM(C33:C37) -> 12520 | D38: =SUM(D33:D37) -> 11469 | E38: =SUM(E33:E37) -> 11598 | F38: =SUM(F33:F37) -> 11707 | G38: =SUM(G33:G37) -> 11796 | H38: =SUM(H33:H37) -> 11865 | I38: =SUM(I33:I37) -> 11914 | ... AK38: =SUM(AK33:AK37) -> 20643 | AM38: =AVERAGE(D38:AK38) -> 15123.147
A45: Selling price | B45: =AVERAGE(B3:AK3) -> 899
A46: Direct materials | B46: =-AVERAGE(B4:AK4) -> -81.527778
A47: Direct labor | B47: =-AVERAGE(D5:AK5) -> -54.084271
A48: Overhead manufacturing costs | B48: =-AVERAGE(D6:AK6) -> -118.62691
A50: Gross margin | B50: =-SUM(B45:B48) -> -644.76104

Sheet 4 Projection 3Y
C1: Y1 | O1: Y2 | AA1: Y3
A2: # | B2: Opis | C2: 1 | D2: 2 | E2: 3 | F2: 4 | G2: 5 | H2: 6 | I2: 7 | J2: 8 | K2: 9 | L2: 10 | M2: 11 | N2: 12 | O2: 13 | P2: 14 | Q2: 15 | R2: 16 | S2: 17 | T2: 18 | U2: 19 | V2: 20 | W2: 21 | X2: 22 | Y2: 23 | Z2: 24 | AA2: 25 | AB2: 26 | AC2: 27 | AD2: 28 | AE2: 29 | AF2: 30 | AG2: 31 | AH2: 32 | AI2: 33 | AJ2: 34 | AK2: 35 | AL2: 36 | AN2: TOTAL
A3: 1 | B3: Self | C3: 200000 | AN3: =SUM(C3:AL3) -> 200000
A4: =A3+1 -> 2 | B4: FFF | C4: 150000 | AN4: =SUM(C4:AL4) -> 150000
A5: =A4+1 -> 3 | B5: Angels | C5: 300000 | AN5: =SUM(C5:AL5) -> 300000
A6: =A5+1 -> 4 | B6: Crowd | AN6: =SUM(C6:AL6) -> 0
A7: =A6+1 -> 5 | B7: Angel Groups & Syndicates | C7: 100000 | AN7: =SUM(C7:AL7) -> 100000
A8: =A7+1 -> 6 | B8: VC | AN8: =SUM(C8:AL8) -> 0
A9: =A8+1 -> 7 | B9: Venture bank | AN9: =SUM(C9:AL9) -> 0
A10: =A9+1 -> 8 | B10: Growth Equity | AN10: =SUM(C10:AL10) -> 0
A11: =A10+1 -> 9 | B11: Strategic investors | T11: 500000 | AN11: =SUM(C11:AL11) -> 500000
A12: =A11+1 -> 10 | B12: Private equity | AN12: =SUM(C12:AL12) -> 0
A13: =A12+1 -> 11 | B13: Public investors | AN13: =SUM(C13:AL13) -> 0
A14: =A13+1 -> 12 | B14: Advance payments | AN14: =SUM(C14:AL14) -> 0
A15: =A14+1 -> 13 | B15: Sale inflows | C15: ='3 Product financial details'!B2*'3 Product financial details'!B3 -> 0 | D15: ='3 Product financial details'!C2*'3 Product financial details'!C3 -> 0 | E15: ='3 Product financial details'!D2*'3 Product financial details'!D3 -> 44950 | F15: ='3 Product financial details'!E2*'3 Product financial details'!E3 -> 53940 | G15: ='3 Product financial details'!F2*'3 Product financial details'!F3 -> 62930 | H15: ='3 Product financial details'!G2*'3 Product financial details'!G3 -> 71920 | I15: ='3 Product financial details'!H2*'3 Product financial details'!H3 -> 80910 | J15: ='3 Product financial details'!I2*'3 Product financial details'!I3 -> 89900 | ... AL15: ='3 Product financial details'!AK2*'3 Product financial details'!AK3 -> 341620 | AN15: =SUM(C15:AL15) -> 6571690
A16: =A15+1 -> 14 | B16: Loans | N16: 150000 | AN16: =SUM(C16:AL16) -> 150000
A17: ΣI | B17: Total inflows | C17: =SUM(C3:C16) -> 750000 | D17: =SUM(D3:D16) -> 0 | E17: =SUM(E3:E16) -> 44950 | F17: =SUM(F3:F16) -> 53940 | G17: =SUM(G3:G16) -> 62930 | H17: =SUM(H3:H16) -> 71920 | I17: =SUM(I3:I16) -> 80910 | J17: =SUM(J3:J16) -> 89900 | ... AL17: =SUM(AL3:AL16) -> 341620 | AN17: =SUM(AN3:AN16) -> 7971690
A18: 5 | B18: Investment | C18: ='2 Investment'!B20 -> 750000 | AN18: =SUM(C18:AL18) -> 750000
A19: =A18+1 -> 6 | B19: Direct materials | C19: ='3 Product financial details'!B2*'3 Product financial details'!B4 -> 0 | D19: ='3 Product financial details'!C2*'3 Product financial details'!C4 -> 0 | E19: ='3 Product financial details'!D2*'3 Product financial details'!D4 -> 6000 | F19: ='3 Product financial details'!E2*'3 Product financial details'!E4 -> 7080 | G19: ='3 Product financial details'!F2*'3 Product financial details'!F4 -> 8050 | H19: ='3 Product financial details'!G2*'3 Product financial details'!G4 -> 8960 | I19: ='3 Product financial details'!H2*'3 Product financial details'!H4 -> 9900 | J19: ='3 Product financial details'!I2*'3 Product financial details'!I4 -> 10800 | ... AL19: ='3 Product financial details'!AK2*'3 Product financial details'!AK4 -> 14440 | AN19: =SUM(C19:AL19) -> 495640
A20: =A19+1 -> 7 | B20: Direct labor | C20: ='3 Product financial details'!B13 -> 0 | D20: ='3 Product financial details'!C13 -> 0 | E20: ='3 Product financial details'!D13 -> 7000 | F20: ='3 Product financial details'!E13 -> 7000 | G20: ='3 Product financial details'!F13 -> 7000 | H20: ='3 Product financial details'!G13 -> 7000 | I20: ='3 Product financial details'!H13 -> 7000 | J20: ='3 Product financial details'!I13 -> 7000 | ... AL20: ='3 Product financial details'!AK13 -> 16000 | AN20: =SUM(C20:AL20) -> 345000
A21: =A20+1 -> 8 | B21: Overhead manufacturing costs | C21: ='3 Product financial details'!B23 -> 11000 | D21: ='3 Product financial details'!C23 -> 11000 | E21: ='3 Product financial details'!D23 -> 16000 | F21: ='3 Product financial details'!E23 -> 16000 | G21: ='3 Product financial details'!F23 -> 16300 | H21: ='3 Product financial details'!G23 -> 16600 | I21: ='3 Product financial details'!H23 -> 16600 | J21: ='3 Product financial details'!I23 -> 16800 | ... AL21: ='3 Product financial details'!AK23 -> 27500 | AN21: =SUM(C21:AL21) -> 722800
A22: =A21+1 -> 9 | B22: Administrative costs | C22: ='3 Product financial details'!B31 -> 15500 | D22: ='3 Product financial details'!C31 -> 15500 | E22: ='3 Product financial details'!D31 -> 15500 | F22: ='3 Product financial details'!E31 -> 15500 | G22: ='3 Product financial details'!F31 -> 15500 | H22: ='3 Product financial details'!G31 -> 15500 | I22: ='3 Product financial details'!H31 -> 15500 | J22: ='3 Product financial details'!I31 -> 15500 | ... AL22: ='3 Product financial details'!AK31 -> 15500 | AN22: =SUM(C22:AL22) -> 558000
A23: =A22+1 -> 10 | B23: Selling costs | C23: ='3 Product financial details'!B38 -> 14520 | D23: ='3 Product financial details'!C38 -> 12520 | E23: ='3 Product financial details'!D38 -> 11469 | F23: ='3 Product financial details'!E38 -> 11598 | G23: ='3 Product financial details'!F38 -> 11707 | H23: ='3 Product financial details'!G38 -> 11796 | I23: ='3 Product financial details'!H38 -> 11865 | J23: ='3 Product financial details'!I38 -> 11914 | ... AL23: ='3 Product financial details'!AK38 -> 20643 | AN23: =SUM(C23:AL23) -> 541227
A24: =A23+1 -> 11 | B24: Loan repayent | AN24: =SUM(C24:AL24) -> 0
A25: =A24+1 -> 12 | B25: Interest | AN25: =SUM(C25:AL25) -> 0
A26: ΣII | B26: Total outflows | C26: =SUM(C18:C25) -> 791020 | D26: =SUM(D18:D25) -> 39020 | E26: =SUM(E18:E25) -> 55969 | F26: =SUM(F18:F25) -> 57178 | G26: =SUM(G18:G25) -> 58557 | H26: =SUM(H18:H25) -> 59856 | I26: =SUM(I18:I25) -> 60865 | J26: =SUM(J18:J25) -> 62014 | ... AL26: =SUM(AL18:AL25) -> 94083 | AN26: =SUM(AN18:AN25) -> 3412667
A27: III | B27: Total inflows - Total outflows | C27: =C17-C26 -> -41020 | D27: =D17-D26 -> -39020 | E27: =E17-E26 -> -11019 | F27: =F17-F26 -> -3238 | G27: =G17-G26 -> 4373 | H27: =H17-H26 -> 12064 | I27: =I17-I26 -> 20045 | J27: =J17-J26 -> 27886 | ... AL27: =AL17-AL26 -> 247537 | AN27: =AN17-AN26 -> 4559023
B28: Cummulative | C28: =C27 -> -41020 | D28: =C28+D27 -> -80040 | E28: =D28+E27 -> -91059 | F28: =E28+F27 -> -94297 | G28: =F28+G27 -> -89924 | H28: =G28+H27 -> -77860 | I28: =H28+I27 -> -57815 | J28: =I28+J27 -> -29929 | K28: =J28+K27 -> 5668 | ... AL28: =AK28+AL27 -> 4559023 | AN28: =AL28 -> 4559023
B29: Discounted CFs | C29: =C27/(1+$C$36)^(C2) -> -40662.845 | D29: =D27/(1+$C$36)^(D2) -> -38343.475 | E29: =E27/(1+$C$36)^(E2) -> -10733.676 | F29: =F27/(1+$C$36)^(F2) -> -3126.6931 | G29: =G27/(1+$C$36)^(G2) -> 4185.911 | H29: =H27/(1+$C$36)^(H2) -> 11447.323 | I29: =I27/(1+$C$36)^(I2) -> 18854.75 | J29: =J27/(1+$C$36)^(J2) -> 26001.777 | ... AL29: =AL27/(1+$C$36)^(AL2) -> 180682.37
B30: PV | C30: =SUM(C29:AL29) -> 3671355.3
B32: Risk free rate | C32: 0.0364 | D32: What country of origin pays for its debts
B33: Company/business specific risk premium | C33: 0.05 | D33: Risk related to this business
B34: Expected inflation | C34: 0.019 | D34: From World Bank projections
B35: Discount rate (y) | C35: =SUM(C32:C34) -> 0.1054
B36: Discount rate (m) | C36: =C35/12 -> 0.0087833333
C38: Initial | D38: After 3y
B39: Self | C39: =C3/(SUM($C$3:$C$13)) -> 0.26666667 | D39: =AN3/(SUM($AN$3:$AN$13)) -> 0.16
B40: FFF | C40: =C4/(SUM($C$3:$C$13)) -> 0.2 | D40: =AN4/(SUM($AN$3:$AN$13)) -> 0.12
B41: Angels | C41: =C5/(SUM($C$3:$C$13)) -> 0.4 | D41: =AN5/(SUM($AN$3:$AN$13)) -> 0.24
B42: Crowd | C42: =C6/(SUM($C$3:$C$13)) -> 0 | D42: =AN6/(SUM($AN$3:$AN$13)) -> 0
...

Sheet Variable Costs
A1: Year 1
A2: Month | B2: Direct Materials | C2: Direct Labor | D2: Overhead Mfg | E2: Variable Cost/Unit
A3: 1 | B3: 125 | C3: 0 | D3: 0 | E3: =SUM(B3:D3) -> 125
A4: 2 | B4: 125 | C4: 0 | D4: 0 | E4: =SUM(B4:D4) -> 125
A5: 3 | B5: 120 | C5: 140 | D5: 320 | E5: =SUM(B5:D5) -> 580
A6: 4 | B6: 118 | C6: 117 | D6: 267 | E6: =SUM(B6:D6) -> 502
A7: 5 | B7: 115 | C7: 100 | D7: 233 | E7: =SUM(B7:D7) -> 448
A8: 6 | B8: 112 | C8: 88 | D8: 208 | E8: =SUM(B8:D8) -> 408
A9: 7 | B9: 110 | C9: 78 | D9: 184 | E9: =SUM(B9:D9) -> 372
A10: 8 | B10: 108 | C10: 70 | D10: 168 | E10: =SUM(B10:D10) -> 346
A11: 9 | B11: 105 | C11: 64 | D11: 157 | E11: =SUM(B11:D11) -> 326
A12: 10 | B12: 103 | C12: 58 | D12: 146 | E12: =SUM(B12:D12) -> 307
A13: 11 | B13: 100 | C13: 54 | D13: 135 | E13: =SUM(B13:D13) -> 289
A14: 12 | B14: 98 | C14: 50 | D14: 126 | E14: =SUM(B14:D14) -> 274
A16: Year 2
A17: Month | B17: Direct Materials | C17: Direct Labor | D17: Overhead Mfg | E17: Variable Cost/Unit
A18: 13 | B18: 95 | C18: 47 | D18: 121 | E18: =SUM(B18:D18) -> 263
A19: 14 | B19: 93 | C19: 44 | D19: 114 | E19: =SUM(B19:D19) -> 251
A20: 15 | B20: 90 | C20: 41 | D20: 109 | E20: =SUM(B20:D20) -> 240
A21: 16 | B21: 88 | C21: 39 | D21: 106 | E21: =SUM(B21:D21) -> 233
A22: 17 | B22: 85 | C22: 37 | D22: 100 | E22: =SUM(B22:D22) -> 222
A23: 18 | B23: 83 | C23: 35 | D23: 97 | E23: =SUM(B23:D23) -> 215
A24: 19 | B24: 80 | C24: 33 | D24: 94 | E24: =SUM(B24:D24) -> 207
A25: 20 | B25: 78 | C25: 32 | D25: 90 | E25: =SUM(B25:D25) -> 200
A26: 21 | B26: 75 | C26: 30 | D26: 88 | E26: =SUM(B26:D26) -> 193
A27: 22 | B27: 73 | C27: 29 | D27: 85 | E27: =SUM(B27:D27) -> 187
A28: 23 | B28: 70 | C28: 28 | D28: 82 | E28: =SUM(B28:D28) -> 180
A29: 24 | B29: 68 | C29: 58 | D29: 87 | E29: =SUM(B29:D29) -> 213
A31: Year 3
A32: Month | B32: Direct Materials | C32: Direct Labor | D32: Overhead Mfg | E32: Variable Cost/Unit
A33: 25 | B33: 65 | C33: 56 | D33: 83 | E33: =SUM(B33:D33) -> 204
A34: 26 | B34: 63 | C34: 54 | D34: 80 | E34: =SUM(B34:D34) -> 197
A35: 27 | B35: 60 | C35: 52 | D35: 81 | E35: =SUM(B35:D35) -> 193
A36: 28 | B36: 58 | C36: 50 | D36: 78 | E36: =SUM(B36:D36) -> 186
A37: 29 | B37: 55 | C37: 48 | D37: 76 | E37: =SUM(B37:D37) -> 179
A38: 30 | B38: 53 | C38: 47 | D38: 77 | E38: =SUM(B38:D38) -> 177
A39: 31 | B39: 50 | C39: 45 | D39: 74 | E39: =SUM(B39:D39) -> 169
A40: 32 | B40: 48 | C40: 44 | D40: 72 | E40: =SUM(B40:D40) -> 164
A41: 33 | B41: 45 | C41: 43 | D41: 73 | E41: =SUM(B41:D41) -> 161
A42: 34 | B42: 43 | C42: 44 | D42: 76 | E42: =SUM(B42:D42) -> 163
...

Sheet Fixed Costs
A1: Fixed Costs Components
A2: Component | B2: Classification
A3: Administrative costs | B3: Fixed
A4: Marketing | B4: Fixed
A5: Social Media | B5: Fixed
A6: Promo materials | B6: Fixed
A7: Rent (portion) | B7: Fixed
A8: Indirect labor | B8: Fixed
A11: Year 1 Fixed Costs (Monthly)
A12: Month | B12: Administrative Costs | C12: Marketing | D12: Social Media | E12: Promo Materials | F12: Total Fixed Costs
A13: 1 | B13: 15500 | C13: 10000 | D13: 3000 | E13: 1500 | F13: =SUM(B13:E13) -> 30000
A14: 2 | B14: 15500 | C14: 8000 | D14: 3000 | E14: 1500 | F14: =SUM(B14:E14) -> 28000
A15: 3 | B15: 15500 | C15: 6000 | D15: 3000 | E15: 1500 | F15: =SUM(B15:E15) -> 26000
A16: 4 | B16: 15500 | C16: 6000 | D16: 3000 | E16: 1500 | F16: =SUM(B16:E16) -> 26000
A17: 5 | B17: 15500 | C17: 6000 | D17: 3000 | E17: 1500 | F17: =SUM(B17:E17) -> 26000
A18: 6 | B18: 15500 | C18: 6000 | D18: 3000 | E18: 1500 | F18: =SUM(B18:E18) -> 26000
A19: 7 | B19: 15500 | C19: 6000 | D19: 3000 | E19: 1500 | F19: =SUM(B19:E19) -> 26000
A20: 8 | B20: 15500 | C20: 6000 | D20: 3000 | E20: 1500 | F20: =SUM(B20:E20) -> 26000
A21: 9 | B21: 15500 | C21: 6000 | D21: 3000 | E21: 1500 | F21: =SUM(B21:E21) -> 26000
A22: 10 | B22: 15500 | C22: 6000 | D22: 3000 | E22: 1500 | F22: =SUM(B22:E22) -> 26000
A23: 11 | B23: 15500 | C23: 6000 | D23: 3000 | E23: 1500 | F23: =SUM(B23:E23) -> 26000
A24: 12 | B24: 15500 | C24: 6000 | D24: 3000 | E24: 1500 | F24: =SUM(B24:E24) -> 26000
A26: Year 2 Fixed Costs (Monthly)
A27: Month | B27: Administrative Costs | C27: Marketing | D27: Social Media | E27: Promo Materials | F27: Total Fixed Costs
A28: 13 | B28: 15500 | C28: 8000 | D28: 3500 | E28: 1500 | F28: =SUM(B28:E28) -> 28500
A29: 14 | B29: 15500 | C29: 8000 | D29: 3500 | E29: 1500 | F29: =SUM(B29:E29) -> 28500
A30: 15 | B30: 15500 | C30: 8000 | D30: 3500 | E30: 1500 | F30: =SUM(B30:E30) -> 28500
A31: 16 | B31: 15500 | C31: 8000 | D31: 3500 | E31: 1500 | F31: =SUM(B31:E31) -> 28500
A32: 17 | B32: 15500 | C32: 8000 | D32: 3500 | E32: 1500 | F32: =SUM(B32:E32) -> 28500
A33: 18 | B33: 15500 | C33: 8000 | D33: 3500 | E33: 1500 | F33: =SUM(B33:E33) -> 28500
A34: 19 | B34: 15500 | C34: 8000 | D34: 3500 | E34: 1500 | F34: =SUM(B34:E34) -> 28500
A35: 20 | B35: 15500 | C35: 8000 | D35: 3500 | E35: 1500 | F35: =SUM(B35:E35) -> 28500
A36: 21 | B36: 15500 | C36: 8000 | D36: 3500 | E36: 1500 | F36: =SUM(B36:E36) -> 28500
A37: 22 | B37: 15500 | C37: 8000 | D37: 3500 | E37: 1500 | F37: =SUM(B37:E37) -> 28500
A38: 23 | B38: 15500 | C38: 8000 | D38: 3500 | E38: 1500 | F38: =SUM(B38:E38) -> 28500
A39: 24 | B39: 15500 | C39: 10000 | D39: 4000 | E39: 2000 | F39: =SUM(B39:E39) -> 31500
A42: Year 3 Fixed Costs (Monthly)
A43: Month | B43: Administrative Costs | C43: Marketing | D43: Social Media | E43: Promo Materials | F43: Total Fixed Costs
A44: 25 | B44: 15500 | C44: 10000 | D44: 4000 | E44: 2000 | F44: =SUM(B44:E44) -> 31500
A45: 26 | B45: 15500 | C45: 10000 | D45: 4000 | E45: 2000 | F45: =SUM(B45:E45) -> 31500
...

Sheet Breakeven Analysis
A1: Year 1 Breakeven Analysis (Monthly)
A2: Month | B2: Selling Price (AED) | C2: Variable Cost/Unit (AED) | D2: Contribution Margin/Unit (AED) | E2: Fixed Costs (AED) | F2: Breakeven Units (Monthly) | G2: Actual Units Sold | H2: Breakeven Achieved?
A3: 1 | B3: 899 | C3: ='Variable Costs'!E3 -> 125 | D3: =B3-C3 -> 774 | E3: ='[3]Fixed Costs'!F13 -> 78000 | F3: =ROUNDUP(E3/D3,0) -> 101 | G3: 0 | H3: =IF(G3>=F3, "Yes", "No") -> No
A4: 2 | B4: 899 | C4: ='Variable Costs'!E4 -> 125 | D4: =B4-C4 -> 774 | E4: ='[3]Fixed Costs'!F14 -> 68000 | F4: =ROUNDUP(E4/D4,0) -> 88 | G4: 0 | H4: =IF(G4>=F4, "Yes", "No") -> No
A5: 3 | B5: 899 | C5: ='Variable Costs'!E5 -> 580 | D5: =B5-C5 -> 319 | E5: ='[3]Fixed Costs'!F15 -> 66000 | F5: =ROUNDUP(E5/D5,0) -> 207 | G5: 50 | H5: =IF(G5>=F5, "Yes", "No") -> No
A6: 4 | B6: 899 | C6: ='Variable Costs'!E6 -> 502 | D6: =B6-C6 -> 397 | E6: ='[3]Fixed Costs'!F16 -> 66000 | F6: =ROUNDUP(E6/D6,0) -> 167 | G6: 60 | H6: =IF(G6>=F6, "Yes", "No") -> No
A7: 5 | B7: 899 | C7: ='Variable Costs'!E7 -> 448 | D7: =B7-C7 -> 451 | E7: ='[3]Fixed Costs'!F17 -> 66500 | F7: =ROUNDUP(E7/D7,0) -> 148 | G7: 70 | H7: =IF(G7>=F7, "Yes", "No") -> No
A8: 6 | B8: 899 | C8: ='Variable Costs'!E8 -> 408 | D8: =B8-C8 -> 491 | E8: ='[3]Fixed Costs'!F18 -> 75500 | F8: =ROUNDUP(E8/D8,0) -> 154 | G8: 80 | H8: =IF(G8>=F8, "Yes", "No") -> No
A9: 7 | B9: 899 | C9: ='Variable Costs'!E9 -> 372 | D9: =B9-C9 -> 527 | E9: ='[3]Fixed Costs'!F19 -> 75500 | F9: =ROUNDUP(E9/D9,0) -> 144 | G9: 90 | H9: =IF(G9>=F9, "Yes", "No") -> No
A10: 8 | B10: 899 | C10: ='Variable Costs'!E10 -> 346 | D10: =B10-C10 -> 553 | E10: ='[3]Fixed Costs'!F20 -> 75500 | F10: =ROUNDUP(E10/D10,0) -> 137 | G10: 100 | H10: =IF(G10>=F10, "Yes", "No") -> No
A11: 9 | B11: 899 | C11: ='Variable Costs'!E11 -> 326 | D11: =B11-C11 -> 573 | E11: ='[3]Fixed Costs'!F21 -> 85000 | F11: =ROUNDUP(E11/D11,0) -> 149 | G11: 110 | H11: =IF(G11>=F11, "Yes", "No") -> No
A12: 10 | B12: 899 | C12: ='Variable Costs'!E12 -> 307 | D12: =B12-C12 -> 592 | E12: ='[3]Fixed Costs'!F22 -> 85000 | F12: =ROUNDUP(E12/D12,0) -> 144 | G12: 120 | H12: =IF(G12>=F12, "Yes", "No") -> No
A13: 11 | B13: 899 | C13: ='Variable Costs'!E13 -> 289 | D13: =B13-C13 -> 610 | E13: ='[3]Fixed Costs'!F23 -> 85000 | F13: =ROUNDUP(E13/D13,0) -> 140 | G13: 130 | H13: =IF(G13>=F13, "Yes", "No") -> No
A14: 12 | B14: 899 | C14: ='Variable Costs'!E14 -> 274 | D14: =B14-C14 -> 625 | E14: ='[3]Fixed Costs'!F24 -> 85000 | F14: =ROUNDUP(E14/D14,0) -> 136 | G14: 140 | H14: =IF(G14>=F14, "Yes", "No") -> Yes
A18: Year 2 Breakeven Analysis (Monthly)
A19: Month | B19: Selling Price (AED) | C19: Variable Cost/Unit (AED) | D19: Contribution Margin/Unit (AED) | E19: Total Fixed Costs (AED) | F19: Breakeven Units (Monthly) | G19: Actual Units Sold | H19: Breakeven Achieved?
A20: 13 | B20: 899 | C20: ='Variable Costs'!E18 -> 263 | D20: =B20-C20 -> 636 | E20: ='[3]Fixed Costs'!F28 -> 94500 | F20: =ROUNDUP(E20/D20,0) -> 149 | G20: 150 | H20: =IF(G20>=F20, "Yes", "No") -> Yes
A21: 14 | B21: 899 | C21: ='Variable Costs'!E19 -> 251 | D21: =B21-C21 -> 648 | E21: ='[3]Fixed Costs'!F29 -> 94500 | F21: =ROUNDUP(E21/D21,0) -> 146 | G21: 160 | H21: =IF(G21>=F21, "Yes", "No") -> Yes
A22: 15 | B22: 899 | C22: ='Variable Costs'!E20 -> 240 | D22: =B22-C22 -> 659 | E22: ='[3]Fixed Costs'!F30 -> 94500 | F22: =ROUNDUP(E22/D22,0) -> 144 | G22: 170 | H22: =IF(G22>=F22, "Yes", "No") -> Yes
A23: 16 | B23: 899 | C23: ='Variable Costs'!E21 -> 233 | D23: =B23-C23 -> 666 | E23: ='[3]Fixed Costs'!F31 -> 103000 | F23: =ROUNDUP(E23/D23,0) -> 155 | G23: 180 | H23: =IF(G23>=F23, "Yes", "No") -> Yes
A24: 17 | B24: 899 | C24: ='Variable Costs'!E22 -> 222 | D24: =B24-C24 -> 677 | E24: ='[3]Fixed Costs'!F32 -> 103000 | F24: =ROUNDUP(E24/D24,0) -> 153 | G24: 190 | H24: =IF(G24>=F24, "Yes", "No") -> Yes
A25: 18 | B25: 899 | C25: ='Variable Costs'!E23 -> 215 | D25: =B25-C25 -> 684 | E25: ='[3]Fixed Costs'!F33 -> 118000 | F25: =ROUNDUP(E25/D25,0) -> 173 | G25: 200 | H25: =IF(G25>=F25, "Yes", "No") -> Yes
A26: 19 | B26: 899 | C26: ='Variable Costs'!E24 -> 207 | D26: =B26-C26 -> 692 | E26: ='[3]Fixed Costs'!F34 -> 118500 | F26: =ROUNDUP(E26/D26,0) -> 172 | G26: 210 | H26: =IF(G26>=F26, "Yes", "No") -> Yes
A27: 20 | B27: 899 | C27: ='Variable Costs'!E25 -> 200 | D27: =B27-C27 -> 699 | E27: ='[3]Fixed Costs'!F35 -> 118500 | F27: =ROUNDUP(E27/D27,0) -> 170 | G27: 220 | H27: =IF(G27>=F27, "Yes", "No") -> Yes
A28: 21 | B28: 899 | C28: ='Variable Costs'!E26 -> 193 | D28: =B28-C28 -> 706 | E28: ='[3]Fixed Costs'!F36 -> 133500 | F28: =ROUNDUP(E28/D28,0) -> 190 | G28: 230 | H28: =IF(G28>=F28, "Yes", "No") -> Yes
A29: 22 | B29: 899 | C29: ='Variable Costs'!E27 -> 187 | D29: =B29-C29 -> 712 | E29: ='[3]Fixed Costs'!F37 -> 134000 | F29: =ROUNDUP(E29/D29,0) -> 189 | G29: 240 | H29: =IF(G29>=F29, "Yes", "No") -> Yes
A30: 23 | B30: 899 | C30: ='Variable Costs'!E28 -> 180 | D30: =B30-C30 -> 719 | E30: ='[3]Fixed Costs'!F38 -> 134000 | F30: =ROUNDUP(E30/D30,0) -> 187 | G30: 250 | H30: =IF(G30>=F30, "Yes", "No") -> Yes
A31: 24 | B31: 899 | C31: ='Variable Costs'!E29 -> 213 | D31: =B31-C31 -> 686 | E31: ='[3]Fixed Costs'!F39 -> 150500 | F31: =ROUNDUP(E31/D31,0) -> 220 | G31: 260 | H31: =IF(G31>=F31, "Yes", "No") -> Yes
A34: Year 3 Breakeven Analysis (Monthly)
A35: Month | B35: Selling Price (AED) | C35: Variable Cost/Unit (AED) | D35: Contribution Margin/Unit (AED) | E35: Total Fixed Costs (AED) | F35: Breakeven Units (Monthly) | G35: Actual Units Sold | H35: Breakeven Achieved?
A36: 25 | B36: 899 | C36: ='Variable Costs'!E33 -> 204 | D36: =B36-C36 -> 695 | E36: 150500 | F36: =ROUNDUP(E36/D36,0) -> 217 | G36: 270 | H36: =IF(G36>=F36, "Yes", "No") -> Yes
A37: 26 | B37: 899 | C37: ='Variable Costs'!E34 -> 197 | D37: =B37-C37 -> 702 | E37: 150500 | F37: =ROUNDUP(E37/D37,0) -> 215 | G37: 280 | H37: =IF(G37>=F37, "Yes", "No") -> Yes
A38: 27 | B38: 899 | C38: ='Variable Costs'!E35 -> 193 | D38: =B38-C38 -> 706 | E38: 168000 | F38: =ROUNDUP(E38/D38,0) -> 238 | G38: 290 | H38: =IF(G38>=F38, "Yes", "No") -> Yes
A39: 28 | B39: 899 | C39: ='Variable Costs'!E36 -> 186 | D39: =B39-C39 -> 713 | E39: 168000 | F39: =ROUNDUP(E39/D39,0) -> 236 | G39: 300 | H39: =IF(G39>=F39, "Yes", "No") -> Yes
A40: 29 | B40: 899 | C40: ='Variable Costs'!E37 -> 179 | D40: =B40-C40 -> 720 | E40: 168000 | F40: =ROUNDUP(E40/D40,0) -> 234 | G40: 310 | H40: =IF(G40>=F40, "Yes", "No") -> Yes
A41: 30 | B41: 899 | C41: ='Variable Costs'!E38 -> 177 | D41: =B41-C41 -> 722 | E41: 175500 | F41: =ROUNDUP(E41/D41,0) -> 244 | G41: 320 | H41: =IF(G41>=F41, "Yes", "No") -> Yes
A42: 31 | B42: 899 | C42: ='Variable Costs'!E39 -> 169 | D42: =B42-C42 -> 730 | E42: 168500 | F42: =ROUNDUP(E42/D42,0) -> 231 | G42: 330 | H42: =IF(G42>=F42, "Yes", "No") -> Yes
A43: 32 | B43: 899 | C43: ='Variable Costs'!E40 -> 164 | D43: =B43-C43 -> 735 | E43: 168500 | F43: =ROUNDUP(E43/D43,0) -> 230 | G43: 340 | H43: =IF(G43>=F43, "Yes", "No") -> Yes
A44: 33 | B44: 899 | C44: ='Variable Costs'!E41 -> 161 | D44: =B44-C44 -> 738 | E44: 169000 | F44: =ROUNDUP(E44/D44,0) -> 229 | G44: 350 | H44: =IF(G44>=F44, "Yes", "No") -> Yes
A45: 34 | B45: 899 | C45: ='Variable Costs'!E42 -> 163 | D45: =B45-C45 -> 736 | E45: 188500 | F45: =ROUNDUP(E45/D45,0) -> 257 | G45: 360 | H45: =IF(G45>=F45, "Yes", "No") -> Yes
...
