Workbook
Name alpha: Settings!$B$14
Name danger_lbl: Settings!$C$29:$C$31
Name danger_lo: Settings!$B$29:$B$31
Name dc_danger: Dash_Calc!$B$4
Name dc_expo: Dash_Calc!$B$6
Name dc_pred: Dash_Calc!$B$5
Name dc_size: Dash_Calc!$B$7
Name g_danger: Clean_2_Features!$I$2:$I$63
Name g_size: Clean_2_Features!$H$2:$H$63
Name g_sleep: Clean_2_Features!$G$2:$G$63
Name grand_mean: Group_Analysis!$B$5
Name grp_n: Group_Analysis!$B$4
Name kf_delta: Dash_Calc!$B$12
Name kf_gest: Dash_Calc!$B$14
Name kf_life: Dash_Calc!$B$15
Name kf_n: Dash_Calc!$B$10
Name kf_short: Dash_Calc!$B$13
Name kf_sleep: Dash_Calc!$B$11
Name l_body: Clean_2_Features!$B$2:$B$63
Name l_brain: Clean_2_Features!$C$2:$C$63
Name l_gest: Clean_2_Features!$E$2:$E$63
Name l_life: Clean_2_Features!$D$2:$D$63
Name lim_brain_max: Settings!$B$8
Name lim_gest_max: Settings!$B$10
Name lim_idx_max: Settings!$B$12
Name lim_idx_min: Settings!$B$11
Name lim_life_max: Settings!$B$9
Name lim_sleep_max: Settings!$B$13
Name lim_w_max: Settings!$B$7
Name lim_w_min: Settings!$B$6
Name list_danger: Settings!$F$5:$F$10
Name list_expo: Settings!$H$5:$H$10
Name list_pred: Settings!$G$5:$G$10
Name list_size: Settings!$I$5:$I$9
Name m_adjr2: Regression!$B$10
Name m_coef: Regression!$B$23:$E$23
Name m_df: Regression!$B$8
Name m_F: Regression!$B$7
Name m_intercept: Regression!$B$24
Name m_n: Regression!$B$9
Name m_pF: Regression!$B$11
Name m_r2: Regression!$B$5
Name m_sdy: Regression!$B$12
Name m_se: Regression!$B$6
Name md_pred: Model_Data!$H$2:$H$52
Name md_res: Model_Data!$I$2:$I$52
Name md_X: Model_Data!$D$2:$G$52
Name md_y: Model_Data!$C$2:$C$52
Name p_d: Sleep_Predictor!$B$8
Name p_g: Sleep_Predictor!$B$7
Name p_l: Sleep_Predictor!$B$6
Name p_w: Sleep_Predictor!$B$5
Name raw_body_weight: Raw_Data!$A$2:$A$63
Name raw_brain_weight: Raw_Data!$B$2:$B$63
Name raw_danger_index: Raw_Data!$G$2:$G$63
Name raw_gestation_time: Raw_Data!$D$2:$D$63
Name raw_max_life_span: Raw_Data!$C$2:$C$63
Name raw_predation_index: Raw_Data!$E$2:$E$63
Name raw_sleep_exposure_index: Raw_Data!$F$2:$F$63
Name raw_total_sleep: Raw_Data!$H$2:$H$63

Sheet Raw_Data
A1: body_weight | B1: brain_weight | C1: max_life_span | D1: gestation_time | E1: predation_index | F1: sleep_exposure_index | G1: danger_index | H1: total_sleep
A2: 6654 | B2: 5712 | C2: 38.6 | D2: 645 | E2: 3 | F2: 5 | G2: 3 | H2: 3.3
A3: 1 | B3: 6.6 | C3: 4.5 | D3: 42 | E3: 3 | F3: 1 | G3: 3 | H3: 8.3
A4: 3.385 | B4: 44.5 | C4: 14 | D4: 60 | E4: 1 | F4: 1 | G4: 1 | H4: 12.5
A5: 0.92 | B5: 5.7 | C5: ? | D5: 25 | E5: 5 | F5: 2 | G5: 3 | H5: 16.5
A6: 2547 | B6: 4603 | C6: 69 | D6: 624 | E6: 3 | F6: 5 | G6: 4 | H6: 3.9
A7: 10.55 | B7: 179.5 | C7: 27 | D7: 180 | E7: 4 | F7: 4 | G7: 4 | H7: 9.8
A8: 0.023 | B8: 0.3 | C8: 19 | D8: 35 | E8: 1 | F8: 1 | G8: 1 | H8: 19.7
A9: 160 | B9: 169 | C9: 30.4 | D9: 392 | E9: 4 | F9: 5 | G9: 4 | H9: 6.2
A10: 3.3 | B10: 25.6 | C10: 28 | D10: 63 | E10: 1 | F10: 2 | G10: 1 | H10: 14.5
A11: 52.16 | B11: 440 | C11: 50 | D11: 230 | E11: 1 | F11: 1 | G11: 1 | H11: 9.7
A12: 0.425 | B12: 6.4 | C12: 7 | D12: 112 | E12: 5 | F12: 4 | G12: 4 | H12: 12.5
A13: 465 | B13: 423 | C13: 30 | D13: 281 | E13: 5 | F13: 5 | G13: 5 | H13: 3.9
A14: 0.55 | B14: 2.4 | C14: ? | D14: ? | E14: 2 | F14: 1 | G14: 2 | H14: 10.3
A15: 187.1 | B15: 419 | C15: 40 | D15: 365 | E15: 5 | F15: 5 | G15: 5 | H15: 3.1
A16: 0.075 | B16: 1.2 | C16: 3.5 | D16: 42 | E16: 1 | F16: 1 | G16: 1 | H16: 8.4
A17: 3 | B17: 25 | C17: 50 | D17: 28 | E17: 2 | F17: 2 | G17: 2 | H17: 8.6
A18: 0.785 | B18: 3.5 | C18: 6 | D18: 42 | E18: 2 | F18: 2 | G18: 2 | H18: 10.7
A19: 0.2 | B19: 5 | C19: 10.4 | D19: 120 | E19: 2 | F19: 2 | G19: 2 | H19: 10.7
A20: 1.41 | B20: 17.5 | C20: 34 | D20: ? | E20: 1 | F20: 2 | G20: 1 | H20: 6.1
A21: 60 | B21: 81 | C21: 7 | D21: ? | E21: 1 | F21: 1 | G21: 1 | H21: 18.1
A22: 529 | B22: 680 | C22: 28 | D22: 400 | E22: 5 | F22: 5 | G22: 5 | H22: ?
A23: 27.66 | B23: 115 | C23: 20 | D23: 148 | E23: 5 | F23: 5 | G23: 5 | H23: 3.8
A24: 0.12 | B24: 1 | C24: 3.9 | D24: 16 | E24: 3 | F24: 1 | G24: 2 | H24: 14.4
A25: 207 | B25: 406 | C25: 39.3 | D25: 252 | E25: 1 | F25: 4 | G25: 1 | H25: 12
A26: 85 | B26: 325 | C26: 41 | D26: 310 | E26: 1 | F26: 3 | G26: 1 | H26: 6.2
A27: 36.33 | B27: 119.5 | C27: 16.2 | D27: 63 | E27: 1 | F27: 1 | G27: 1 | H27: 13
A28: 0.101 | B28: 4 | C28: 9 | D28: 28 | E28: 5 | F28: 1 | G28: 3 | H28: 13.8
A29: 1.04 | B29: 5.5 | C29: 7.6 | D29: 68 | E29: 5 | F29: 3 | G29: 4 | H29: 8.2
A30: 521 | B30: 655 | C30: 46 | D30: 336 | E30: 5 | F30: 5 | G30: 5 | H30: 2.9
A31: 100 | B31: 157 | C31: 22.4 | D31: 100 | E31: 1 | F31: 1 | G31: 1 | H31: 10.8
A32: 35 | B32: 56 | C32: 16.3 | D32: 33 | E32: 3 | F32: 5 | G32: 4 | H32: ?
A33: 0.005 | B33: 0.14 | C33: 2.6 | D33: 21.5 | E33: 5 | F33: 2 | G33: 4 | H33: 9.1
A34: 0.01 | B34: 0.25 | C34: 24 | D34: 50 | E34: 1 | F34: 1 | G34: 1 | H34: 19.9
A35: 62 | B35: 1320 | C35: 100 | D35: 267 | E35: 1 | F35: 1 | G35: 1 | H35: 8
A36: 0.122 | B36: 3 | C36: ? | D36: 30 | E36: 2 | F36: 1 | G36: 1 | H36: 10.6
A37: 1.35 | B37: 8.1 | C37: ? | D37: 45 | E37: 3 | F37: 1 | G37: 3 | H37: 11.2
A38: 0.023 | B38: 0.4 | C38: 3.2 | D38: 19 | E38: 4 | F38: 1 | G38: 3 | H38: 13.2
A39: 0.048 | B39: 0.33 | C39: 2 | D39: 30 | E39: 4 | F39: 1 | G39: 3 | H39: 12.8
A40: 1.7 | B40: 6.3 | C40: 5 | D40: 12 | E40: 2 | F40: 1 | G40: 1 | H40: 19.4
...

Sheet Clean_1_Numeric
A1: record_id | B1: body_weight | C1: brain_weight | D1: max_life_span | E1: gestation_time | F1: predation_index | G1: sleep_exposure_index | H1: danger_index | I1: total_sleep | J1: missing_count | K1: placeholders_found | L1: other_non_numeric | M1: has_sleep | N1: complete_case | O1: range_ok | P1: include_row
A2: =ROW()-1 -> 1 | B2: =IF(ISNUMBER(Raw_Data!A2),Raw_Data!A2,"") -> 6654 | C2: =IF(ISNUMBER(Raw_Data!B2),Raw_Data!B2,"") -> 5712 | D2: =IF(ISNUMBER(Raw_Data!C2),Raw_Data!C2,"") -> 38.6 | E2: =IF(ISNUMBER(Raw_Data!D2),Raw_Data!D2,"") -> 645 | F2: =IF(ISNUMBER(Raw_Data!E2),Raw_Data!E2,"") -> 3 | G2: =IF(ISNUMBER(Raw_Data!F2),Raw_Data!F2,"") -> 5 | H2: =IF(ISNUMBER(Raw_Data!G2),Raw_Data!G2,"") -> 3 | I2: =IF(ISNUMBER(Raw_Data!H2),Raw_Data!H2,"") -> 3.3 | J2: =COUNTBLANK(B2:I2) -> 0 | K2: =COUNTIF(Raw_Data!A2:H2,"~?") -> 0 | L2: =J2-K2 -> 0 | M2: =IF(ISNUMBER(I2),1,0) -> 1 | N2: =IF(AND(J2=0,O2=1),1,0) -> 1 | O2: =IF(AND(OR(B2="",AND(B2>=lim_w_min,B2<=lim_w_max)),OR(C2="",AND(C2>=lim_w_min,C2<=lim_brain_max)),OR(D2="",AND(D2>0,D2<=lim_life_max)),OR(E2="",AND(E2>0,E2<=lim_gest_max)),MIN(F2:H2)>=lim_idx_min,MAX(F2:H2)<=lim_idx_max,OR(I2="",AND(I2>0,I2<=lim_sleep_max))),1,0) -> 1 | P2: =M2*O2 -> 1
A3: =ROW()-1 -> 2 | B3: =IF(ISNUMBER(Raw_Data!A3),Raw_Data!A3,"") -> 1 | C3: =IF(ISNUMBER(Raw_Data!B3),Raw_Data!B3,"") -> 6.6 | D3: =IF(ISNUMBER(Raw_Data!C3),Raw_Data!C3,"") -> 4.5 | E3: =IF(ISNUMBER(Raw_Data!D3),Raw_Data!D3,"") -> 42 | F3: =IF(ISNUMBER(Raw_Data!E3),Raw_Data!E3,"") -> 3 | G3: =IF(ISNUMBER(Raw_Data!F3),Raw_Data!F3,"") -> 1 | H3: =IF(ISNUMBER(Raw_Data!G3),Raw_Data!G3,"") -> 3 | I3: =IF(ISNUMBER(Raw_Data!H3),Raw_Data!H3,"") -> 8.3 | J3: =COUNTBLANK(B3:I3) -> 0 | K3: =COUNTIF(Raw_Data!A3:H3,"~?") -> 0 | L3: =J3-K3 -> 0 | M3: =IF(ISNUMBER(I3),1,0) -> 1 | N3: =IF(AND(J3=0,O3=1),1,0) -> 1 | O3: =IF(AND(OR(B3="",AND(B3>=lim_w_min,B3<=lim_w_max)),OR(C3="",AND(C3>=lim_w_min,C3<=lim_brain_max)),OR(D3="",AND(D3>0,D3<=lim_life_max)),OR(E3="",AND(E3>0,E3<=lim_gest_max)),MIN(F3:H3)>=lim_idx_min,MAX(F3:H3)<=lim_idx_max,OR(I3="",AND(I3>0,I3<=lim_sleep_max))),1,0) -> 1 | P3: =M3*O3 -> 1
A4: =ROW()-1 -> 3 | B4: =IF(ISNUMBER(Raw_Data!A4),Raw_Data!A4,"") -> 3.385 | C4: =IF(ISNUMBER(Raw_Data!B4),Raw_Data!B4,"") -> 44.5 | D4: =IF(ISNUMBER(Raw_Data!C4),Raw_Data!C4,"") -> 14 | E4: =IF(ISNUMBER(Raw_Data!D4),Raw_Data!D4,"") -> 60 | F4: =IF(ISNUMBER(Raw_Data!E4),Raw_Data!E4,"") -> 1 | G4: =IF(ISNUMBER(Raw_Data!F4),Raw_Data!F4,"") -> 1 | H4: =IF(ISNUMBER(Raw_Data!G4),Raw_Data!G4,"") -> 1 | I4: =IF(ISNUMBER(Raw_Data!H4),Raw_Data!H4,"") -> 12.5 | J4: =COUNTBLANK(B4:I4) -> 0 | K4: =COUNTIF(Raw_Data!A4:H4,"~?") -> 0 | L4: =J4-K4 -> 0 | M4: =IF(ISNUMBER(I4),1,0) -> 1 | N4: =IF(AND(J4=0,O4=1),1,0) -> 1 | O4: =IF(AND(OR(B4="",AND(B4>=lim_w_min,B4<=lim_w_max)),OR(C4="",AND(C4>=lim_w_min,C4<=lim_brain_max)),OR(D4="",AND(D4>0,D4<=lim_life_max)),OR(E4="",AND(E4>0,E4<=lim_gest_max)),MIN(F4:H4)>=lim_idx_min,MAX(F4:H4)<=lim_idx_max,OR(I4="",AND(I4>0,I4<=lim_sleep_max))),1,0) -> 1 | P4: =M4*O4 -> 1
A5: =ROW()-1 -> 4 | B5: =IF(ISNUMBER(Raw_Data!A5),Raw_Data!A5,"") -> 0.92 | C5: =IF(ISNUMBER(Raw_Data!B5),Raw_Data!B5,"") -> 5.7 | D5: =IF(ISNUMBER(Raw_Data!C5),Raw_Data!C5,"") | E5: =IF(ISNUMBER(Raw_Data!D5),Raw_Data!D5,"") -> 25 | F5: =IF(ISNUMBER(Raw_Data!E5),Raw_Data!E5,"") -> 5 | G5: =IF(ISNUMBER(Raw_Data!F5),Raw_Data!F5,"") -> 2 | H5: =IF(ISNUMBER(Raw_Data!G5),Raw_Data!G5,"") -> 3 | I5: =IF(ISNUMBER(Raw_Data!H5),Raw_Data!H5,"") -> 16.5 | J5: =COUNTBLANK(B5:I5) -> 1 | K5: =COUNTIF(Raw_Data!A5:H5,"~?") -> 1 | L5: =J5-K5 -> 0 | M5: =IF(ISNUMBER(I5),1,0) -> 1 | N5: =IF(AND(J5=0,O5=1),1,0) -> 0 | O5: =IF(AND(OR(B5="",AND(B5>=lim_w_min,B5<=lim_w_max)),OR(C5="",AND(C5>=lim_w_min,C5<=lim_brain_max)),OR(D5="",AND(D5>0,D5<=lim_life_max)),OR(E5="",AND(E5>0,E5<=lim_gest_max)),MIN(F5:H5)>=lim_idx_min,MAX(F5:H5)<=lim_idx_max,OR(I5="",AND(I5>0,I5<=lim_sleep_max))),1,0) -> 1 | P5: =M5*O5 -> 1
A6: =ROW()-1 -> 5 | B6: =IF(ISNUMBER(Raw_Data!A6),Raw_Data!A6,"") -> 2547 | C6: =IF(ISNUMBER(Raw_Data!B6),Raw_Data!B6,"") -> 4603 | D6: =IF(ISNUMBER(Raw_Data!C6),Raw_Data!C6,"") -> 69 | E6: =IF(ISNUMBER(Raw_Data!D6),Raw_Data!D6,"") -> 624 | F6: =IF(ISNUMBER(Raw_Data!E6),Raw_Data!E6,"") -> 3 | G6: =IF(ISNUMBER(Raw_Data!F6),Raw_Data!F6,"") -> 5 | H6: =IF(ISNUMBER(Raw_Data!G6),Raw_Data!G6,"") -> 4 | I6: =IF(ISNUMBER(Raw_Data!H6),Raw_Data!H6,"") -> 3.9 | J6: =COUNTBLANK(B6:I6) -> 0 | K6: =COUNTIF(Raw_Data!A6:H6,"~?") -> 0 | L6: =J6-K6 -> 0 | M6: =IF(ISNUMBER(I6),1,0) -> 1 | N6: =IF(AND(J6=0,O6=1),1,0) -> 1 | O6: =IF(AND(OR(B6="",AND(B6>=lim_w_min,B6<=lim_w_max)),OR(C6="",AND(C6>=lim_w_min,C6<=lim_brain_max)),OR(D6="",AND(D6>0,D6<=lim_life_max)),OR(E6="",AND(E6>0,E6<=lim_gest_max)),MIN(F6:H6)>=lim_idx_min,MAX(F6:H6)<=lim_idx_max,OR(I6="",AND(I6>0,I6<=lim_sleep_max))),1,0) -> 1 | P6: =M6*O6 -> 1
A7: =ROW()-1 -> 6 | B7: =IF(ISNUMBER(Raw_Data!A7),Raw_Data!A7,"") -> 10.55 | C7: =IF(ISNUMBER(Raw_Data!B7),Raw_Data!B7,"") -> 179.5 | D7: =IF(ISNUMBER(Raw_Data!C7),Raw_Data!C7,"") -> 27 | E7: =IF(ISNUMBER(Raw_Data!D7),Raw_Data!D7,"") -> 180 | F7: =IF(ISNUMBER(Raw_Data!E7),Raw_Data!E7,"") -> 4 | G7: =IF(ISNUMBER(Raw_Data!F7),Raw_Data!F7,"") -> 4 | H7: =IF(ISNUMBER(Raw_Data!G7),Raw_Data!G7,"") -> 4 | I7: =IF(ISNUMBER(Raw_Data!H7),Raw_Data!H7,"") -> 9.8 | J7: =COUNTBLANK(B7:I7) -> 0 | K7: =COUNTIF(Raw_Data!A7:H7,"~?") -> 0 | L7: =J7-K7 -> 0 | M7: =IF(ISNUMBER(I7),1,0) -> 1 | N7: =IF(AND(J7=0,O7=1),1,0) -> 1 | O7: =IF(AND(OR(B7="",AND(B7>=lim_w_min,B7<=lim_w_max)),OR(C7="",AND(C7>=lim_w_min,C7<=lim_brain_max)),OR(D7="",AND(D7>0,D7<=lim_life_max)),OR(E7="",AND(E7>0,E7<=lim_gest_max)),MIN(F7:H7)>=lim_idx_min,MAX(F7:H7)<=lim_idx_max,OR(I7="",AND(I7>0,I7<=lim_sleep_max))),1,0) -> 1 | P7: =M7*O7 -> 1
A8: =ROW()-1 -> 7 | B8: =IF(ISNUMBER(Raw_Data!A8),Raw_Data!A8,"") -> 0.023 | C8: =IF(ISNUMBER(Raw_Data!B8),Raw_Data!B8,"") -> 0.3 | D8: =IF(ISNUMBER(Raw_Data!C8),Raw_Data!C8,"") -> 19 | E8: =IF(ISNUMBER(Raw_Data!D8),Raw_Data!D8,"") -> 35 | F8: =IF(ISNUMBER(Raw_Data!E8),Raw_Data!E8,"") -> 1 | G8: =IF(ISNUMBER(Raw_Data!F8),Raw_Data!F8,"") -> 1 | H8: =IF(ISNUMBER(Raw_Data!G8),Raw_Data!G8,"") -> 1 | I8: =IF(ISNUMBER(Raw_Data!H8),Raw_Data!H8,"") -> 19.7 | J8: =COUNTBLANK(B8:I8) -> 0 | K8: =COUNTIF(Raw_Data!A8:H8,"~?") -> 0 | L8: =J8-K8 -> 0 | M8: =IF(ISNUMBER(I8),1,0) -> 1 | N8: =IF(AND(J8=0,O8=1),1,0) -> 1 | O8: =IF(AND(OR(B8="",AND(B8>=lim_w_min,B8<=lim_w_max)),OR(C8="",AND(C8>=lim_w_min,C8<=lim_brain_max)),OR(D8="",AND(D8>0,D8<=lim_life_max)),OR(E8="",AND(E8>0,E8<=lim_gest_max)),MIN(F8:H8)>=lim_idx_min,MAX(F8:H8)<=lim_idx_max,OR(I8="",AND(I8>0,I8<=lim_sleep_max))),1,0) -> 1 | P8: =M8*O8 -> 1
A9: =ROW()-1 -> 8 | B9: =IF(ISNUMBER(Raw_Data!A9),Raw_Data!A9,"") -> 160 | C9: =IF(ISNUMBER(Raw_Data!B9),Raw_Data!B9,"") -> 169 | D9: =IF(ISNUMBER(Raw_Data!C9),Raw_Data!C9,"") -> 30.4 | E9: =IF(ISNUMBER(Raw_Data!D9),Raw_Data!D9,"") -> 392 | F9: =IF(ISNUMBER(Raw_Data!E9),Raw_Data!E9,"") -> 4 | G9: =IF(ISNUMBER(Raw_Data!F9),Raw_Data!F9,"") -> 5 | H9: =IF(ISNUMBER(Raw_Data!G9),Raw_Data!G9,"") -> 4 | I9: =IF(ISNUMBER(Raw_Data!H9),Raw_Data!H9,"") -> 6.2 | J9: =COUNTBLANK(B9:I9) -> 0 | K9: =COUNTIF(Raw_Data!A9:H9,"~?") -> 0 | L9: =J9-K9 -> 0 | M9: =IF(ISNUMBER(I9),1,0) -> 1 | N9: =IF(AND(J9=0,O9=1),1,0) -> 1 | O9: =IF(AND(OR(B9="",AND(B9>=lim_w_min,B9<=lim_w_max)),OR(C9="",AND(C9>=lim_w_min,C9<=lim_brain_max)),OR(D9="",AND(D9>0,D9<=lim_life_max)),OR(E9="",AND(E9>0,E9<=lim_gest_max)),MIN(F9:H9)>=lim_idx_min,MAX(F9:H9)<=lim_idx_max,OR(I9="",AND(I9>0,I9<=lim_sleep_max))),1,0) -> 1 | P9: =M9*O9 -> 1
A10: =ROW()-1 -> 9 | B10: =IF(ISNUMBER(Raw_Data!A10),Raw_Data!A10,"") -> 3.3 | C10: =IF(ISNUMBER(Raw_Data!B10),Raw_Data!B10,"") -> 25.6 | D10: =IF(ISNUMBER(Raw_Data!C10),Raw_Data!C10,"") -> 28 | E10: =IF(ISNUMBER(Raw_Data!D10),Raw_Data!D10,"") -> 63 | F10: =IF(ISNUMBER(Raw_Data!E10),Raw_Data!E10,"") -> 1 | G10: =IF(ISNUMBER(Raw_Data!F10),Raw_Data!F10,"") -> 2 | H10: =IF(ISNUMBER(Raw_Data!G10),Raw_Data!G10,"") -> 1 | I10: =IF(ISNUMBER(Raw_Data!H10),Raw_Data!H10,"") -> 14.5 | J10: =COUNTBLANK(B10:I10) -> 0 | K10: =COUNTIF(Raw_Data!A10:H10,"~?") -> 0 | L10: =J10-K10 -> 0 | M10: =IF(ISNUMBER(I10),1,0) -> 1 | N10: =IF(AND(J10=0,O10=1),1,0) -> 1 | O10: =IF(AND(OR(B10="",AND(B10>=lim_w_min,B10<=lim_w_max)),OR(C10="",AND(C10>=lim_w_min,C10<=lim_brain_max)),OR(D10="",AND(D10>0,D10<=lim_life_max)),OR(E10="",AND(E10>0,E10<=lim_gest_max)),MIN(F10:H10)>=lim_idx_min,MAX(F10:H10)<=lim_idx_max,OR(I10="",AND(I10>0,I10<=lim_sleep_max))),1,0) -> 1 | P10: =M10*O10 -> 1
A11: =ROW()-1 -> 10 | B11: =IF(ISNUMBER(Raw_Data!A11),Raw_Data!A11,"") -> 52.16 | C11: =IF(ISNUMBER(Raw_Data!B11),Raw_Data!B11,"") -> 440 | D11: =IF(ISNUMBER(Raw_Data!C11),Raw_Data!C11,"") -> 50 | E11: =IF(ISNUMBER(Raw_Data!D11),Raw_Data!D11,"") -> 230 | F11: =IF(ISNUMBER(Raw_Data!E11),Raw_Data!E11,"") -> 1 | G11: =IF(ISNUMBER(Raw_Data!F11),Raw_Data!F11,"") -> 1 | H11: =IF(ISNUMBER(Raw_Data!G11),Raw_Data!G11,"") -> 1 | I11: =IF(ISNUMBER(Raw_Data!H11),Raw_Data!H11,"") -> 9.7 | J11: =COUNTBLANK(B11:I11) -> 0 | K11: =COUNTIF(Raw_Data!A11:H11,"~?") -> 0 | L11: =J11-K11 -> 0 | M11: =IF(ISNUMBER(I11),1,0) -> 1 | N11: =IF(AND(J11=0,O11=1),1,0) -> 1 | O11: =IF(AND(OR(B11="",AND(B11>=lim_w_min,B11<=lim_w_max)),OR(C11="",AND(C11>=lim_w_min,C11<=lim_brain_max)),OR(D11="",AND(D11>0,D11<=lim_life_max)),OR(E11="",AND(E11>0,E11<=lim_gest_max)),MIN(F11:H11)>=lim_idx_min,MAX(F11:H11)<=lim_idx_max,OR(I11="",AND(I11>0,I11<=lim_sleep_max))),1,0) -> 1 | P11: =M11*O11 -> 1
A12: =ROW()-1 -> 11 | B12: =IF(ISNUMBER(Raw_Data!A12),Raw_Data!A12,"") -> 0.425 | C12: =IF(ISNUMBER(Raw_Data!B12),Raw_Data!B12,"") -> 6.4 | D12: =IF(ISNUMBER(Raw_Data!C12),Raw_Data!C12,"") -> 7 | E12: =IF(ISNUMBER(Raw_Data!D12),Raw_Data!D12,"") -> 112 | F12: =IF(ISNUMBER(Raw_Data!E12),Raw_Data!E12,"") -> 5 | G12: =IF(ISNUMBER(Raw_Data!F12),Raw_Data!F12,"") -> 4 | H12: =IF(ISNUMBER(Raw_Data!G12),Raw_Data!G12,"") -> 4 | I12: =IF(ISNUMBER(Raw_Data!H12),Raw_Data!H12,"") -> 12.5 | J12: =COUNTBLANK(B12:I12) -> 0 | K12: =COUNTIF(Raw_Data!A12:H12,"~?") -> 0 | L12: =J12-K12 -> 0 | M12: =IF(ISNUMBER(I12),1,0) -> 1 | N12: =IF(AND(J12=0,O12=1),1,0) -> 1 | O12: =IF(AND(OR(B12="",AND(B12>=lim_w_min,B12<=lim_w_max)),OR(C12="",AND(C12>=lim_w_min,C12<=lim_brain_max)),OR(D12="",AND(D12>0,D12<=lim_life_max)),OR(E12="",AND(E12>0,E12<=lim_gest_max)),MIN(F12:H12)>=lim_idx_min,MAX(F12:H12)<=lim_idx_max,OR(I12="",AND(I12>0,I12<=lim_sleep_max))),1,0) -> 1 | P12: =M12*O12 -> 1
A13: =ROW()-1 -> 12 | B13: =IF(ISNUMBER(Raw_Data!A13),Raw_Data!A13,"") -> 465 | C13: =IF(ISNUMBER(Raw_Data!B13),Raw_Data!B13,"") -> 423 | D13: =IF(ISNUMBER(Raw_Data!C13),Raw_Data!C13,"") -> 30 | E13: =IF(ISNUMBER(Raw_Data!D13),Raw_Data!D13,"") -> 281 | F13: =IF(ISNUMBER(Raw_Data!E13),Raw_Data!E13,"") -> 5 | G13: =IF(ISNUMBER(Raw_Data!F13),Raw_Data!F13,"") -> 5 | H13: =IF(ISNUMBER(Raw_Data!G13),Raw_Data!G13,"") -> 5 | I13: =IF(ISNUMBER(Raw_Data!H13),Raw_Data!H13,"") -> 3.9 | J13: =COUNTBLANK(B13:I13) -> 0 | K13: =COUNTIF(Raw_Data!A13:H13,"~?") -> 0 | L13: =J13-K13 -> 0 | M13: =IF(ISNUMBER(I13),1,0) -> 1 | N13: =IF(AND(J13=0,O13=1),1,0) -> 1 | O13: =IF(AND(OR(B13="",AND(B13>=lim_w_min,B13<=lim_w_max)),OR(C13="",AND(C13>=lim_w_min,C13<=lim_brain_max)),OR(D13="",AND(D13>0,D13<=lim_life_max)),OR(E13="",AND(E13>0,E13<=lim_gest_max)),MIN(F13:H13)>=lim_idx_min,MAX(F13:H13)<=lim_idx_max,OR(I13="",AND(I13>0,I13<=lim_sleep_max))),1,0) -> 1 | P13: =M13*O13 -> 1
... A63: =ROW()-1 -> 62 | B63: =IF(ISNUMBER(Raw_Data!A63),Raw_Data!A63,"") -> 4.05 | C63: =IF(ISNUMBER(Raw_Data!B63),Raw_Data!B63,"") -> 17 | D63: =IF(ISNUMBER(Raw_Data!C63),Raw_Data!C63,"") -> 13 | E63: =IF(ISNUMBER(Raw_Data!D63),Raw_Data!D63,"") -> 38 | F63: =IF(ISNUMBER(Raw_Data!E63),Raw_Data!E63,"") -> 3 | G63: =IF(ISNUMBER(Raw_Data!F63),Raw_Data!F63,"") -> 1 | H63: =IF(ISNUMBER(Raw_Data!G63),Raw_Data!G63,"") -> 1 | I63: =IF(ISNUMBER(Raw_Data!H63),Raw_Data!H63,"") | J63: =COUNTBLANK(B63:I63) -> 1 | K63: =COUNTIF(Raw_Data!A63:H63,"~?") -> 1 | L63: =J63-K63 -> 0 | M63: =IF(ISNUMBER(I63),1,0) -> 0 | N63: =IF(AND(J63=0,O63=1),1,0) -> 0 | O63: =IF(AND(OR(B63="",AND(B63>=lim_w_min,B63<=lim_w_max)),OR(C63="",AND(C63>=lim_w_min,C63<=lim_brain_max)),OR(D63="",AND(D63>0,D63<=lim_life_max)),OR(E63="",AND(E63>0,E63<=lim_gest_max)),MIN(F63:H63)>=lim_idx_min,MAX(F63:H63)<=lim_idx_max,OR(I63="",AND(I63>0,I63<=lim_sleep_max))),1,0) -> 1 | P63: =M63*O63 -> 0

Sheet Clean_2_Features
A1: record_id | B1: log10_body_weight | C1: log10_brain_weight | D1: log10_max_life_span | E1: log10_gestation_time | F1: brain_g_per_body_kg | G1: sleep_group | H1: body_size_class | I1: danger_group | J1: sleep_squared | K1: include_row | L1: complete_case | M1: model_seq
A2: =Clean_1_Numeric!A2 -> 1 | B2: =IF(ISNUMBER(Clean_1_Numeric!B2),LOG10(Clean_1_Numeric!B2),"") -> 3.8230828 | C2: =IF(ISNUMBER(Clean_1_Numeric!C2),LOG10(Clean_1_Numeric!C2),"") -> 3.7567882 | D2: =IF(ISNUMBER(Clean_1_Numeric!D2),LOG10(Clean_1_Numeric!D2),"") -> 1.5865873 | E2: =IF(ISNUMBER(Clean_1_Numeric!E2),LOG10(Clean_1_Numeric!E2),"") -> 2.8095597 | F2: =IF(AND(ISNUMBER(Clean_1_Numeric!B2),ISNUMBER(Clean_1_Numeric!C2)),Clean_1_Numeric!C2/Clean_1_Numeric!B2,"") -> 0.85843102 | G2: =IF(ISNUMBER(Clean_1_Numeric!I2),LOOKUP(Clean_1_Numeric!I2,sleep_lo,sleep_lbl),"") -> Short (<8h) | H2: =IF(ISNUMBER(Clean_1_Numeric!B2),LOOKUP(Clean_1_Numeric!B2,size_lo,size_lbl),"") -> Large (100+ kg) | I2: =LOOKUP(Clean_1_Numeric!H2,danger_lo,danger_lbl) -> Moderate (3) | J2: =IF(ISNUMBER(Clean_1_Numeric!I2),Clean_1_Numeric!I2^2,"") -> 10.89 | K2: =Clean_1_Numeric!P2 -> 1 | L2: =Clean_1_Numeric!N2 -> 1 | M2: =IF(L2=1,COUNTIF(L$2:L2,1),"") -> 1
A3: =Clean_1_Numeric!A3 -> 2 | B3: =IF(ISNUMBER(Clean_1_Numeric!B3),LOG10(Clean_1_Numeric!B3),"") -> 0 | C3: =IF(ISNUMBER(Clean_1_Numeric!C3),LOG10(Clean_1_Numeric!C3),"") -> 0.81954394 | D3: =IF(ISNUMBER(Clean_1_Numeric!D3),LOG10(Clean_1_Numeric!D3),"") -> 0.65321251 | E3: =IF(ISNUMBER(Clean_1_Numeric!E3),LOG10(Clean_1_Numeric!E3),"") -> 1.6232493 | F3: =IF(AND(ISNUMBER(Clean_1_Numeric!B3),ISNUMBER(Clean_1_Numeric!C3)),Clean_1_Numeric!C3/Clean_1_Numeric!B3,"") -> 6.6 | G3: =IF(ISNUMBER(Clean_1_Numeric!I3),LOOKUP(Clean_1_Numeric!I3,sleep_lo,sleep_lbl),"") -> Medium (8-12h) | H3: =IF(ISNUMBER(Clean_1_Numeric!B3),LOOKUP(Clean_1_Numeric!B3,size_lo,size_lbl),"") -> Small (1-10 kg) | I3: =LOOKUP(Clean_1_Numeric!H3,danger_lo,danger_lbl) -> Moderate (3) | J3: =IF(ISNUMBER(Clean_1_Numeric!I3),Clean_1_Numeric!I3^2,"") -> 68.89 | K3: =Clean_1_Numeric!P3 -> 1 | L3: =Clean_1_Numeric!N3 -> 1 | M3: =IF(L3=1,COUNTIF(L$2:L3,1),"") -> 2
A4: =Clean_1_Numeric!A4 -> 3 | B4: =IF(ISNUMBER(Clean_1_Numeric!B4),LOG10(Clean_1_Numeric!B4),"") -> 0.52955867 | C4: =IF(ISNUMBER(Clean_1_Numeric!C4),LOG10(Clean_1_Numeric!C4),"") -> 1.64836 | D4: =IF(ISNUMBER(Clean_1_Numeric!D4),LOG10(Clean_1_Numeric!D4),"") -> 1.146128 | E4: =IF(ISNUMBER(Clean_1_Numeric!E4),LOG10(Clean_1_Numeric!E4),"") -> 1.7781513 | F4: =IF(AND(ISNUMBER(Clean_1_Numeric!B4),ISNUMBER(Clean_1_Numeric!C4)),Clean_1_Numeric!C4/Clean_1_Numeric!B4,"") -> 13.146233 | G4: =IF(ISNUMBER(Clean_1_Numeric!I4),LOOKUP(Clean_1_Numeric!I4,sleep_lo,sleep_lbl),"") -> Long (12h+) | H4: =IF(ISNUMBER(Clean_1_Numeric!B4),LOOKUP(Clean_1_Numeric!B4,size_lo,size_lbl),"") -> Small (1-10 kg) | I4: =LOOKUP(Clean_1_Numeric!H4,danger_lo,danger_lbl) -> Low (1-2) | J4: =IF(ISNUMBER(Clean_1_Numeric!I4),Clean_1_Numeric!I4^2,"") -> 156.25 | K4: =Clean_1_Numeric!P4 -> 1 | L4: =Clean_1_Numeric!N4 -> 1 | M4: =IF(L4=1,COUNTIF(L$2:L4,1),"") -> 3
A5: =Clean_1_Numeric!A5 -> 4 | B5: =IF(ISNUMBER(Clean_1_Numeric!B5),LOG10(Clean_1_Numeric!B5),"") -> -0.036212173 | C5: =IF(ISNUMBER(Clean_1_Numeric!C5),LOG10(Clean_1_Numeric!C5),"") -> 0.75587486 | D5: =IF(ISNUMBER(Clean_1_Numeric!D5),LOG10(Clean_1_Numeric!D5),"") | E5: =IF(ISNUMBER(Clean_1_Numeric!E5),LOG10(Clean_1_Numeric!E5),"") -> 1.39794 | F5: =IF(AND(ISNUMBER(Clean_1_Numeric!B5),ISNUMBER(Clean_1_Numeric!C5)),Clean_1_Numeric!C5/Clean_1_Numeric!B5,"") -> 6.1956522 | G5: =IF(ISNUMBER(Clean_1_Numeric!I5),LOOKUP(Clean_1_Numeric!I5,sleep_lo,sleep_lbl),"") -> Long (12h+) | H5: =IF(ISNUMBER(Clean_1_Numeric!B5),LOOKUP(Clean_1_Numeric!B5,size_lo,size_lbl),"") -> Tiny (<1 kg) | I5: =LOOKUP(Clean_1_Numeric!H5,danger_lo,danger_lbl) -> Moderate (3) | J5: =IF(ISNUMBER(Clean_1_Numeric!I5),Clean_1_Numeric!I5^2,"") -> 272.25 | K5: =Clean_1_Numeric!P5 -> 1 | L5: =Clean_1_Numeric!N5 -> 0 | M5: =IF(L5=1,COUNTIF(L$2:L5,1),"")
A6: =Clean_1_Numeric!A6 -> 5 | B6: =IF(ISNUMBER(Clean_1_Numeric!B6),LOG10(Clean_1_Numeric!B6),"") -> 3.4060289 | C6: =IF(ISNUMBER(Clean_1_Numeric!C6),LOG10(Clean_1_Numeric!C6),"") -> 3.663041 | D6: =IF(ISNUMBER(Clean_1_Numeric!D6),LOG10(Clean_1_Numeric!D6),"") -> 1.8388491 | E6: =IF(ISNUMBER(Clean_1_Numeric!E6),LOG10(Clean_1_Numeric!E6),"") -> 2.7951846 | F6: =IF(AND(ISNUMBER(Clean_1_Numeric!B6),ISNUMBER(Clean_1_Numeric!C6)),Clean_1_Numeric!C6/Clean_1_Numeric!B6,"") -> 1.8072242 | G6: =IF(ISNUMBER(Clean_1_Numeric!I6),LOOKUP(Clean_1_Numeric!I6,sleep_lo,sleep_lbl),"") -> Short (<8h) | H6: =IF(ISNUMBER(Clean_1_Numeric!B6),LOOKUP(Clean_1_Numeric!B6,size_lo,size_lbl),"") -> Large (100+ kg) | I6: =LOOKUP(Clean_1_Numeric!H6,danger_lo,danger_lbl) -> High (4-5) | J6: =IF(ISNUMBER(Clean_1_Numeric!I6),Clean_1_Numeric!I6^2,"") -> 15.21 | K6: =Clean_1_Numeric!P6 -> 1 | L6: =Clean_1_Numeric!N6 -> 1 | M6: =IF(L6=1,COUNTIF(L$2:L6,1),"") -> 4
A7: =Clean_1_Numeric!A7 -> 6 | B7: =IF(ISNUMBER(Clean_1_Numeric!B7),LOG10(Clean_1_Numeric!B7),"") -> 1.0232525 | C7: =IF(ISNUMBER(Clean_1_Numeric!C7),LOG10(Clean_1_Numeric!C7),"") -> 2.2540645 | D7: =IF(ISNUMBER(Clean_1_Numeric!D7),LOG10(Clean_1_Numeric!D7),"") -> 1.4313638 | E7: =IF(ISNUMBER(Clean_1_Numeric!E7),LOG10(Clean_1_Numeric!E7),"") -> 2.2552725 | F7: =IF(AND(ISNUMBER(Clean_1_Numeric!B7),ISNUMBER(Clean_1_Numeric!C7)),Clean_1_Numeric!C7/Clean_1_Numeric!B7,"") -> 17.014218 | G7: =IF(ISNUMBER(Clean_1_Numeric!I7),LOOKUP(Clean_1_Numeric!I7,sleep_lo,sleep_lbl),"") -> Medium (8-12h) | H7: =IF(ISNUMBER(Clean_1_Numeric!B7),LOOKUP(Clean_1_Numeric!B7,size_lo,size_lbl),"") -> Medium (10-100 kg) | I7: =LOOKUP(Clean_1_Numeric!H7,danger_lo,danger_lbl) -> High (4-5) | J7: =IF(ISNUMBER(Clean_1_Numeric!I7),Clean_1_Numeric!I7^2,"") -> 96.04 | K7: =Clean_1_Numeric!P7 -> 1 | L7: =Clean_1_Numeric!N7 -> 1 | M7: =IF(L7=1,COUNTIF(L$2:L7,1),"") -> 5
A8: =Clean_1_Numeric!A8 -> 7 | B8: =IF(ISNUMBER(Clean_1_Numeric!B8),LOG10(Clean_1_Numeric!B8),"") -> -1.6382722 | C8: =IF(ISNUMBER(Clean_1_Numeric!C8),LOG10(Clean_1_Numeric!C8),"") -> -0.52287875 | D8: =IF(ISNUMBER(Clean_1_Numeric!D8),LOG10(Clean_1_Numeric!D8),"") -> 1.2787536 | E8: =IF(ISNUMBER(Clean_1_Numeric!E8),LOG10(Clean_1_Numeric!E8),"") -> 1.544068 | F8: =IF(AND(ISNUMBER(Clean_1_Numeric!B8),ISNUMBER(Clean_1_Numeric!C8)),Clean_1_Numeric!C8/Clean_1_Numeric!B8,"") -> 13.043478 | G8: =IF(ISNUMBER(Clean_1_Numeric!I8),LOOKUP(Clean_1_Numeric!I8,sleep_lo,sleep_lbl),"") -> Long (12h+) | H8: =IF(ISNUMBER(Clean_1_Numeric!B8),LOOKUP(Clean_1_Numeric!B8,size_lo,size_lbl),"") -> Tiny (<1 kg) | I8: =LOOKUP(Clean_1_Numeric!H8,danger_lo,danger_lbl) -> Low (1-2) | J8: =IF(ISNUMBER(Clean_1_Numeric!I8),Clean_1_Numeric!I8^2,"") -> 388.09 | K8: =Clean_1_Numeric!P8 -> 1 | L8: =Clean_1_Numeric!N8 -> 1 | M8: =IF(L8=1,COUNTIF(L$2:L8,1),"") -> 6
A9: =Clean_1_Numeric!A9 -> 8 | B9: =IF(ISNUMBER(Clean_1_Numeric!B9),LOG10(Clean_1_Numeric!B9),"") -> 2.20412 | C9: =IF(ISNUMBER(Clean_1_Numeric!C9),LOG10(Clean_1_Numeric!C9),"") -> 2.2278867 | D9: =IF(ISNUMBER(Clean_1_Numeric!D9),LOG10(Clean_1_Numeric!D9),"") -> 1.4828736 | E9: =IF(ISNUMBER(Clean_1_Numeric!E9),LOG10(Clean_1_Numeric!E9),"") -> 2.5932861 | F9: =IF(AND(ISNUMBER(Clean_1_Numeric!B9),ISNUMBER(Clean_1_Numeric!C9)),Clean_1_Numeric!C9/Clean_1_Numeric!B9,"") -> 1.05625 | G9: =IF(ISNUMBER(Clean_1_Numeric!I9),LOOKUP(Clean_1_Numeric!I9,sleep_lo,sleep_lbl),"") -> Short (<8h) | H9: =IF(ISNUMBER(Clean_1_Numeric!B9),LOOKUP(Clean_1_Numeric!B9,size_lo,size_lbl),"") -> Large (100+ kg) | I9: =LOOKUP(Clean_1_Numeric!H9,danger_lo,danger_lbl) -> High (4-5) | J9: =IF(ISNUMBER(Clean_1_Numeric!I9),Clean_1_Numeric!I9^2,"") -> 38.44 | K9: =Clean_1_Numeric!P9 -> 1 | L9: =Clean_1_Numeric!N9 -> 1 | M9: =IF(L9=1,COUNTIF(L$2:L9,1),"") -> 7
A10: =Clean_1_Numeric!A10 -> 9 | B10: =IF(ISNUMBER(Clean_1_Numeric!B10),LOG10(Clean_1_Numeric!B10),"") -> 0.51851394 | C10: =IF(ISNUMBER(Clean_1_Numeric!C10),LOG10(Clean_1_Numeric!C10),"") -> 1.40824 | D10: =IF(ISNUMBER(Clean_1_Numeric!D10),LOG10(Clean_1_Numeric!D10),"") -> 1.447158 | E10: =IF(ISNUMBER(Clean_1_Numeric!E10),LOG10(Clean_1_Numeric!E10),"") -> 1.7993405 | F10: =IF(AND(ISNUMBER(Clean_1_Numeric!B10),ISNUMBER(Clean_1_Numeric!C10)),Clean_1_Numeric!C10/Clean_1_Numeric!B10,"") -> 7.7575758 | G10: =IF(ISNUMBER(Clean_1_Numeric!I10),LOOKUP(Clean_1_Numeric!I10,sleep_lo,sleep_lbl),"") -> Long (12h+) | H10: =IF(ISNUMBER(Clean_1_Numeric!B10),LOOKUP(Clean_1_Numeric!B10,size_lo,size_lbl),"") -> Small (1-10 kg) | I10: =LOOKUP(Clean_1_Numeric!H10,danger_lo,danger_lbl) -> Low (1-2) | J10: =IF(ISNUMBER(Clean_1_Numeric!I10),Clean_1_Numeric!I10^2,"") -> 210.25 | K10: =Clean_1_Numeric!P10 -> 1 | L10: =Clean_1_Numeric!N10 -> 1 | M10: =IF(L10=1,COUNTIF(L$2:L10,1),"") -> 8
A11: =Clean_1_Numeric!A11 -> 10 | B11: =IF(ISNUMBER(Clean_1_Numeric!B11),LOG10(Clean_1_Numeric!B11),"") -> 1.7173376 | C11: =IF(ISNUMBER(Clean_1_Numeric!C11),LOG10(Clean_1_Numeric!C11),"") -> 2.6434527 | D11: =IF(ISNUMBER(Clean_1_Numeric!D11),LOG10(Clean_1_Numeric!D11),"") -> 1.69897 | E11: =IF(ISNUMBER(Clean_1_Numeric!E11),LOG10(Clean_1_Numeric!E11),"") -> 2.3617278 | F11: =IF(AND(ISNUMBER(Clean_1_Numeric!B11),ISNUMBER(Clean_1_Numeric!C11)),Clean_1_Numeric!C11/Clean_1_Numeric!B11,"") -> 8.4355828 | G11: =IF(ISNUMBER(Clean_1_Numeric!I11),LOOKUP(Clean_1_Numeric!I11,sleep_lo,sleep_lbl),"") -> Medium (8-12h) | H11: =IF(ISNUMBER(Clean_1_Numeric!B11),LOOKUP(Clean_1_Numeric!B11,size_lo,size_lbl),"") -> Medium (10-100 kg) | I11: =LOOKUP(Clean_1_Numeric!H11,danger_lo,danger_lbl) -> Low (1-2) | J11: =IF(ISNUMBER(Clean_1_Numeric!I11),Clean_1_Numeric!I11^2,"") -> 94.09 | K11: =Clean_1_Numeric!P11 -> 1 | L11: =Clean_1_Numeric!N11 -> 1 | M11: =IF(L11=1,COUNTIF(L$2:L11,1),"") -> 9
A12: =Clean_1_Numeric!A12 -> 11 | B12: =IF(ISNUMBER(Clean_1_Numeric!B12),LOG10(Clean_1_Numeric!B12),"") -> -0.37161107 | C12: =IF(ISNUMBER(Clean_1_Numeric!C12),LOG10(Clean_1_Numeric!C12),"") -> 0.80617997 | D12: =IF(ISNUMBER(Clean_1_Numeric!D12),LOG10(Clean_1_Numeric!D12),"") -> 0.84509804 | E12: =IF(ISNUMBER(Clean_1_Numeric!E12),LOG10(Clean_1_Numeric!E12),"") -> 2.049218 | F12: =IF(AND(ISNUMBER(Clean_1_Numeric!B12),ISNUMBER(Clean_1_Numeric!C12)),Clean_1_Numeric!C12/Clean_1_Numeric!B12,"") -> 15.058824 | G12: =IF(ISNUMBER(Clean_1_Numeric!I12),LOOKUP(Clean_1_Numeric!I12,sleep_lo,sleep_lbl),"") -> Long (12h+) | H12: =IF(ISNUMBER(Clean_1_Numeric!B12),LOOKUP(Clean_1_Numeric!B12,size_lo,size_lbl),"") -> Tiny (<1 kg) | I12: =LOOKUP(Clean_1_Numeric!H12,danger_lo,danger_lbl) -> High (4-5) | J12: =IF(ISNUMBER(Clean_1_Numeric!I12),Clean_1_Numeric!I12^2,"") -> 156.25 | K12: =Clean_1_Numeric!P12 -> 1 | L12: =Clean_1_Numeric!N12 -> 1 | M12: =IF(L12=1,COUNTIF(L$2:L12,1),"") -> 10
A13: =Clean_1_Numeric!A13 -> 12 | B13: =IF(ISNUMBER(Clean_1_Numeric!B13),LOG10(Clean_1_Numeric!B13),"") -> 2.667453 | C13: =IF(ISNUMBER(Clean_1_Numeric!C13),LOG10(Clean_1_Numeric!C13),"") -> 2.6263404 | D13: =IF(ISNUMBER(Clean_1_Numeric!D13),LOG10(Clean_1_Numeric!D13),"") -> 1.4771213 | E13: =IF(ISNUMBER(Clean_1_Numeric!E13),LOG10(Clean_1_Numeric!E13),"") -> 2.4487063 | F13: =IF(AND(ISNUMBER(Clean_1_Numeric!B13),ISNUMBER(Clean_1_Numeric!C13)),Clean_1_Numeric!C13/Clean_1_Numeric!B13,"") -> 0.90967742 | G13: =IF(ISNUMBER(Clean_1_Numeric!I13),LOOKUP(Clean_1_Numeric!I13,sleep_lo,sleep_lbl),"") -> Short (<8h) | H13: =IF(ISNUMBER(Clean_1_Numeric!B13),LOOKUP(Clean_1_Numeric!B13,size_lo,size_lbl),"") -> Large (100+ kg) | I13: =LOOKUP(Clean_1_Numeric!H13,danger_lo,danger_lbl) -> High (4-5) | J13: =IF(ISNUMBER(Clean_1_Numeric!I13),Clean_1_Numeric!I13^2,"") -> 15.21 | K13: =Clean_1_Numeric!P13 -> 1 | L13: =Clean_1_Numeric!N13 -> 1 | M13: =IF(L13=1,COUNTIF(L$2:L13,1),"") -> 11
... A63: =Clean_1_Numeric!A63 -> 62 | B63: =IF(ISNUMBER(Clean_1_Numeric!B63),LOG10(Clean_1_Numeric!B63),"") -> 0.60745502 | C63: =IF(ISNUMBER(Clean_1_Numeric!C63),LOG10(Clean_1_Numeric!C63),"") -> 1.2304489 | D63: =IF(ISNUMBER(Clean_1_Numeric!D63),LOG10(Clean_1_Numeric!D63),"") -> 1.1139434 | E63: =IF(ISNUMBER(Clean_1_Numeric!E63),LOG10(Clean_1_Numeric!E63),"") -> 1.5797836 | F63: =IF(AND(ISNUMBER(Clean_1_Numeric!B63),ISNUMBER(Clean_1_Numeric!C63)),Clean_1_Numeric!C63/Clean_1_Numeric!B63,"") -> 4.1975309 | G63: =IF(ISNUMBER(Clean_1_Numeric!I63),LOOKUP(Clean_1_Numeric!I63,sleep_lo,sleep_lbl),"") | H63: =IF(ISNUMBER(Clean_1_Numeric!B63),LOOKUP(Clean_1_Numeric!B63,size_lo,size_lbl),"") -> Small (1-10 kg) | I63: =LOOKUP(Clean_1_Numeric!H63,danger_lo,danger_lbl) -> Low (1-2) | J63: =IF(ISNUMBER(Clean_1_Numeric!I63),Clean_1_Numeric!I63^2,"") | K63: =Clean_1_Numeric!P63 -> 0 | L63: =Clean_1_Numeric!N63 -> 0 | M63: =IF(L63=1,COUNTIF(L$2:L63,1),"")

Sheet Model_Data
A1: k | B1: source_row | C1: total_sleep | D1: log10_body_weight | E1: log10_max_life_span | F1: log10_gestation_time | G1: danger_index | H1: predicted_sleep | I1: residual | J1: std_residual
A2: 1 | B2: =MATCH(A2,x_seq,0) -> 1 | C2: =INDEX(s_sleep,B2) -> 3.3 | D2: =INDEX(l_body,B2) -> 3.8230828 | E2: =INDEX(l_life,B2) -> 1.5865873 | F2: =INDEX(l_gest,B2) -> 2.8095597 | G2: =INDEX(s_danger,B2) -> 3 | H2: =m_intercept+SUMPRODUCT(m_coef,D2:G2) -> 3.8303393 | I2: =C2-H2 -> -0.53033935 | J2: =I2/m_se -> -0.18887132
A3: 2 | B3: =MATCH(A3,x_seq,0) -> 2 | C3: =INDEX(s_sleep,B3) -> 8.3 | D3: =INDEX(l_body,B3) -> 0 | E3: =INDEX(l_life,B3) -> 0.65321251 | F3: =INDEX(l_gest,B3) -> 1.6232493 | G3: =INDEX(s_danger,B3) -> 3 | H3: =m_intercept+SUMPRODUCT(m_coef,D3:G3) -> 11.086802 | I3: =C3-H3 -> -2.7868016 | J3: =I3/m_se -> -0.99247191
A4: 3 | B4: =MATCH(A4,x_seq,0) -> 3 | C4: =INDEX(s_sleep,B4) -> 12.5 | D4: =INDEX(l_body,B4) -> 0.52955867 | E4: =INDEX(l_life,B4) -> 1.146128 | F4: =INDEX(l_gest,B4) -> 1.7781513 | G4: =INDEX(s_danger,B4) -> 1 | H4: =m_intercept+SUMPRODUCT(m_coef,D4:G4) -> 13.484478 | I4: =C4-H4 -> -0.98447753 | J4: =I4/m_se -> -0.3506049
A5: 4 | B5: =MATCH(A5,x_seq,0) -> 5 | C5: =INDEX(s_sleep,B5) -> 3.9 | D5: =INDEX(l_body,B5) -> 3.4060289 | E5: =INDEX(l_life,B5) -> 1.8388491 | F5: =INDEX(l_gest,B5) -> 2.7951846 | G5: =INDEX(s_danger,B5) -> 4 | H5: =m_intercept+SUMPRODUCT(m_coef,D5:G5) -> 3.0317909 | I5: =C5-H5 -> 0.8682091 | J5: =I5/m_se -> 0.30919788
A6: 5 | B6: =MATCH(A6,x_seq,0) -> 6 | C6: =INDEX(s_sleep,B6) -> 9.8 | D6: =INDEX(l_body,B6) -> 1.0232525 | E6: =INDEX(l_life,B6) -> 1.4313638 | F6: =INDEX(l_gest,B6) -> 2.2552725 | G6: =INDEX(s_danger,B6) -> 4 | H6: =m_intercept+SUMPRODUCT(m_coef,D6:G6) -> 6.9679482 | I6: =C6-H6 -> 2.8320518 | J6: =I6/m_se -> 1.008587
A7: 6 | B7: =MATCH(A7,x_seq,0) -> 7 | C7: =INDEX(s_sleep,B7) -> 19.7 | D7: =INDEX(l_body,B7) -> -1.6382722 | E7: =INDEX(l_life,B7) -> 1.2787536 | F7: =INDEX(l_gest,B7) -> 1.544068 | G7: =INDEX(s_danger,B7) -> 1 | H7: =m_intercept+SUMPRODUCT(m_coef,D7:G7) -> 16.585814 | I7: =C7-H7 -> 3.114186 | J7: =I7/m_se -> 1.1090643
A8: 7 | B8: =MATCH(A8,x_seq,0) -> 8 | C8: =INDEX(s_sleep,B8) -> 6.2 | D8: =INDEX(l_body,B8) -> 2.20412 | E8: =INDEX(l_life,B8) -> 1.4828736 | F8: =INDEX(l_gest,B8) -> 2.5932861 | G8: =INDEX(s_danger,B8) -> 4 | H8: =m_intercept+SUMPRODUCT(m_coef,D8:G8) -> 4.6000149 | I8: =C8-H8 -> 1.5999851 | J8: =I8/m_se -> 0.56980743
A9: 8 | B9: =MATCH(A9,x_seq,0) -> 9 | C9: =INDEX(s_sleep,B9) -> 14.5 | D9: =INDEX(l_body,B9) -> 0.51851394 | E9: =INDEX(l_life,B9) -> 1.447158 | F9: =INDEX(l_gest,B9) -> 1.7993405 | G9: =INDEX(s_danger,B9) -> 1 | H9: =m_intercept+SUMPRODUCT(m_coef,D9:G9) -> 13.712807 | I9: =C9-H9 -> 0.78719272 | J9: =I9/m_se -> 0.28034527
A10: 9 | B10: =MATCH(A10,x_seq,0) -> 10 | C10: =INDEX(s_sleep,B10) -> 9.7 | D10: =INDEX(l_body,B10) -> 1.7173376 | E10: =INDEX(l_life,B10) -> 1.69897 | F10: =INDEX(l_gest,B10) -> 2.3617278 | G10: =INDEX(s_danger,B10) -> 1 | H10: =m_intercept+SUMPRODUCT(m_coef,D10:G10) -> 10.672172 | I10: =C10-H10 -> -0.97217225 | J10: =I10/m_se -> -0.34622258
A11: 10 | B11: =MATCH(A11,x_seq,0) -> 11 | C11: =INDEX(s_sleep,B11) -> 12.5 | D11: =INDEX(l_body,B11) -> -0.37161107 | E11: =INDEX(l_life,B11) -> 0.84509804 | F11: =INDEX(l_gest,B11) -> 2.049218 | G11: =INDEX(s_danger,B11) -> 4 | H11: =m_intercept+SUMPRODUCT(m_coef,D11:G11) -> 8.5087579 | I11: =C11-H11 -> 3.9912421 | J11: =I11/m_se -> 1.4214129
A12: 11 | B12: =MATCH(A12,x_seq,0) -> 12 | C12: =INDEX(s_sleep,B12) -> 3.9 | D12: =INDEX(l_body,B12) -> 2.667453 | E12: =INDEX(l_life,B12) -> 1.4771213 | F12: =INDEX(l_gest,B12) -> 2.4487063 | G12: =INDEX(s_danger,B12) -> 5 | H12: =m_intercept+SUMPRODUCT(m_coef,D12:G12) -> 3.1970432 | I12: =C12-H12 -> 0.70295679 | J12: =I12/m_se -> 0.25034608
A13: 12 | B13: =MATCH(A13,x_seq,0) -> 14 | C13: =INDEX(s_sleep,B13) -> 3.1 | D13: =INDEX(l_body,B13) -> 2.2720738 | E13: =INDEX(l_life,B13) -> 1.60206 | F13: =INDEX(l_gest,B13) -> 2.5622929 | G13: =INDEX(s_danger,B13) -> 5 | H13: =m_intercept+SUMPRODUCT(m_coef,D13:G13) -> 3.2677022 | I13: =C13-H13 -> -0.16770224 | J13: =I13/m_se -> -0.059724294
... A52: 51 | B52: =MATCH(A52,x_seq,0) -> 61 | C52: =INDEX(s_sleep,B52) -> 19.4 | D52: =INDEX(l_body,B52) -> 0.54406804 | E52: =INDEX(l_life,B52) -> 0.47712125 | F52: =INDEX(l_gest,B52) -> 1.146128 | G52: =INDEX(s_danger,B52) -> 1 | H52: =m_intercept+SUMPRODUCT(m_coef,D52:G52) -> 15.213077 | I52: =C52-H52 -> 4.1869228 | J52: =I52/m_se -> 1.4911012

Sheet Settings
A1: Settings, assumptions & workbook map
F3: Dashboard dropdown lists
A4: 1. Validation limits & test settings | F4: danger | G4: pred | H4: expo | I4: size
A5: Parameter | B5: Value | C5: Notes | F5: All | G5: All | H5: All | I5: All
A6: Minimum plausible weight (kg / g) | B6: 0.001 | C6: Smallest animal is a bat (0.005 kg) | F6: 1 | G6: 1 | H6: 1 | I6: =Settings!$C$23 -> Tiny (<1 kg)
A7: Maximum plausible body weight (kg) | B7: 20000 | C7: Assumption (largest in file 6,654 kg) | F7: 2 | G7: 2 | H7: 2 | I7: =Settings!$C$24 -> Small (1-10 kg)
A8: Maximum plausible brain weight (g) | B8: 10000 | C8: Assumption (largest 5,712 g) | F8: 3 | G8: 3 | H8: 3 | I8: =Settings!$C$25 -> Medium (10-100 kg)
A9: Maximum life span (years) | B9: 150 | C9: Assumption | F9: 4 | G9: 4 | H9: 4 | I9: =Settings!$C$26 -> Large (100+ kg)
A10: Maximum gestation (days) | B10: 1000 | C10: Assumption (largest 645) | F10: 5 | G10: 5 | H10: 5
A11: Minimum index value (1-5 scales) | B11: 1 | C11: Predation, exposure, danger
A12: Maximum index value (1-5 scales) | B12: 5 | C12: Predation, exposure, danger
A13: Maximum sleep (hours per day) | B13: 24 | C13: Physical limit
A14: Significance level (alpha) | B14: 0.05 | C14: Used for CIs and significance flags
A16: 2. Banding tables (LOOKUP lower bounds feed Clean_2_Features)
A17: Sleep groups (hours / day) | B17: Lower bound (>=) | C17: Label (auto)
A18: Short | B18: 0 | C18: =$A$18&" (<"&$B$19&"h)" -> Short (<8h)
A19: Medium | B19: 8 | C19: =$A$19&" ("&$B$19&"-"&$B$20&"h)" -> Medium (8-12h)
A20: Long | B20: 12 | C20: =$A$20&" ("&$B$20&"h+)" -> Long (12h+)
A22: Body-size classes (kg) | B22: Lower bound (>=) | C22: Label (auto)
A23: Tiny | B23: 0 | C23: =$A$23&" (<"&$B$24&" kg)" -> Tiny (<1 kg)
A24: Small | B24: 1 | C24: =$A$24&" ("&$B$24&"-"&$B$25&" kg)" -> Small (1-10 kg)
A25: Medium | B25: 10 | C25: =$A$25&" ("&$B$25&"-"&$B$26&" kg)" -> Medium (10-100 kg)
A26: Large | B26: 100 | C26: =$A$26&" ("&$B$26&"+ kg)" -> Large (100+ kg)
A28: Danger groups (danger_index) | B28: Lower bound (>=) | C28: Label (auto)
A29: Low | B29: 1 | C29: =$A$29&" ("&$B$29&"-"&($B$30-1)&")" -> Low (1-2)
A30: Moderate | B30: 3 | C30: =$A$30&" ("&$B$30&")" -> Moderate (3)
A31: High | B31: 4 | C31: =$A$31&" ("&$B$31&"-5)" -> High (4-5)

Sheet Data_Quality
A1: Data quality & cleaning report (all formulas)
A4: A. Missing data by column
A5: Column | B5: Treatment | C5: Non-missing | D5: Missing | E5: % missing | F5: "?" in Raw_Data | G5: Min | H5: Max
A6: body_weight | B6: Complete - no action | C6: =COUNT(s_body) -> 62 | D6: =ROWS(s_body)-C6 -> 0 | E6: =IF(ROWS(s_body)=0,0,D6/ROWS(s_body)) -> 0 | F6: =COUNTIF(raw_body_weight,"~?") -> 0 | G6: =MIN(s_body) -> 0.005 | H6: =MAX(s_body) -> 6654
A7: brain_weight | B7: Complete - no action | C7: =COUNT(s_brain) -> 62 | D7: =ROWS(s_brain)-C7 -> 0 | E7: =IF(ROWS(s_brain)=0,0,D7/ROWS(s_brain)) -> 0 | F7: =COUNTIF(raw_brain_weight,"~?") -> 0 | G7: =MIN(s_brain) -> 0.14 | H7: =MAX(s_brain) -> 5712
A8: max_life_span | B8: Kept as blank; excluded pairwise; excluded from regression | C8: =COUNT(s_life) -> 58 | D8: =ROWS(s_life)-C8 -> 4 | E8: =IF(ROWS(s_life)=0,0,D8/ROWS(s_life)) -> 0.064516129 | F8: =COUNTIF(raw_max_life_span,"~?") -> 4 | G8: =MIN(s_life) -> 2 | H8: =MAX(s_life) -> 100
A9: gestation_time | B9: Kept as blank; excluded pairwise; excluded from regression | C9: =COUNT(s_gest) -> 58 | D9: =ROWS(s_gest)-C9 -> 4 | E9: =IF(ROWS(s_gest)=0,0,D9/ROWS(s_gest)) -> 0.064516129 | F9: =COUNTIF(raw_gestation_time,"~?") -> 4 | G9: =MIN(s_gest) -> 12 | H9: =MAX(s_gest) -> 645
A10: predation_index | B10: Complete - no action | C10: =COUNT(s_pred) -> 62 | D10: =ROWS(s_pred)-C10 -> 0 | E10: =IF(ROWS(s_pred)=0,0,D10/ROWS(s_pred)) -> 0 | F10: =COUNTIF(raw_predation_index,"~?") -> 0 | G10: =MIN(s_pred) -> 1 | H10: =MAX(s_pred) -> 5
A11: sleep_exposure_index | B11: Complete - no action | C11: =COUNT(s_expo) -> 62 | D11: =ROWS(s_expo)-C11 -> 0 | E11: =IF(ROWS(s_expo)=0,0,D11/ROWS(s_expo)) -> 0 | F11: =COUNTIF(raw_sleep_exposure_index,"~?") -> 0 | G11: =MIN(s_expo) -> 1 | H11: =MAX(s_expo) -> 5
A12: danger_index | B12: Complete - no action | C12: =COUNT(s_danger) -> 62 | D12: =ROWS(s_danger)-C12 -> 0 | E12: =IF(ROWS(s_danger)=0,0,D12/ROWS(s_danger)) -> 0 | F12: =COUNTIF(raw_danger_index,"~?") -> 0 | G12: =MIN(s_danger) -> 1 | H12: =MAX(s_danger) -> 5
A13: total_sleep | B13: Outcome - animals without it are excluded from sleep analyses | C13: =COUNT(s_sleep) -> 58 | D13: =ROWS(s_sleep)-C13 -> 4 | E13: =IF(ROWS(s_sleep)=0,0,D13/ROWS(s_sleep)) -> 0.064516129 | F13: =COUNTIF(raw_total_sleep,"~?") -> 4 | G13: =MIN(s_sleep) -> 2.6 | H13: =MAX(s_sleep) -> 19.9
A15: B. Record-level summary
A16: Check | B16: Meaning | C16: Records | D16: % of records
A17: Total records | B17: Animals in Raw_Data | C17: =ROWS(s_body) -> 62 | D17: =IF($C$17=0,0,C17/$C$17) -> 1
A18: Rows with at least one missing value | B18: missing_count > 0 | C18: =COUNTIF(s_missing,">0") -> 11 | D18: =IF($C$17=0,0,C18/$C$17) -> 0.17741935
A19: Rows missing the outcome (total_sleep) | B19: Excluded from sleep analyses | C19: =ROWS(s_sleep)-SUM(s_hassleep) -> 4 | D19: =IF($C$17=0,0,C19/$C$17) -> 0.064516129
A20: Rows with sleep recorded | B20: Used in correlations & group analysis | C20: =SUM(s_hassleep) -> 58 | D20: =IF($C$17=0,0,C20/$C$17) -> 0.93548387
A21: Complete cases | B21: No missing value in any column - used for regression | C21: =SUM(s_complete) -> 51 | D21: =IF($C$17=0,0,C21/$C$17) -> 0.82258065
A22: Rows passing range checks | B22: All values within Settings limits | C22: =SUM(s_rangeok) -> 62 | D22: =IF($C$17=0,0,C22/$C$17) -> 1
A23: Non-numeric values that are not "?" | B23: Unexpected text - should be 0 | C23: =SUM(Clean_1_Numeric!L2:L63) -> 0 | D23: =IF($C$17=0,0,C23/$C$17) -> 0
A25: Model rows check | B25: =IF(SUM(s_complete)=ROWS(md_y),"OK - Model_Data holds every complete case","CHECK - Model_Data row count differs from complete cases") -> OK - Model_Data holds every complete case
A27: C. Skewness: why we transform
A28: Variable | B28: Decision | C28: Skew (raw) | D28: Skew (log10) | E28: Improvement
A29: body_weight | B29: =IF(ABS(C29)>1,"Log10-transform (|skew| > 1)","Keep raw") -> Log10-transform (|skew| > 1) | C29: =SKEW(s_body) -> 6.5636081 | D29: =SKEW(l_body) -> 0.1526676 | E29: =ABS(C29)-ABS(D29) -> 6.4109405
A30: brain_weight | B30: =IF(ABS(C30)>1,"Log10-transform (|skew| > 1)","Keep raw") -> Log10-transform (|skew| > 1) | C30: =SKEW(s_brain) -> 5.0715895 | D30: =SKEW(l_brain) -> 0.045626098 | E30: =ABS(C30)-ABS(D30) -> 5.0259634
A31: max_life_span | B31: =IF(ABS(C31)>1,"Log10-transform (|skew| > 1)","Keep raw") -> Log10-transform (|skew| > 1) | C31: =SKEW(s_life) -> 2.0137595 | D31: =SKEW(l_life) -> -0.17169383 | E31: =ABS(C31)-ABS(D31) -> 1.8420657
A32: gestation_time | B32: =IF(ABS(C32)>1,"Log10-transform (|skew| > 1)","Keep raw") -> Log10-transform (|skew| > 1) | C32: =SKEW(s_gest) -> 1.6835008 | D32: =SKEW(l_gest) -> 0.049883014 | E32: =ABS(C32)-ABS(D32) -> 1.6336178
A34: D. Outlier scan (Tukey 1.5 x IQR) - flagged, not removed
A35: Variable | B35: Treatment | C35: Q1 | D35: Q3 | E35: Lower fence | F35: Upper fence | G35: Below | H35: Above
A36: body_weight (kg) | B36: Flag only: real animals (e.g. elephants), retained | C36: =Descriptive_Stats!H5 -> 0.6 | D36: =Descriptive_Stats!I5 -> 48.2025 | E36: =C36-1.5*(D36-C36) -> -70.80375 | F36: =D36+1.5*(D36-C36) -> 119.60625 | G36: =COUNTIF(s_body,"<"&E36) -> 0 | H36: =COUNTIF(s_body,">"&F36) -> 10
A37: brain_weight (g) | B37: Flag only: real animals (e.g. elephants), retained | C37: =Descriptive_Stats!H6 -> 4.25 | D37: =Descriptive_Stats!I6 -> 166 | E37: =C37-1.5*(D37-C37) -> -238.375 | F37: =D37+1.5*(D37-C37) -> 408.625 | G37: =COUNTIF(s_brain,"<"&E37) -> 0 | H37: =COUNTIF(s_brain,">"&F37) -> 9
A38: max_life_span (years) | B38: Flag only: real animals (e.g. elephants), retained | C38: =Descriptive_Stats!H7 -> 6.625 | D38: =Descriptive_Stats!I7 -> 27.75 | E38: =C38-1.5*(D38-C38) -> -25.0625 | F38: =D38+1.5*(D38-C38) -> 59.4375 | G38: =COUNTIF(s_life,"<"&E38) -> 0 | H38: =COUNTIF(s_life,">"&F38) -> 2
A39: gestation_time (days) | B39: Flag only: real animals (e.g. elephants), retained | C39: =Descriptive_Stats!H8 -> 35.75 | D39: =Descriptive_Stats!I8 -> 207.5 | E39: =C39-1.5*(D39-C39) -> -221.875 | F39: =D39+1.5*(D39-C39) -> 465.125 | G39: =COUNTIF(s_gest,"<"&E39) -> 0 | H39: =COUNTIF(s_gest,">"&F39) -> 2
A40: total_sleep (h/day) | B40: Flag only: real animals (e.g. elephants), retained | C40: =Descriptive_Stats!H12 -> 8.05 | D40: =Descriptive_Stats!I12 -> 13.2 | E40: =C40-1.5*(D40-C40) -> 0.325 | F40: =D40+1.5*(D40-C40) -> 20.925 | G40: =COUNTIF(s_sleep,"<"&E40) -> 0 | H40: =COUNTIF(s_sleep,">"&F40) -> 0
A42: E. Pipeline map
A43: Clean_1_Numeric / B:I | B43: Keep numbers, turn "?" into blank
A44: Clean_1_Numeric / missing_count, placeholders | B44: Blanks per row; literal "?" found via COUNTIF "~?"
A45: Clean_1_Numeric / range_ok, include_row | B45: Limits from Settings; include = sleep present AND range ok
A46: Clean_2_Features / log10_* | B46: LOG10 of weights, life span, gestation
A47: Clean_2_Features / groups | B47: LOOKUP against Settings bands (sleep, size, danger)
...

Sheet Descriptive_Stats
A1: Descriptive statistics
A4: Variable | B4: N | C4: Missing | D4: Mean | E4: Median | F4: Std dev | G4: Min | H4: Q1 | I4: Q3 | J4: Max | K4: Skewness | L4: CV %
A5: body_weight (kg) | B5: =COUNT(s_body) -> 62 | C5: =ROWS(s_body)-B5 -> 0 | D5: =AVERAGE(s_body) -> 198.78998 | E5: =MEDIAN(s_body) -> 3.3425 | F5: =STDEV(s_body) -> 899.15801 | G5: =MIN(s_body) -> 0.005 | H5: =QUARTILE(s_body,1) -> 0.6 | I5: =QUARTILE(s_body,3) -> 48.2025 | J5: =MAX(s_body) -> 6654 | K5: =SKEW(s_body) -> 6.5636081 | L5: =IF(D5=0,0,F5/D5*100) -> 452.31555
A6: brain_weight (g) | B6: =COUNT(s_brain) -> 62 | C6: =ROWS(s_brain)-B6 -> 0 | D6: =AVERAGE(s_brain) -> 283.13419 | E6: =MEDIAN(s_brain) -> 17.25 | F6: =STDEV(s_brain) -> 930.27894 | G6: =MIN(s_brain) -> 0.14 | H6: =QUARTILE(s_brain,1) -> 4.25 | I6: =QUARTILE(s_brain,3) -> 166 | J6: =MAX(s_brain) -> 5712 | K6: =SKEW(s_brain) -> 5.0715895 | L6: =IF(D6=0,0,F6/D6*100) -> 328.56467
A7: max_life_span (years) | B7: =COUNT(s_life) -> 58 | C7: =ROWS(s_life)-B7 -> 4 | D7: =AVERAGE(s_life) -> 19.877586 | E7: =MEDIAN(s_life) -> 15.1 | F7: =STDEV(s_life) -> 18.206255 | G7: =MIN(s_life) -> 2 | H7: =QUARTILE(s_life,1) -> 6.625 | I7: =QUARTILE(s_life,3) -> 27.75 | J7: =MAX(s_life) -> 100 | K7: =SKEW(s_life) -> 2.0137595 | L7: =IF(D7=0,0,F7/D7*100) -> 91.591882
A8: gestation_time (days) | B8: =COUNT(s_gest) -> 58 | C8: =ROWS(s_gest)-B8 -> 4 | D8: =AVERAGE(s_gest) -> 142.35345 | E8: =MEDIAN(s_gest) -> 79 | F8: =STDEV(s_gest) -> 146.80504 | G8: =MIN(s_gest) -> 12 | H8: =QUARTILE(s_gest,1) -> 35.75 | I8: =QUARTILE(s_gest,3) -> 207.5 | J8: =MAX(s_gest) -> 645 | K8: =SKEW(s_gest) -> 1.6835008 | L8: =IF(D8=0,0,F8/D8*100) -> 103.12714
A9: predation_index | B9: =COUNT(s_pred) -> 62 | C9: =ROWS(s_pred)-B9 -> 0 | D9: =AVERAGE(s_pred) -> 2.8709677 | E9: =MEDIAN(s_pred) -> 3 | F9: =STDEV(s_pred) -> 1.4764143 | G9: =MIN(s_pred) -> 1 | H9: =QUARTILE(s_pred,1) -> 2 | I9: =QUARTILE(s_pred,3) -> 4 | J9: =MAX(s_pred) -> 5 | K9: =SKEW(s_pred) -> 0.22951867 | L9: =IF(D9=0,0,F9/D9*100) -> 51.425665
A10: sleep_exposure_index | B10: =COUNT(s_expo) -> 62 | C10: =ROWS(s_expo)-B10 -> 0 | D10: =AVERAGE(s_expo) -> 2.4193548 | E10: =MEDIAN(s_expo) -> 2 | F10: =STDEV(s_expo) -> 1.6047919 | G10: =MIN(s_expo) -> 1 | H10: =QUARTILE(s_expo,1) -> 1 | I10: =QUARTILE(s_expo,3) -> 4 | J10: =MAX(s_expo) -> 5 | K10: =SKEW(s_expo) -> 0.67953569 | L10: =IF(D10=0,0,F10/D10*100) -> 66.331397
A11: danger_index | B11: =COUNT(s_danger) -> 62 | C11: =ROWS(s_danger)-B11 -> 0 | D11: =AVERAGE(s_danger) -> 2.6129032 | E11: =MEDIAN(s_danger) -> 2 | F11: =STDEV(s_danger) -> 1.4412522 | G11: =MIN(s_danger) -> 1 | H11: =QUARTILE(s_danger,1) -> 1 | I11: =QUARTILE(s_danger,3) -> 4 | J11: =MAX(s_danger) -> 5 | K11: =SKEW(s_danger) -> 0.37765588 | L11: =IF(D11=0,0,F11/D11*100) -> 55.159034
A12: total_sleep (h/day) | B12: =COUNT(s_sleep) -> 58 | C12: =ROWS(s_sleep)-B12 -> 4 | D12: =AVERAGE(s_sleep) -> 10.532759 | E12: =MEDIAN(s_sleep) -> 10.45 | F12: =STDEV(s_sleep) -> 4.6067604 | G12: =MIN(s_sleep) -> 2.6 | H12: =QUARTILE(s_sleep,1) -> 8.05 | I12: =QUARTILE(s_sleep,3) -> 13.2 | J12: =MAX(s_sleep) -> 19.9 | K12: =SKEW(s_sleep) -> 0.20124524 | L12: =IF(D12=0,0,F12/D12*100) -> 43.737453
A13: log10 body_weight | B13: =COUNT(l_body) -> 62 | C13: =ROWS(l_body)-B13 -> 0 | D13: =AVERAGE(l_body) -> 0.58088579 | E13: =MEDIAN(l_body) -> 0.52403631 | F13: =STDEV(l_body) -> 1.3563571 | G13: =MIN(l_body) -> -2.30103 | H13: =QUARTILE(l_body,1) -> -0.22596267 | I13: =QUARTILE(l_body,3) -> 1.6780695 | J13: =MAX(l_body) -> 3.8230828 | K13: =SKEW(l_body) -> 0.1526676 | L13: =IF(D13=0,0,F13/D13*100) -> 233.49807
A14: log10 brain_weight | B14: =COUNT(l_brain) -> 62 | C14: =ROWS(l_brain)-B14 -> 0 | D14: =AVERAGE(l_brain) -> 1.3637706 | E14: =MEDIAN(l_brain) -> 1.2367435 | F14: =STDEV(l_brain) -> 1.0625067 | G14: =MIN(l_brain) -> -0.85387196 | H14: =QUARTILE(l_brain,1) -> 0.62628749 | I14: =QUARTILE(l_brain,3) -> 2.2198899 | J14: =MAX(l_brain) -> 3.7567882 | K14: =SKEW(l_brain) -> 0.045626098 | L14: =IF(D14=0,0,F14/D14*100) -> 77.909484
A15: log10 max_life_span | B15: =COUNT(l_life) -> 58 | C15: =ROWS(l_life)-B15 -> 4 | D15: =AVERAGE(l_life) -> 1.126151 | E15: =MEDIAN(l_life) -> 1.1778215 | F15: =STDEV(l_life) -> 0.40976316 | G15: =MIN(l_life) -> 0.30103 | H15: =QUARTILE(l_life,1) -> 0.82095953 | I15: =QUARTILE(l_life,3) -> 1.4432095 | J15: =MAX(l_life) -> 2 | K15: =SKEW(l_life) -> -0.17169383 | L15: =IF(D15=0,0,F15/D15*100) -> 36.386163
A16: log10 gestation_time | B16: =COUNT(l_gest) -> 58 | C16: =ROWS(l_gest)-B16 -> 4 | D16: =AVERAGE(l_gest) -> 1.9300876 | E16: =MEDIAN(l_gest) -> 1.8933757 | F16: =STDEV(l_gest) -> 0.46046146 | G16: =MIN(l_gest) -> 1.0791812 | H16: =QUARTILE(l_gest,1) -> 1.5529969 | I16: =QUARTILE(l_gest,3) -> 2.316922 | J16: =MAX(l_gest) -> 2.8095597 | K16: =SKEW(l_gest) -> 0.049883014 | L16: =IF(D16=0,0,F16/D16*100) -> 23.857024
A17: brain g per body kg | B17: =COUNT(x_ratio) -> 62 | C17: =ROWS(x_ratio)-B17 -> 0 | D17: =AVERAGE(x_ratio) -> 9.6242136 | E17: =MEDIAN(x_ratio) -> 6.6108564 | F17: =STDEV(x_ratio) -> 8.9150449 | G17: =MIN(x_ratio) -> 0.85843102 | H17: =QUARTILE(x_ratio,1) -> 3.102574 | I17: =QUARTILE(x_ratio,3) -> 13.66842 | J17: =MAX(x_ratio) -> 39.60396 | K17: =SKEW(x_ratio) -> 1.3483686 | L17: =IF(D17=0,0,F17/D17*100) -> 92.631411
A22: Distribution of total sleep (all animals with sleep recorded)
A23: Bin (hours) | B23: From (>=) | C23: To (<) | D23: Animals | E23: % of animals
A24: 2-4 h | B24: 2 | C24: 4 | D24: =COUNTIFS(s_sleep,">="&B24,s_sleep,"<"&C24) -> 8 | E24: =IF(SUM($D$24:$D$32)=0,0,D24/SUM($D$24:$D$32)) -> 0.13793103
A25: 4-6 h | B25: 4 | C25: 6 | D25: =COUNTIFS(s_sleep,">="&B25,s_sleep,"<"&C25) -> 2 | E25: =IF(SUM($D$24:$D$32)=0,0,D25/SUM($D$24:$D$32)) -> 0.034482759
A26: 6-8 h | B26: 6 | C26: 8 | D26: =COUNTIFS(s_sleep,">="&B26,s_sleep,"<"&C26) -> 4 | E26: =IF(SUM($D$24:$D$32)=0,0,D26/SUM($D$24:$D$32)) -> 0.068965517
A27: 8-10 h | B27: 8 | C27: 10 | D27: =COUNTIFS(s_sleep,">="&B27,s_sleep,"<"&C27) -> 12 | E27: =IF(SUM($D$24:$D$32)=0,0,D27/SUM($D$24:$D$32)) -> 0.20689655
A28: 10-12 h | B28: 10 | C28: 12 | D28: =COUNTIFS(s_sleep,">="&B28,s_sleep,"<"&C28) -> 10 | E28: =IF(SUM($D$24:$D$32)=0,0,D28/SUM($D$24:$D$32)) -> 0.17241379
A29: 12-14 h | B29: 12 | C29: 14 | D29: =COUNTIFS(s_sleep,">="&B29,s_sleep,"<"&C29) -> 11 | E29: =IF(SUM($D$24:$D$32)=0,0,D29/SUM($D$24:$D$32)) -> 0.18965517
A30: 14-16 h | B30: 14 | C30: 16 | D30: =COUNTIFS(s_sleep,">="&B30,s_sleep,"<"&C30) -> 3 | E30: =IF(SUM($D$24:$D$32)=0,0,D30/SUM($D$24:$D$32)) -> 0.051724138
A31: 16-18 h | B31: 16 | C31: 18 | D31: =COUNTIFS(s_sleep,">="&B31,s_sleep,"<"&C31) -> 3 | E31: =IF(SUM($D$24:$D$32)=0,0,D31/SUM($D$24:$D$32)) -> 0.051724138
A32: 18-20 h | B32: 18 | C32: 20.01 | D32: =COUNTIFS(s_sleep,">="&B32,s_sleep,"<"&C32) -> 5 | E32: =IF(SUM($D$24:$D$32)=0,0,D32/SUM($D$24:$D$32)) -> 0.086206897

Sheet Correlation
A1: Correlation with total sleep (hours / day)
A2: Pairwise Pearson r on available values. Log10 versions are used for the skewed measurements. Negative r = more of the variable, less sleep.
A3: Strength thresholds (|r| >=): | B3: Very strong | C3: 0.7 | D3: Strong | E3: 0.5 | F3: Moderate | G3: 0.3 | H3: Weak | I3: 0.1
K4: Variables ranked by |r|
A5: Variable | B5: Pairs (n) | C5: r with sleep | D5: |r| | E5: Rank | F5: Direction | G5: Strength | H5: t-stat | I5: p-value | J5: Sig. | K5: Rank | L5: Variable | M5: r | N5: Strength
A6: body_weight (kg) | B6: =SUMPRODUCT(ISNUMBER(s_body)*ISNUMBER(s_sleep)) -> 58 | C6: =CORREL(s_body,s_sleep) -> -0.30718591 | D6: =ABS(C6) -> 0.30718591 | E6: =RANK(D6,$D$6:$D$16)+COUNTIF($D$5:D5,D6) -> 11 | F6: =IF(C6>0,"More sleep","Less sleep") -> Less sleep | G6: =IF(D6>=thr_vs,"Very strong",IF(D6>=thr_s,"Strong",IF(D6>=thr_m,"Moderate",IF(D6>=thr_w,"Weak","Negligible")))) -> Moderate | H6: =C6*SQRT((B6-2)/(1-C6^2)) -> -2.4155625 | I6: =TDIST(ABS(H6),B6-2,2) -> 0.01899885 | J6: =IF(I6<0.001,"***",IF(I6<0.01,"**",IF(I6<alpha,"*","ns"))) -> * | K6: 1 | L6: =INDEX($A$6:$A$16,MATCH(K6,$E$6:$E$16,0)) -> log10 gestation_time | M6: =INDEX($C$6:$C$16,MATCH(K6,$E$6:$E$16,0)) -> -0.66365599 | N6: =INDEX($G$6:$G$16,MATCH(K6,$E$6:$E$16,0)) -> Strong
A7: brain_weight (g) | B7: =SUMPRODUCT(ISNUMBER(s_brain)*ISNUMBER(s_sleep)) -> 58 | C7: =CORREL(s_brain,s_sleep) -> -0.35810203 | D7: =ABS(C7) -> 0.35810203 | E7: =RANK(D7,$D$6:$D$16)+COUNTIF($D$5:D6,D7) -> 10 | F7: =IF(C7>0,"More sleep","Less sleep") -> Less sleep | G7: =IF(D7>=thr_vs,"Very strong",IF(D7>=thr_s,"Strong",IF(D7>=thr_m,"Moderate",IF(D7>=thr_w,"Weak","Negligible")))) -> Moderate | H7: =C7*SQRT((B7-2)/(1-C7^2)) -> -2.8701302 | I7: =TDIST(ABS(H7),B7-2,2) -> 0.0057795312 | J7: =IF(I7<0.001,"***",IF(I7<0.01,"**",IF(I7<alpha,"*","ns"))) -> ** | K7: 2 | L7: =INDEX($A$6:$A$16,MATCH(K7,$E$6:$E$16,0)) -> sleep_exposure_index | M7: =INDEX($C$6:$C$16,MATCH(K7,$E$6:$E$16,0)) -> -0.64228451 | N7: =INDEX($G$6:$G$16,MATCH(K7,$E$6:$E$16,0)) -> Strong
A8: max_life_span (years) | B8: =SUMPRODUCT(ISNUMBER(s_life)*ISNUMBER(s_sleep)) -> 54 | C8: =CORREL(s_life,s_sleep) -> -0.41020239 | D8: =ABS(C8) -> 0.41020239 | E8: =RANK(D8,$D$6:$D$16)+COUNTIF($D$5:D7,D8) -> 8 | F8: =IF(C8>0,"More sleep","Less sleep") -> Less sleep | G8: =IF(D8>=thr_vs,"Very strong",IF(D8>=thr_s,"Strong",IF(D8>=thr_m,"Moderate",IF(D8>=thr_w,"Weak","Negligible")))) -> Moderate | H8: =C8*SQRT((B8-2)/(1-C8^2)) -> -3.2434532 | I8: =TDIST(ABS(H8),B8-2,2) -> 0.0020655491 | J8: =IF(I8<0.001,"***",IF(I8<0.01,"**",IF(I8<alpha,"*","ns"))) -> ** | K8: 3 | L8: =INDEX($A$6:$A$16,MATCH(K8,$E$6:$E$16,0)) -> gestation_time (days) | M8: =INDEX($C$6:$C$16,MATCH(K8,$E$6:$E$16,0)) -> -0.6313262 | N8: =INDEX($G$6:$G$16,MATCH(K8,$E$6:$E$16,0)) -> Strong
A9: gestation_time (days) | B9: =SUMPRODUCT(ISNUMBER(s_gest)*ISNUMBER(s_sleep)) -> 54 | C9: =CORREL(s_gest,s_sleep) -> -0.6313262 | D9: =ABS(C9) -> 0.6313262 | E9: =RANK(D9,$D$6:$D$16)+COUNTIF($D$5:D8,D9) -> 3 | F9: =IF(C9>0,"More sleep","Less sleep") -> Less sleep | G9: =IF(D9>=thr_vs,"Very strong",IF(D9>=thr_s,"Strong",IF(D9>=thr_m,"Moderate",IF(D9>=thr_w,"Weak","Negligible")))) -> Strong | H9: =C9*SQRT((B9-2)/(1-C9^2)) -> -5.8703493 | I9: =TDIST(ABS(H9),B9-2,2) -> 3.0827943e-07 | J9: =IF(I9<0.001,"***",IF(I9<0.01,"**",IF(I9<alpha,"*","ns"))) -> *** | K9: 4 | L9: =INDEX($A$6:$A$16,MATCH(K9,$E$6:$E$16,0)) -> danger_index | M9: =INDEX($C$6:$C$16,MATCH(K9,$E$6:$E$16,0)) -> -0.58774241 | N9: =INDEX($G$6:$G$16,MATCH(K9,$E$6:$E$16,0)) -> Strong
A10: predation_index | B10: =SUMPRODUCT(ISNUMBER(s_pred)*ISNUMBER(s_sleep)) -> 58 | C10: =CORREL(s_pred,s_sleep) -> -0.39583497 | D10: =ABS(C10) -> 0.39583497 | E10: =RANK(D10,$D$6:$D$16)+COUNTIF($D$5:D9,D10) -> 9 | F10: =IF(C10>0,"More sleep","Less sleep") -> Less sleep | G10: =IF(D10>=thr_vs,"Very strong",IF(D10>=thr_s,"Strong",IF(D10>=thr_m,"Moderate",IF(D10>=thr_w,"Weak","Negligible")))) -> Moderate | H10: =C10*SQRT((B10-2)/(1-C10^2)) -> -3.2256211 | I10: =TDIST(ABS(H10),B10-2,2) -> 0.0021004323 | J10: =IF(I10<0.001,"***",IF(I10<0.01,"**",IF(I10<alpha,"*","ns"))) -> ** | K10: 5 | L10: =INDEX($A$6:$A$16,MATCH(K10,$E$6:$E$16,0)) -> log10 brain_weight | M10: =INDEX($C$6:$C$16,MATCH(K10,$E$6:$E$16,0)) -> -0.56259577 | N10: =INDEX($G$6:$G$16,MATCH(K10,$E$6:$E$16,0)) -> Strong
A11: sleep_exposure_index | B11: =SUMPRODUCT(ISNUMBER(s_expo)*ISNUMBER(s_sleep)) -> 58 | C11: =CORREL(s_expo,s_sleep) -> -0.64228451 | D11: =ABS(C11) -> 0.64228451 | E11: =RANK(D11,$D$6:$D$16)+COUNTIF($D$5:D10,D11) -> 2 | F11: =IF(C11>0,"More sleep","Less sleep") -> Less sleep | G11: =IF(D11>=thr_vs,"Very strong",IF(D11>=thr_s,"Strong",IF(D11>=thr_m,"Moderate",IF(D11>=thr_w,"Weak","Negligible")))) -> Strong | H11: =C11*SQRT((B11-2)/(1-C11^2)) -> -6.2708785 | I11: =TDIST(ABS(H11),B11-2,2) -> 5.4915611e-08 | J11: =IF(I11<0.001,"***",IF(I11<0.01,"**",IF(I11<alpha,"*","ns"))) -> *** | K11: 6 | L11: =INDEX($A$6:$A$16,MATCH(K11,$E$6:$E$16,0)) -> log10 body_weight | M11: =INDEX($C$6:$C$16,MATCH(K11,$E$6:$E$16,0)) -> -0.5328345 | N11: =INDEX($G$6:$G$16,MATCH(K11,$E$6:$E$16,0)) -> Strong
A12: danger_index | B12: =SUMPRODUCT(ISNUMBER(s_danger)*ISNUMBER(s_sleep)) -> 58 | C12: =CORREL(s_danger,s_sleep) -> -0.58774241 | D12: =ABS(C12) -> 0.58774241 | E12: =RANK(D12,$D$6:$D$16)+COUNTIF($D$5:D11,D12) -> 4 | F12: =IF(C12>0,"More sleep","Less sleep") -> Less sleep | G12: =IF(D12>=thr_vs,"Very strong",IF(D12>=thr_s,"Strong",IF(D12>=thr_m,"Moderate",IF(D12>=thr_w,"Weak","Negligible")))) -> Strong | H12: =C12*SQRT((B12-2)/(1-C12^2)) -> -5.4363409 | I12: =TDIST(ABS(H12),B12-2,2) -> 1.2304663e-06 | J12: =IF(I12<0.001,"***",IF(I12<0.01,"**",IF(I12<alpha,"*","ns"))) -> *** | K12: 7 | L12: =INDEX($A$6:$A$16,MATCH(K12,$E$6:$E$16,0)) -> log10 max_life_span | M12: =INDEX($C$6:$C$16,MATCH(K12,$E$6:$E$16,0)) -> -0.42994087 | N12: =INDEX($G$6:$G$16,MATCH(K12,$E$6:$E$16,0)) -> Moderate
A13: log10 body_weight | B13: =SUMPRODUCT(ISNUMBER(l_body)*ISNUMBER(s_sleep)) -> 58 | C13: =CORREL(l_body,s_sleep) -> -0.5328345 | D13: =ABS(C13) -> 0.5328345 | E13: =RANK(D13,$D$6:$D$16)+COUNTIF($D$5:D12,D13) -> 6 | F13: =IF(C13>0,"More sleep","Less sleep") -> Less sleep | G13: =IF(D13>=thr_vs,"Very strong",IF(D13>=thr_s,"Strong",IF(D13>=thr_m,"Moderate",IF(D13>=thr_w,"Weak","Negligible")))) -> Strong | H13: =C13*SQRT((B13-2)/(1-C13^2)) -> -4.7119789 | I13: =TDIST(ABS(H13),B13-2,2) -> 1.6639439e-05 | J13: =IF(I13<0.001,"***",IF(I13<0.01,"**",IF(I13<alpha,"*","ns"))) -> *** | K13: 8 | L13: =INDEX($A$6:$A$16,MATCH(K13,$E$6:$E$16,0)) -> max_life_span (years) | M13: =INDEX($C$6:$C$16,MATCH(K13,$E$6:$E$16,0)) -> -0.41020239 | N13: =INDEX($G$6:$G$16,MATCH(K13,$E$6:$E$16,0)) -> Moderate
A14: log10 brain_weight | B14: =SUMPRODUCT(ISNUMBER(l_brain)*ISNUMBER(s_sleep)) -> 58 | C14: =CORREL(l_brain,s_sleep) -> -0.56259577 | D14: =ABS(C14) -> 0.56259577 | E14: =RANK(D14,$D$6:$D$16)+COUNTIF($D$5:D13,D14) -> 5 | F14: =IF(C14>0,"More sleep","Less sleep") -> Less sleep | G14: =IF(D14>=thr_vs,"Very strong",IF(D14>=thr_s,"Strong",IF(D14>=thr_m,"Moderate",IF(D14>=thr_w,"Weak","Negligible")))) -> Strong | H14: =C14*SQRT((B14-2)/(1-C14^2)) -> -5.092437 | I14: =TDIST(ABS(H14),B14-2,2) -> 4.297493e-06 | J14: =IF(I14<0.001,"***",IF(I14<0.01,"**",IF(I14<alpha,"*","ns"))) -> *** | K14: 9 | L14: =INDEX($A$6:$A$16,MATCH(K14,$E$6:$E$16,0)) -> predation_index | M14: =INDEX($C$6:$C$16,MATCH(K14,$E$6:$E$16,0)) -> -0.39583497 | N14: =INDEX($G$6:$G$16,MATCH(K14,$E$6:$E$16,0)) -> Moderate
A15: log10 max_life_span | B15: =SUMPRODUCT(ISNUMBER(l_life)*ISNUMBER(s_sleep)) -> 54 | C15: =CORREL(l_life,s_sleep) -> -0.42994087 | D15: =ABS(C15) -> 0.42994087 | E15: =RANK(D15,$D$6:$D$16)+COUNTIF($D$5:D14,D15) -> 7 | F15: =IF(C15>0,"More sleep","Less sleep") -> Less sleep | G15: =IF(D15>=thr_vs,"Very strong",IF(D15>=thr_s,"Strong",IF(D15>=thr_m,"Moderate",IF(D15>=thr_w,"Weak","Negligible")))) -> Moderate | H15: =C15*SQRT((B15-2)/(1-C15^2)) -> -3.4339297 | I15: =TDIST(ABS(H15),B15-2,2) -> 0.0011758494 | J15: =IF(I15<0.001,"***",IF(I15<0.01,"**",IF(I15<alpha,"*","ns"))) -> ** | K15: 10 | L15: =INDEX($A$6:$A$16,MATCH(K15,$E$6:$E$16,0)) -> brain_weight (g) | M15: =INDEX($C$6:$C$16,MATCH(K15,$E$6:$E$16,0)) -> -0.35810203 | N15: =INDEX($G$6:$G$16,MATCH(K15,$E$6:$E$16,0)) -> Moderate
