Workbook

Sheet Sheet1
A1: SHEET 2 — CLEANED & NUMERIC DATA (All textual responses converted to numbers)
A2: Gender | B2: Male=1, Female=2
A3: School Location | B3: Abu Dhabi=1, Dubai=2, Sharjah=3, Ajman/Other=4
A4: Q4 Daily SM Hours | B4: <1hr=1, 1-2hrs=2, 3-4hrs=3, 5-6hrs=4, 7+hrs=5
A5: Q5 Check School | B5: Never=1, Rarely=2, Sometimes=3, Often=4, Very Often=5
A6: Q6 Multitask | B6: Never=1, Rarely=2, Sometimes=3, Often=4, Always=5
A7: Q7 Platform | B7: TikTok=1, Instagram=2, Snapchat=3, YouTube Shorts=4, Other=5
A8: Q8–Q10, Q12 | B8: Strongly Disagree=1 … Strongly Agree=5
A9: Q11 | B9: Strongly Disagree=1 … Strongly Agree=5 [REVERSED for disruption score]
A10: Q13 Overall Grade | B10: Below 60%=1, 60-69%=2, 70-79%=3, 80-89%=4, 90-100%=5
A11: Q14 Subjects | B11: 1=Much below average … 5=Much above average
A12: Q15 Performance Change | B12: Improved significantly=1 … Declined significantly=5
A13: Q16 SM Affects Grades | B13: Yes definitely=1, Yes somewhat=2, No not really=3, No helps me=4
A16: Resp. # | B16: Gender (1=M, 2=F) | C16: Grade | D16: School Location (1–4) | E16: Q4 Daily SM Hours | F16: Q5 Check During School | G16: Q6 Multitask Study | H16: Q7 Platform | I16: Q8 Difficult Focus | J16: Q9 Stop-Check Phone | K16: Q10 Lose Track Time | L16: Q11 Can Concentrate | M16: Q12 Parents-Teachers Note | N16: Q13 Overall Grade | O16: Q14 Math | P16: Q14 Science | Q16: Q14 English | R16: Q14 Arabic | S16: Q15 Performance Change | T16: Q16 SM Affects Grades | U16: Q11 Reversed | V16: Concentration Disruption Score
A17: 1 | B17: 1 | C17: 10 | D17: 2 | E17: 4 | F17: 4 | G17: 4 | H17: 1 | I17: 4 | J17: 4 | K17: 5 | L17: 2 | M17: 4 | N17: 2 | O17: 2 | P17: 3 | Q17: 3 | R17: 2 | S17: 4 | T17: 2 | U17: 4 | V17: 4.2
A18: 2 | B18: 2 | C18: 11 | D18: 1 | E18: 3 | F18: 3 | G18: 3 | H18: 2 | I18: 3 | J18: 4 | K18: 4 | L18: 3 | M18: 3 | N18: 3 | O18: 3 | P18: 3 | Q18: 4 | R18: 3 | S18: 3 | T18: 2 | U18: 3 | V18: 3.4
A19: 3 | B19: 1 | C19: 9 | D19: 3 | E19: 5 | F19: 5 | G19: 5 | H19: 1 | I19: 5 | J19: 5 | K19: 5 | L19: 1 | M19: 5 | N19: 1 | O19: 1 | P19: 2 | Q19: 2 | R19: 1 | S19: 5 | T19: 1 | U19: 5 | V19: 5
A20: 4 | B20: 2 | C20: 12 | D20: 2 | E20: 3 | F20: 3 | G20: 2 | H20: 1 | I20: 3 | J20: 3 | K20: 4 | L20: 3 | M20: 3 | N20: 4 | O20: 4 | P20: 4 | Q20: 4 | R20: 3 | S20: 3 | T20: 2 | U20: 3 | V20: 3.2
A21: 5 | B21: 1 | C21: 10 | D21: 1 | E21: 4 | F21: 4 | G21: 4 | H21: 3 | I21: 4 | J21: 4 | K21: 4 | L21: 2 | M21: 4 | N21: 2 | O21: 2 | P21: 3 | Q21: 3 | R21: 2 | S21: 4 | T21: 2 | U21: 4 | V21: 4
A22: 6 | B22: 2 | C22: 9 | D22: 2 | E22: 2 | F22: 2 | G22: 2 | H22: 2 | I22: 2 | J22: 2 | K22: 3 | L22: 4 | M22: 2 | N22: 4 | O22: 4 | P22: 4 | Q22: 4 | R22: 2 | S22: 2 | T22: 3 | U22: 2 | V22: 2.2
A23: 7 | B23: 1 | C23: 11 | D23: 3 | E23: 5 | F23: 5 | G23: 5 | H23: 1 | I23: 5 | J23: 5 | K23: 5 | L23: 1 | M23: 5 | N23: 1 | O23: 1 | P23: 2 | Q23: 2 | R23: 1 | S23: 5 | T23: 1 | U23: 5 | V23: 5
A24: 8 | B24: 2 | C24: 10 | D24: 2 | E24: 3 | F24: 3 | G24: 3 | H24: 1 | I24: 3 | J24: 3 | K24: 3 | L24: 3 | M24: 3 | N24: 3 | O24: 3 | P24: 4 | Q24: 3 | R24: 3 | S24: 3 | T24: 2 | U24: 3 | V24: 3
A25: 9 | B25: 1 | C25: 12 | D25: 1 | E25: 4 | F25: 4 | G25: 4 | H25: 2 | I25: 4 | J25: 4 | K25: 5 | L25: 2 | M25: 4 | N25: 2 | O25: 2 | P25: 3 | Q25: 2 | R25: 2 | S25: 4 | T25: 2 | U25: 4 | V25: 4.2
A26: 10 | B26: 2 | C26: 11 | D26: 2 | E26: 2 | F26: 2 | G26: 2 | H26: 2 | I26: 2 | J26: 2 | K26: 3 | L26: 4 | M26: 2 | N26: 4 | O26: 4 | P26: 4 | Q26: 4 | R26: 2 | S26: 2 | T26: 3 | U26: 2 | V26: 2.2
A27: 11 | B27: 1 | C27: 12 | D27: 4 | E27: 2 | F27: 1 | G27: 1 | H27: 1 | I27: 1 | J27: 2 | K27: 3 | L27: 3 | M27: 2 | N27: 4 | O27: 5 | P27: 5 | Q27: 3 | R27: 5 | S27: 3 | T27: 2 | U27: 3 | V27: 2.2
A28: 12 | B28: 1 | C28: 11 | D28: 4 | E28: 3 | F28: 3 | G28: 4 | H28: 1 | I28: 4 | J28: 2 | K28: 4 | L28: 4 | M28: 2 | N28: 4 | O28: 5 | P28: 4 | Q28: 5 | R28: 4 | S28: 2 | T28: 3 | U28: 2 | V28: 2.8
... A112: 96 | B112: 2 | C112: 12 | D112: 3 | E112: 3 | F112: 3 | G112: 2 | H112: 5 | I112: 3 | J112: 2 | K112: 2 | L112: 3 | M112: 4 | N112: 3 | O112: 4 | P112: 3 | Q112: 4 | R112: 3 | S112: 2 | T112: 3 | U112: 3 | V112: 2.8
A114: Gender | B114: Male=1, Female=2
A115: School Location | B115: Abu Dhabi=1, Dubai=2, Sharjah=3, Ajman/Other=4
A116: Q4 Daily SM Hours | B116: <1hr=1, 1-2hrs=2, 3-4hrs=3, 5-6hrs=4, 7+hrs=5
A117: Q5 Check School | B117: Never=1, Rarely=2, Sometimes=3, Often=4, Very Often=5
A118: Q6 Multitask | B118: Never=1, Rarely=2, Sometimes=3, Often=4, Always=5
A119: Q7 Platform | B119: TikTok=1, Instagram=2, Snapchat=3, YouTube Shorts=4, Other=5
A120: Q8–Q10, Q12 | B120: Strongly Disagree=1 … Strongly Agree=5
A121: Q11 | B121: Strongly Disagree=1 … Strongly Agree=5 [REVERSED for disruption score]
A122: Q13 Overall Grade | B122: Below 60%=1, 60-69%=2, 70-79%=3, 80-89%=4, 90-100%=5
A123: Q14 Subjects | B123: 1=Much below average … 5=Much above average
A124: Q15 Performance Change | B124: Improved significantly=1 … Declined significantly=5
A125: Q16 SM Affects Grades | B125: Yes definitely=1, Yes somewhat=2, No not really=3, No helps me=4

Sheet Sheet2_Descriptives
A1: Gender
A2: Description | B2: Formula
A3: Count of Males (1) | B3: =COUNTIF(Sheet1!$B$17:$B$112, 1) -> 49
A4: Count of Females (2) | B4: =COUNTIF(Sheet1!$B$17:$B$112, 2) -> 47
A5: Total respondents | B5: =COUNTA(Sheet1!$B$17:$B$112) -> 96
A6: Percentage Male | B6: =COUNTIF(Sheet1!$B$17:$B$112, 1)/COUNTA(Sheet1!$B$17:$B$112) -> 0.51041667
A7: Percentage Female | B7: =COUNTIF(Sheet1!$B$17:$B$112, 2)/COUNTA(Sheet1!$B$17:$B$112) -> 0.48958333
A10: Grade
A11: Description | B11: Formula
A12: Count of Grade 9 | B12: =COUNTIF(Sheet1!$C$17:$C$112, 9) -> 17
A13: Count of Grade 10 | B13: =COUNTIF(Sheet1!$C$17:$C$112, 10) -> 26
A14: Count of Grade 11 | B14: =COUNTIF(Sheet1!$C$17:$C$112, 11) -> 24
A15: Count of Grade 12 | B15: =COUNTIF(Sheet1!$C$17:$C$112, 12) -> 29
A16: Total respondents | B16: =COUNTA(Sheet1!$C$17:$C$112) -> 96
A17: Percentage Grade 9 | B17: =COUNTIF(Sheet1!$C$17:$C$112, 9)/COUNTA(Sheet1!$C$17:$C$112) -> 0.17708333
A18: Percentage Grade 10 | B18: =COUNTIF(Sheet1!$C$17:$C$112, 10)/COUNTA(Sheet1!$C$17:$C$112) -> 0.27083333
A19: Percentage Grade 11 | B19: =COUNTIF(Sheet1!$C$17:$C$112, 11)/COUNTA(Sheet1!$C$17:$C$112) -> 0.25
A20: Percentage Grade 12 | B20: =COUNTIF(Sheet1!$C$17:$C$112, 12)/COUNTA(Sheet1!$C$17:$C$112) -> 0.30208333
A22: School
A23: Description | B23: Formula
A24: Count of Abu Dhabi (1) | B24: =COUNTIF(Sheet1!$D$17:$D$112, 1) -> 25
A25: Count of Dubai (2) | B25: =COUNTIF(Sheet1!$D$17:$D$112, 2) -> 25
A26: Count of Sharjah (3) | B26: =COUNTIF(Sheet1!$D$17:$D$112, 3) -> 26
A27: Count of Other (4) | B27: =COUNTIF(Sheet1!$D$17:$D$112, 4) -> 20
A28: Total respondents | B28: =COUNTA(Sheet1!$D$17:$D$112) -> 96
A29: Percentage Abu Dhabi | B29: =COUNTIF(Sheet1!$D$17:$D$112, 1)/COUNTA(Sheet1!$D$17:$D$112) -> 0.26041667
A30: Percentage Dubai | B30: =COUNTIF(Sheet1!$D$17:$D$112, 2)/COUNTA(Sheet1!$D$17:$D$112) -> 0.26041667
A31: Percentage Sharjah | B31: =COUNTIF(Sheet1!$D$17:$D$112, 3)/COUNTA(Sheet1!$D$17:$D$112) -> 0.27083333
A32: Percentage Other | B32: =COUNTIF(Sheet1!$D$17:$D$112, 4)/COUNTA(Sheet1!$D$17:$D$112) -> 0.20833333

Sheet Sheet3_Correlation
A1: Q4_Daily_Hours | B1: Q13_Overall_Grade | E1: Q4_Daily_Hours | F1: Q13_Overall_Grade | G1: r (correlation) | H1: =CORREL(Sheet3_Correlation!$A$2:$A$97, Sheet3_Correlation!$B$2:$B$97) -> -0.83467788
A2: =Sheet1!E17 -> 4 | B2: =Sheet1!N17 -> 2 | D2: Q4_Daily_Hours | E2: 1
A3: =Sheet1!E18 -> 3 | B3: =Sheet1!N18 -> 3 | D3: Q13_Overall_Grade | E3: -0.83467788 | F3: 1
A4: =Sheet1!E19 -> 5 | B4: =Sheet1!N19 -> 1
A5: =Sheet1!E20 -> 3 | B5: =Sheet1!N20 -> 4 | D5: t-statistic | E5: =(H1*SQRT(96-2))/SQRT(1-H1^2) -> -14.693912
A6: =Sheet1!E21 -> 4 | B6: =Sheet1!N21 -> 2 | D6: p-value (two-tail) | E6: =_xlfn.T.DIST.2T(ABS(E5), 94) -> 4.3613485e-26
A7: =Sheet1!E22 -> 2 | B7: =Sheet1!N22 -> 4
A8: =Sheet1!E23 -> 5 | B8: =Sheet1!N23 -> 1
A9: =Sheet1!E24 -> 3 | B9: =Sheet1!N24 -> 3
A10: =Sheet1!E25 -> 4 | B10: =Sheet1!N25 -> 2
A11: =Sheet1!E26 -> 2 | B11: =Sheet1!N26 -> 4
A12: =Sheet1!E27 -> 2 | B12: =Sheet1!N27 -> 4
A13: =Sheet1!E28 -> 3 | B13: =Sheet1!N28 -> 4
A14: =Sheet1!E29 -> 2 | B14: =Sheet1!N29 -> 3
A15: =Sheet1!E30 -> 2 | B15: =Sheet1!N30 -> 5
A16: =Sheet1!E31 -> 2 | B16: =Sheet1!N31 -> 3
A17: =Sheet1!E32 -> 2 | B17: =Sheet1!N32 -> 4
A18: =Sheet1!E33 -> 5 | B18: =Sheet1!N33 -> 2
... A97: =Sheet1!E112 -> 3 | B97: =Sheet1!N112 -> 3

Sheet Sheet4_Regression
A1: Q13_Grade | B1: Q4_Hours | C1: Q5_CheckSchool | D1: Q6_Multitask | F1: SUMMARY OUTPUT
A2: =Sheet1!$N17 -> 2 | B2: =Sheet1!$E17 -> 4 | C2: =Sheet1!$F17 -> 4 | D2: =Sheet1!$G17 -> 4
A3: =Sheet1!$N18 -> 3 | B3: =Sheet1!$E18 -> 3 | C3: =Sheet1!$F18 -> 3 | D3: =Sheet1!$G18 -> 3 | F3: Regression Statistics
A4: =Sheet1!$N19 -> 1 | B4: =Sheet1!$E19 -> 5 | C4: =Sheet1!$F19 -> 5 | D4: =Sheet1!$G19 -> 5 | F4: Multiple R | G4: 0.84974989
A5: =Sheet1!$N20 -> 4 | B5: =Sheet1!$E20 -> 3 | C5: =Sheet1!$F20 -> 3 | D5: =Sheet1!$G20 -> 2 | F5: R Square | G5: 0.72207487
A6: =Sheet1!$N21 -> 2 | B6: =Sheet1!$E21 -> 4 | C6: =Sheet1!$F21 -> 4 | D6: =Sheet1!$G21 -> 4 | F6: Adjusted R Square | G6: 0.7130121
A7: =Sheet1!$N22 -> 4 | B7: =Sheet1!$E22 -> 2 | C7: =Sheet1!$F22 -> 2 | D7: =Sheet1!$G22 -> 2 | F7: Standard Error | G7: 0.69223859
A8: =Sheet1!$N23 -> 1 | B8: =Sheet1!$E23 -> 5 | C8: =Sheet1!$F23 -> 5 | D8: =Sheet1!$G23 -> 5 | F8: Observations | G8: 96
A9: =Sheet1!$N24 -> 3 | B9: =Sheet1!$E24 -> 3 | C9: =Sheet1!$F24 -> 3 | D9: =Sheet1!$G24 -> 3
A10: =Sheet1!$N25 -> 2 | B10: =Sheet1!$E25 -> 4 | C10: =Sheet1!$F25 -> 4 | D10: =Sheet1!$G25 -> 4 | F10: ANOVA
A11: =Sheet1!$N26 -> 4 | B11: =Sheet1!$E26 -> 2 | C11: =Sheet1!$F26 -> 2 | D11: =Sheet1!$G26 -> 2 | G11: df | H11: SS | I11: MS | J11: F | K11: Significance F
A12: =Sheet1!$N27 -> 4 | B12: =Sheet1!$E27 -> 2 | C12: =Sheet1!$F27 -> 1 | D12: =Sheet1!$G27 -> 1 | F12: Regression | G12: 3 | H12: 114.53913 | I12: 38.179709 | J12: 79.674803 | K12: 1.7341513e-25
A13: =Sheet1!$N28 -> 4 | B13: =Sheet1!$E28 -> 3 | C13: =Sheet1!$F28 -> 3 | D13: =Sheet1!$G28 -> 4 | F13: Residual | G13: 92 | H13: 44.085873 | I13: 0.47919427
A14: =Sheet1!$N29 -> 3 | B14: =Sheet1!$E29 -> 2 | C14: =Sheet1!$F29 -> 3 | D14: =Sheet1!$G29 -> 2 | F14: Total | G14: 95 | H14: 158.625
A15: =Sheet1!$N30 -> 5 | B15: =Sheet1!$E30 -> 2 | C15: =Sheet1!$F30 -> 1 | D15: =Sheet1!$G30 -> 2
A16: =Sheet1!$N31 -> 3 | B16: =Sheet1!$E31 -> 2 | C16: =Sheet1!$F31 -> 3 | D16: =Sheet1!$G31 -> 1 | G16: Coefficients | H16: Standard Error | I16: t Stat | J16: P-value | K16: Lower 95% | L16: Upper 95% | M16: Lower 95.0% | N16: Upper 95.0%
A17: =Sheet1!$N32 -> 4 | B17: =Sheet1!$E32 -> 2 | C17: =Sheet1!$F32 -> 2 | D17: =Sheet1!$G32 -> 2 | F17: Intercept | G17: 5.9012105 | H17: 0.21396741 | I17: 27.57995 | J17: 2.8960061e-46 | K17: 5.4762528 | L17: 6.3261683 | M17: 5.4762528 | N17: 6.3261683
A18: =Sheet1!$N33 -> 2 | B18: =Sheet1!$E33 -> 5 | C18: =Sheet1!$F33 -> 5 | D18: =Sheet1!$G33 -> 4 | F18: Q4_Hours | G18: -0.6262286 | H18: 0.14131597 | I18: -4.4314072 | J18: 2.5807266e-05 | K18: -0.90689431 | L18: -0.34556289 | M18: -0.90689431 | N18: -0.34556289
A19: =Sheet1!$N34 -> 4 | B19: =Sheet1!$E34 -> 3 | C19: =Sheet1!$F34 -> 2 | D19: =Sheet1!$G34 -> 4 | F19: Q5_CheckSchool | G19: -0.29503794 | H19: 0.10177541 | I19: -2.8989118 | J19: 0.0046816439 | K19: -0.49717269 | L19: -0.092903191 | M19: -0.49717269 | N19: -0.092903191
A20: =Sheet1!$N35 -> 2 | B20: =Sheet1!$E35 -> 3 | C20: =Sheet1!$F35 -> 3 | D20: =Sheet1!$G35 -> 3 | F20: Q6_Multitask | G20: -0.028599191 | H20: 0.09318864 | I20: -0.30689568 | J20: 0.75961633 | K20: -0.21367987 | L20: 0.15648149 | M20: -0.21367987 | N20: 0.15648149
A21: =Sheet1!$N36 -> 1 | B21: =Sheet1!$E36 -> 5 | C21: =Sheet1!$F36 -> 4 | D21: =Sheet1!$G36 -> 4
A22: =Sheet1!$N37 -> 3 | B22: =Sheet1!$E37 -> 2 | C22: =Sheet1!$F37 -> 2 | D22: =Sheet1!$G37 -> 1
A23: =Sheet1!$N38 -> 1 | B23: =Sheet1!$E38 -> 4 | C23: =Sheet1!$F38 -> 5 | D23: =Sheet1!$G38 -> 3
A24: =Sheet1!$N39 -> 4 | B24: =Sheet1!$E39 -> 3 | C24: =Sheet1!$F39 -> 2 | D24: =Sheet1!$G39 -> 2 | F24: RESIDUAL OUTPUT | J24: PROBABILITY OUTPUT
A25: =Sheet1!$N40 -> 4 | B25: =Sheet1!$E40 -> 2 | C25: =Sheet1!$F40 -> 2 | D25: =Sheet1!$G40 -> 1
A26: =Sheet1!$N41 -> 5 | B26: =Sheet1!$E41 -> 1 | C26: =Sheet1!$F41 -> 2 | D26: =Sheet1!$G41 -> 2 | F26: Observation | G26: Predicted Q13_Grade | H26: Residuals | J26: Percentile | K26: Q13_Grade
A27: =Sheet1!$N42 -> 1 | B27: =Sheet1!$E42 -> 5 | C27: =Sheet1!$F42 -> 4 | D27: =Sheet1!$G42 -> 4 | F27: 1 | G27: 2.1017476 | H27: -0.10174761 | J27: 0.52083333 | K27: 1
A28: =Sheet1!$N43 -> 3 | B28: =Sheet1!$E43 -> 4 | C28: =Sheet1!$F43 -> 3 | D28: =Sheet1!$G43 -> 5 | F28: 2 | G28: 3.0516133 | H28: -0.051613339 | J28: 1.5625 | K28: 1
A29: =Sheet1!$N44 -> 1 | B29: =Sheet1!$E44 -> 4 | C29: =Sheet1!$F44 -> 3 | D29: =Sheet1!$G44 -> 5 | F29: 3 | G29: 1.1518819 | H29: -0.15188188 | J29: 2.6041667 | K29: 1
A30: =Sheet1!$N45 -> 2 | B30: =Sheet1!$E45 -> 4 | C30: =Sheet1!$F45 -> 4 | D30: =Sheet1!$G45 -> 3 | F30: 4 | G30: 3.0802125 | H30: 0.91978747 | J30: 3.6458333 | K30: 1
A31: =Sheet1!$N46 -> 4 | B31: =Sheet1!$E46 -> 2 | C31: =Sheet1!$F46 -> 2 | D31: =Sheet1!$G46 -> 2 | F31: 5 | G31: 2.1017476 | H31: -0.10174761 | J31: 4.6875 | K31: 1
A32: =Sheet1!$N47 -> 2 | B32: =Sheet1!$E47 -> 4 | C32: =Sheet1!$F47 -> 5 | D32: =Sheet1!$G47 -> 5 | F32: 6 | G32: 4.0014791 | H32: -0.0014790708 | J32: 5.7291667 | K32: 1
A33: =Sheet1!$N48 -> 3 | B33: =Sheet1!$E48 -> 4 | C33: =Sheet1!$F48 -> 3 | D33: =Sheet1!$G48 -> 4 | F33: 7 | G33: 1.1518819 | H33: -0.15188188 | J33: 6.7708333 | K33: 1
A34: =Sheet1!$N49 -> 5 | B34: =Sheet1!$E49 -> 1 | C34: =Sheet1!$F49 -> 2 | D34: =Sheet1!$G49 -> 1 | F34: 8 | G34: 3.0516133 | H34: -0.051613339 | J34: 7.8125 | K34: 1
A35: =Sheet1!$N50 -> 2 | B35: =Sheet1!$E50 -> 3 | C35: =Sheet1!$F50 -> 4 | D35: =Sheet1!$G50 -> 4 | F35: 9 | G35: 2.1017476 | H35: -0.10174761 | J35: 8.8541667 | K35: 1
A36: =Sheet1!$N51 -> 5 | B36: =Sheet1!$E51 -> 2 | C36: =Sheet1!$F51 -> 1 | D36: =Sheet1!$G51 -> 2 | F36: 10 | G36: 4.0014791 | H36: -0.0014790708 | J36: 9.8958333 | K36: 1
A37: =Sheet1!$N52 -> 1 | B37: =Sheet1!$E52 -> 4 | C37: =Sheet1!$F52 -> 5 | D37: =Sheet1!$G52 -> 3 | F37: 11 | G37: 4.3251162 | H37: -0.3251162 | J37: 10.9375 | K37: 1
A38: =Sheet1!$N53 -> 2 | B38: =Sheet1!$E53 -> 4 | C38: =Sheet1!$F53 -> 3 | D38: =Sheet1!$G53 -> 5 | F38: 12 | G38: 3.0230141 | H38: 0.97698585 | J38: 11.979167 | K38: 1
... A97: =Sheet1!$N112 -> 3 | B97: =Sheet1!$E112 -> 3 | C97: =Sheet1!$F112 -> 3 | D97: =Sheet1!$G112 -> 2 | F97: 71 | G97: 1.1518819 | H97: -0.15188188 | J97: 73.4375 | K97: 4
F98: 72 | G98: 1.7781105 | H98: 1.2218895 | J98: 74.479167 | K98: 4
...

Sheet Sheet5_TTest
A1: Male_Concentration | B1: Female_Concentration | D1: t-Test: Two-Sample Assuming Unequal Variances
A2: {=_xlfn._xlws.FILTER(Sheet1!$V$17:$V$112, Sheet1!$B$17:$B$112=1)} -> 4.2 | B2: {=IFERROR(INDEX(Sheet1!$V$17:$V$112, SMALL(IF(Sheet1!$B$17:$B$112=2, ROW(Sheet1!$V$17:$V$112)-ROW(Sheet1!$V$17)+1), ROW(1:1))), "")} -> 3.4
A3: 5 | B3: {=IFERROR(INDEX(Sheet1!$V$17:$V$112, SMALL(IF(Sheet1!$B$17:$B$112=2, ROW(Sheet1!$V$17:$V$112)-ROW(Sheet1!$V$17)+1), ROW(2:2))), "")} -> 3.2 | E3: Male_Concentration | F3: Female_Concentration
A4: 4 | B4: {=IFERROR(INDEX(Sheet1!$V$17:$V$112, SMALL(IF(Sheet1!$B$17:$B$112=2, ROW(Sheet1!$V$17:$V$112)-ROW(Sheet1!$V$17)+1), ROW(3:3))), "")} -> 2.2 | D4: Mean | E4: 3.5387755 | F4: 2.9957447
A5: 5 | B5: {=IFERROR(INDEX(Sheet1!$V$17:$V$112, SMALL(IF(Sheet1!$B$17:$B$112=2, ROW(Sheet1!$V$17:$V$112)-ROW(Sheet1!$V$17)+1), ROW(4:4))), "")} -> 3 | D5: Variance | E5: 1.2136735 | F5: 1.2165032
A6: 4.2 | B6: {=IFERROR(INDEX(Sheet1!$V$17:$V$112, SMALL(IF(Sheet1!$B$17:$B$112=2, ROW(Sheet1!$V$17:$V$112)-ROW(Sheet1!$V$17)+1), ROW(5:5))), "")} -> 2.2 | D6: Observations | E6: 49 | F6: 47
A7: 2.2 | B7: {=IFERROR(INDEX(Sheet1!$V$17:$V$112, SMALL(IF(Sheet1!$B$17:$B$112=2, ROW(Sheet1!$V$17:$V$112)-ROW(Sheet1!$V$17)+1), ROW(6:6))), "")} -> 1.8 | D7: Hypothesized Mean Difference | E7: 0
A8: 2.8 | B8: {=IFERROR(INDEX(Sheet1!$V$17:$V$112, SMALL(IF(Sheet1!$B$17:$B$112=2, ROW(Sheet1!$V$17:$V$112)-ROW(Sheet1!$V$17)+1), ROW(7:7))), "")} -> 2.4 | D8: df | E8: 94
A9: 1.4 | B9: {=IFERROR(INDEX(Sheet1!$V$17:$V$112, SMALL(IF(Sheet1!$B$17:$B$112=2, ROW(Sheet1!$V$17:$V$112)-ROW(Sheet1!$V$17)+1), ROW(8:8))), "")} -> 2.8 | D9: t Stat | E9: 2.4128295
A10: 2.6 | B10: {=IFERROR(INDEX(Sheet1!$V$17:$V$112, SMALL(IF(Sheet1!$B$17:$B$112=2, ROW(Sheet1!$V$17:$V$112)-ROW(Sheet1!$V$17)+1), ROW(9:9))), "")} -> 1.6 | D10: P(T<=t) one-tail | E10: 0.008884582
A11: 4.6 | B11: {=IFERROR(INDEX(Sheet1!$V$17:$V$112, SMALL(IF(Sheet1!$B$17:$B$112=2, ROW(Sheet1!$V$17:$V$112)-ROW(Sheet1!$V$17)+1), ROW(10:10))), "")} -> 2.2 | D11: t Critical one-tail | E11: 1.6612259
A12: 3.4 | B12: {=IFERROR(INDEX(Sheet1!$V$17:$V$112, SMALL(IF(Sheet1!$B$17:$B$112=2, ROW(Sheet1!$V$17:$V$112)-ROW(Sheet1!$V$17)+1), ROW(11:11))), "")} -> 1.4 | D12: P(T<=t) two-tail | E12: 0.017769164
A13: 4.4 | B13: {=IFERROR(INDEX(Sheet1!$V$17:$V$112, SMALL(IF(Sheet1!$B$17:$B$112=2, ROW(Sheet1!$V$17:$V$112)-ROW(Sheet1!$V$17)+1), ROW(12:12))), "")} -> 4.8 | D13: t Critical two-tail | E13: 1.9855234
A14: 4.2 | B14: {=IFERROR(INDEX(Sheet1!$V$17:$V$112, SMALL(IF(Sheet1!$B$17:$B$112=2, ROW(Sheet1!$V$17:$V$112)-ROW(Sheet1!$V$17)+1), ROW(13:13))), "")} -> 4.4
A15: 3.4 | B15: {=IFERROR(INDEX(Sheet1!$V$17:$V$112, SMALL(IF(Sheet1!$B$17:$B$112=2, ROW(Sheet1!$V$17:$V$112)-ROW(Sheet1!$V$17)+1), ROW(14:14))), "")} -> 3.6
A16: 4.6 | B16: {=IFERROR(INDEX(Sheet1!$V$17:$V$112, SMALL(IF(Sheet1!$B$17:$B$112=2, ROW(Sheet1!$V$17:$V$112)-ROW(Sheet1!$V$17)+1), ROW(15:15))), "")} -> 1.2
A17: 4 | B17: {=IFERROR(INDEX(Sheet1!$V$17:$V$112, SMALL(IF(Sheet1!$B$17:$B$112=2, ROW(Sheet1!$V$17:$V$112)-ROW(Sheet1!$V$17)+1), ROW(16:16))), "")} -> 1.6
A18: 3 | B18: {=IFERROR(INDEX(Sheet1!$V$17:$V$112, SMALL(IF(Sheet1!$B$17:$B$112=2, ROW(Sheet1!$V$17:$V$112)-ROW(Sheet1!$V$17)+1), ROW(17:17))), "")} -> 4.4
A19: 4.2 | B19: {=IFERROR(INDEX(Sheet1!$V$17:$V$112, SMALL(IF(Sheet1!$B$17:$B$112=2, ROW(Sheet1!$V$17:$V$112)-ROW(Sheet1!$V$17)+1), ROW(18:18))), "")} -> 4.6
A20: 3 | B20: {=IFERROR(INDEX(Sheet1!$V$17:$V$112, SMALL(IF(Sheet1!$B$17:$B$112=2, ROW(Sheet1!$V$17:$V$112)-ROW(Sheet1!$V$17)+1), ROW(19:19))), "")} -> 2.4
A21: 3.6 | B21: {=IFERROR(INDEX(Sheet1!$V$17:$V$112, SMALL(IF(Sheet1!$B$17:$B$112=2, ROW(Sheet1!$V$17:$V$112)-ROW(Sheet1!$V$17)+1), ROW(20:20))), "")} -> 2.2
A22: 4.4 | B22: {=IFERROR(INDEX(Sheet1!$V$17:$V$112, SMALL(IF(Sheet1!$B$17:$B$112=2, ROW(Sheet1!$V$17:$V$112)-ROW(Sheet1!$V$17)+1), ROW(21:21))), "")} -> 4.6
A23: 2.4 | B23: {=IFERROR(INDEX(Sheet1!$V$17:$V$112, SMALL(IF(Sheet1!$B$17:$B$112=2, ROW(Sheet1!$V$17:$V$112)-ROW(Sheet1!$V$17)+1), ROW(22:22))), "")} -> 4.8
A24: 3 | B24: {=IFERROR(INDEX(Sheet1!$V$17:$V$112, SMALL(IF(Sheet1!$B$17:$B$112=2, ROW(Sheet1!$V$17:$V$112)-ROW(Sheet1!$V$17)+1), ROW(23:23))), "")} -> 2
A25: 2.4 | B25: {=IFERROR(INDEX(Sheet1!$V$17:$V$112, SMALL(IF(Sheet1!$B$17:$B$112=2, ROW(Sheet1!$V$17:$V$112)-ROW(Sheet1!$V$17)+1), ROW(24:24))), "")} -> 1.4
A26: 3 | B26: {=IFERROR(INDEX(Sheet1!$V$17:$V$112, SMALL(IF(Sheet1!$B$17:$B$112=2, ROW(Sheet1!$V$17:$V$112)-ROW(Sheet1!$V$17)+1), ROW(25:25))), "")} -> 3.2
A27: 4.6 | B27: {=IFERROR(INDEX(Sheet1!$V$17:$V$112, SMALL(IF(Sheet1!$B$17:$B$112=2, ROW(Sheet1!$V$17:$V$112)-ROW(Sheet1!$V$17)+1), ROW(26:26))), "")} -> 2.2
A28: 4.4 | B28: {=IFERROR(INDEX(Sheet1!$V$17:$V$112, SMALL(IF(Sheet1!$B$17:$B$112=2, ROW(Sheet1!$V$17:$V$112)-ROW(Sheet1!$V$17)+1), ROW(27:27))), "")} -> 3.2
A29: 1.6 | B29: {=IFERROR(INDEX(Sheet1!$V$17:$V$112, SMALL(IF(Sheet1!$B$17:$B$112=2, ROW(Sheet1!$V$17:$V$112)-ROW(Sheet1!$V$17)+1), ROW(28:28))), "")} -> 4.2
A30: 4.2 | B30: {=IFERROR(INDEX(Sheet1!$V$17:$V$112, SMALL(IF(Sheet1!$B$17:$B$112=2, ROW(Sheet1!$V$17:$V$112)-ROW(Sheet1!$V$17)+1), ROW(29:29))), "")} -> 3.8
A31: 4.8 | B31: {=IFERROR(INDEX(Sheet1!$V$17:$V$112, SMALL(IF(Sheet1!$B$17:$B$112=2, ROW(Sheet1!$V$17:$V$112)-ROW(Sheet1!$V$17)+1), ROW(30:30))), "")} -> 3.2
A32: 4.6 | B32: {=IFERROR(INDEX(Sheet1!$V$17:$V$112, SMALL(IF(Sheet1!$B$17:$B$112=2, ROW(Sheet1!$V$17:$V$112)-ROW(Sheet1!$V$17)+1), ROW(31:31))), "")} -> 1.8
A33: 3.6 | B33: {=IFERROR(INDEX(Sheet1!$V$17:$V$112, SMALL(IF(Sheet1!$B$17:$B$112=2, ROW(Sheet1!$V$17:$V$112)-ROW(Sheet1!$V$17)+1), ROW(32:32))), "")} -> 1.4
A34: 3.2 | B34: {=IFERROR(INDEX(Sheet1!$V$17:$V$112, SMALL(IF(Sheet1!$B$17:$B$112=2, ROW(Sheet1!$V$17:$V$112)-ROW(Sheet1!$V$17)+1), ROW(33:33))), "")} -> 1.8
A35: 2.2 | B35: {=IFERROR(INDEX(Sheet1!$V$17:$V$112, SMALL(IF(Sheet1!$B$17:$B$112=2, ROW(Sheet1!$V$17:$V$112)-ROW(Sheet1!$V$17)+1), ROW(34:34))), "")} -> 3.8
A36: 4.2 | B36: {=IFERROR(INDEX(Sheet1!$V$17:$V$112, SMALL(IF(Sheet1!$B$17:$B$112=2, ROW(Sheet1!$V$17:$V$112)-ROW(Sheet1!$V$17)+1), ROW(35:35))), "")} -> 2.8
A37: 4.8 | B37: {=IFERROR(INDEX(Sheet1!$V$17:$V$112, SMALL(IF(Sheet1!$B$17:$B$112=2, ROW(Sheet1!$V$17:$V$112)-ROW(Sheet1!$V$17)+1), ROW(36:36))), "")} -> 3
A38: 4.2 | B38: {=IFERROR(INDEX(Sheet1!$V$17:$V$112, SMALL(IF(Sheet1!$B$17:$B$112=2, ROW(Sheet1!$V$17:$V$112)-ROW(Sheet1!$V$17)+1), ROW(37:37))), "")} -> 4.6
A39: 4.8 | B39: {=IFERROR(INDEX(Sheet1!$V$17:$V$112, SMALL(IF(Sheet1!$B$17:$B$112=2, ROW(Sheet1!$V$17:$V$112)-ROW(Sheet1!$V$17)+1), ROW(38:38))), "")} -> 2.6
A40: 1.4 | B40: {=IFERROR(INDEX(Sheet1!$V$17:$V$112, SMALL(IF(Sheet1!$B$17:$B$112=2, ROW(Sheet1!$V$17:$V$112)-ROW(Sheet1!$V$17)+1), ROW(39:39))), "")} -> 5
...

Sheet ANOVA_Data
A1: Group 1 (<1hr) | B1: Group 2 (1-2hrs) | C1: Group 3 (3-4hrs) | D1: Group 4 (5-6hrs) | E1: Group 5 (7+hrs) | G1: Anova: Single Factor
A2: {=_xlfn._xlws.FILTER(Sheet1!$N$17:$N$112, Sheet1!$E$17:$E$112=1)} -> 5 | B2: {=_xlfn._xlws.FILTER(Sheet1!$N$17:$N$112, Sheet1!$E$17:$E$112=2)} -> 4 | C2: {=_xlfn._xlws.FILTER(Sheet1!$N$17:$N$112, Sheet1!$E$17:$E$112=3)} -> 3 | D2: {=_xlfn._xlws.FILTER(Sheet1!$N$17:$N$112, Sheet1!$E$17:$E$112=4)} -> 2 | E2: {=_xlfn._xlws.FILTER(Sheet1!$N$17:$N$112, Sheet1!$E$17:$E$112=5)} -> 1
A3: 5 | B3: 4 | C3: 4 | D3: 2 | E3: 1 | G3: SUMMARY
A4: 5 | B4: 4 | C4: 3 | D4: 2 | E4: 2 | G4: Groups | H4: Count | I4: Sum | J4: Average | K4: Variance
A5: 5 | B5: 3 | C5: 4 | D5: 1 | E5: 1 | G5: Group 1 (<1hr) | H5: 6 | I5: 30 | J5: 5 | K5: 0
A6: 5 | B6: 5 | C6: 4 | D6: 3 | E6: 1 | G6: Group 2 (1-2hrs) | H6: 23 | I6: 91 | J6: 3.9565217 | K6: 0.49802372
A7: 5 | B7: 3 | C7: 2 | D7: 1 | E7: 2 | G7: Group 3 (3-4hrs) | H7: 23 | I7: 70 | J7: 3.0434783 | K7: 0.77075099
B8: 4 | C8: 4 | D8: 2 | E8: 2 | G8: Group 4 (5-6hrs) | H8: 27 | I8: 56 | J8: 2.0740741 | K8: 0.60968661
B9: 3 | C9: 2 | D9: 2 | E9: 1 | G9: Group 5 (7+hrs) | H9: 17 | I9: 23 | J9: 1.3529412 | K9: 0.24264706
B10: 4 | C10: 3 | D10: 3 | E10: 2
B11: 4 | C11: 4 | D11: 1 | E11: 1
B12: 5 | C12: 4 | D12: 2 | E12: 1 | G12: ANOVA
B13: 5 | C13: 4 | D13: 1 | E13: 1 | G13: Source of Variation | H13: SS | I13: df | J13: MS | K13: F | L13: P-value | M13: F crit
B14: 4 | C14: 2 | D14: 1 | E14: 2 | G14: Between Groups | H14: 110.97775 | I14: 4 | J14: 27.744438 | K14: 52.988241 | L14: 5.6249718e-23 | M14: 2.4717915
B15: 4 | C15: 3 | D15: 3 | E15: 1 | G15: Within Groups | H15: 47.647248 | I15: 91 | J15: 0.52359613
B16: 4 | C16: 2 | D16: 2 | E16: 2
B17: 5 | C17: 4 | D17: 2 | E17: 1 | G17: Total | H17: 158.625 | I17: 95
B18: 4 | C18: 2 | D18: 3 | E18: 1
B19: 5 | C19: 3 | D19: 1
B20: 4 | C20: 4 | D20: 2
B21: 4 | C21: 2 | D21: 3
B22: 3 | C22: 2 | D22: 1
B23: 3 | C23: 2 | D23: 2
B24: 3 | C24: 3 | D24: 3
D25: 3
D26: 3
D27: 2
D28: 3
