Workbook

Sheet Raw Data
A1: Raw Survey Data — Satisfaction with Online Learning
A3: Response Scale: | B3: 1 = Strongly Disagree 2 = Disagree 3 = Neither Agree nor Disagree 4 = Agree 5 = Strongly Agree
A5: Question Codebook
A6: Q1 | B6: I am pleased with my whole experience with online learning.
A7: Q2 | B7: Online classes allow me to balance my education and other obligations.
A8: Q3 | B8: I feel engaged and involved in my online classes.
A9: Q4 | B9: I feel like I learn just as much online as I would in a real classroom.
A10: Q5 | B10: I would recommend online learning to other students.
A12: Note: | B12: Data below is simulated for this assignment because the actual Module 14 respondent dataset was not provided. Two responses were randomly set to blank to demonstrate realistic missing-data handling (see Data Cleaning sheet).
A14: RespondentID | B14: Q1 | C14: Q2 | D14: Q3 | E14: Q4 | F14: Q5 | G14: Avg_Score
A15: R001 | B15: 4 | C15: 5 | D15: 2 | E15: 3 | F15: 4 | G15: =IFERROR(AVERAGE(B15:F15),"") -> 3.6
A16: R002 | B16: 5 | C16: 4 | D16: 4 | E16: 4 | F16: 2 | G16: =IFERROR(AVERAGE(B16:F16),"") -> 3.8
A17: R003 | B17: 5 | C17: 5 | D17: 5 | E17: 4 | F17: 5 | G17: =IFERROR(AVERAGE(B17:F17),"") -> 4.8
A18: R004 | B18: 4 | C18: 5 | D18: 4 | E18: 3 | F18: 5 | G18: =IFERROR(AVERAGE(B18:F18),"") -> 4.2
A19: R005 | B19: 3 | C19: 4 | D19: 5 | E19: 5 | F19: 3 | G19: =IFERROR(AVERAGE(B19:F19),"") -> 4
A20: R006 | B20: 3 | C20: 5 | D20: 4 | E20: 5 | F20: 5 | G20: =IFERROR(AVERAGE(B20:F20),"") -> 4.4
A21: R007 | B21: 2 | C21: 5 | D21: 4 | E21: 2 | F21: 5 | G21: =IFERROR(AVERAGE(B21:F21),"") -> 3.6
A22: R008 | B22: 5 | C22: 5 | D22: 4 | E22: 3 | F22: 4 | G22: =IFERROR(AVERAGE(B22:F22),"") -> 4.2
A23: R009 | B23: 4 | C23: 5 | D23: 1 | E23: 3 | F23: 4 | G23: =IFERROR(AVERAGE(B23:F23),"") -> 3.4
A24: R010 | B24: 5 | C24: 5 | D24: 2 | E24: 2 | F24: 3 | G24: =IFERROR(AVERAGE(B24:F24),"") -> 3.4
A25: R011 | B25: 1 | C25: 5 | D25: 1 | E25: 1 | F25: 2 | G25: =IFERROR(AVERAGE(B25:F25),"") -> 2
A26: R012 | B26: 5 | C26: 3 | E26: 4 | F26: 5 | G26: =IFERROR(AVERAGE(B26:F26),"") -> 4.25
A27: R013 | B27: 5 | C27: 4 | D27: 3 | E27: 3 | F27: 5 | G27: =IFERROR(AVERAGE(B27:F27),"") -> 4
A28: R014 | B28: 3 | C28: 2 | D28: 4 | E28: 1 | F28: 5 | G28: =IFERROR(AVERAGE(B28:F28),"") -> 3
A29: R015 | B29: 3 | C29: 4 | D29: 5 | E29: 2 | F29: 4 | G29: =IFERROR(AVERAGE(B29:F29),"") -> 3.6
A30: R016 | B30: 3 | C30: 4 | D30: 3 | E30: 5 | F30: 4 | G30: =IFERROR(AVERAGE(B30:F30),"") -> 3.8
A31: R017 | B31: 4 | C31: 4 | D31: 4 | E31: 2 | F31: 5 | G31: =IFERROR(AVERAGE(B31:F31),"") -> 3.8
A32: R018 | B32: 4 | C32: 5 | D32: 5 | E32: 2 | F32: 5 | G32: =IFERROR(AVERAGE(B32:F32),"") -> 4.2
A33: R019 | B33: 4 | C33: 4 | D33: 3 | E33: 3 | F33: 5 | G33: =IFERROR(AVERAGE(B33:F33),"") -> 3.8
A34: R020 | B34: 4 | C34: 4 | D34: 2 | E34: 5 | F34: 5 | G34: =IFERROR(AVERAGE(B34:F34),"") -> 4
A35: R021 | B35: 4 | C35: 5 | D35: 3 | E35: 2 | F35: 5 | G35: =IFERROR(AVERAGE(B35:F35),"") -> 3.8
A36: R022 | B36: 3 | C36: 3 | D36: 2 | E36: 4 | F36: 2 | G36: =IFERROR(AVERAGE(B36:F36),"") -> 2.8
A37: R023 | B37: 4 | C37: 5 | D37: 5 | E37: 4 | F37: 3 | G37: =IFERROR(AVERAGE(B37:F37),"") -> 4.2
A38: R024 | B38: 4 | C38: 3 | D38: 5 | E38: 2 | F38: 5 | G38: =IFERROR(AVERAGE(B38:F38),"") -> 3.8
... A40: R026 | B40: 5 | C40: 5 | D40: 5 | E40: 3 | F40: 1 | G40: =IFERROR(AVERAGE(B40:F40),"") -> 3.8
A41: R027 | B41: 3 | C41: 4 | D41: 5 | E41: 4 | G41: =IFERROR(AVERAGE(B41:F41),"") -> 4
A42: R028 | B42: 4 | C42: 1 | D42: 2 | E42: 4 | F42: 5 | G42: =IFERROR(AVERAGE(B42:F42),"") -> 3.2
A43: R029 | B43: 4 | C43: 5 | D43: 5 | E43: 4 | F43: 1 | G43: =IFERROR(AVERAGE(B43:F43),"") -> 3.8
A44: R030 | B44: 2 | C44: 5 | D44: 4 | E44: 1 | F44: 3 | G44: =IFERROR(AVERAGE(B44:F44),"") -> 3
A45: R031 | B45: 4 | C45: 5 | D45: 5 | E45: 5 | F45: 4 | G45: =IFERROR(AVERAGE(B45:F45),"") -> 4.6
...

Sheet Data Cleaning
A1: Data Cleaning Summary
A3: Approach: | B3: Missing responses were left blank in Raw Data rather than deleted or imputed. Because fewer than 5% of responses are missing on any single item, a pairwise-deletion approach is used: each question's statistics are calculated only from respondents who answered that question (AVERAGE, MEDIAN, etc. in Excel ignore blank cells automatically). This preserves all valid data instead of discarding a respondent's entire record over one skipped item.
A6: Question | B6: Total Respondents (N) | C6: Valid Responses | D6: Missing | E6: % Missing
A7: Q1: I am pleased with my whole experience with online learning. | B7: 45 | C7: =COUNT('Raw Data'!B15:B59) -> 45 | D7: =COUNTBLANK('Raw Data'!B15:B59) -> 0 | E7: =D7/B7 -> 0
A8: Q2: Online classes allow me to balance my education and other obligations. | B8: 45 | C8: =COUNT('Raw Data'!C15:C59) -> 45 | D8: =COUNTBLANK('Raw Data'!C15:C59) -> 0 | E8: =D8/B8 -> 0
A9: Q3: I feel engaged and involved in my online classes. | B9: 45 | C9: =COUNT('Raw Data'!D15:D59) -> 44 | D9: =COUNTBLANK('Raw Data'!D15:D59) -> 1 | E9: =D9/B9 -> 0.022222222
A10: Q4: I feel like I learn just as much online as I would in a real classroom. | B10: 45 | C10: =COUNT('Raw Data'!E15:E59) -> 45 | D10: =COUNTBLANK('Raw Data'!E15:E59) -> 0 | E10: =D10/B10 -> 0
A11: Q5: I would recommend online learning to other students. | B11: 45 | C11: =COUNT('Raw Data'!F15:F59) -> 44 | D11: =COUNTBLANK('Raw Data'!F15:F59) -> 1 | E11: =D11/B11 -> 0.022222222
A13: No duplicate respondents, out-of-range values (outside 1-5), or non-numeric entries were found in the dataset.

Sheet Descriptive Stats
A1: Descriptive Statistics
A3: Question | B3: N (valid) | C3: Mean | D3: Median | E3: Mode | F3: Std Dev | G3: Min | H3: Max
A4: Q1: I am pleased with my whole experience with online learning. | B4: =COUNT('Raw Data'!B15:B59) -> 45 | C4: =AVERAGE('Raw Data'!B15:B59) -> 3.7111111 | D4: =MEDIAN('Raw Data'!B15:B59) -> 4 | E4: =_xlfn.MODE.SNGL('Raw Data'!B15:B59) -> 4 | F4: =_xlfn.STDEV.S('Raw Data'!B15:B59) -> 1.1205158 | G4: =MIN('Raw Data'!B15:B59) -> 1 | H4: =MAX('Raw Data'!B15:B59) -> 5
A5: Q2: Online classes allow me to balance my education and other obligations. | B5: =COUNT('Raw Data'!C15:C59) -> 45 | C5: =AVERAGE('Raw Data'!C15:C59) -> 4.2444444 | D5: =MEDIAN('Raw Data'!C15:C59) -> 5 | E5: =_xlfn.MODE.SNGL('Raw Data'!C15:C59) -> 5 | F5: =_xlfn.STDEV.S('Raw Data'!C15:C59) -> 0.98062029 | G5: =MIN('Raw Data'!C15:C59) -> 1 | H5: =MAX('Raw Data'!C15:C59) -> 5
A6: Q3: I feel engaged and involved in my online classes. | B6: =COUNT('Raw Data'!D15:D59) -> 44 | C6: =AVERAGE('Raw Data'!D15:D59) -> 3.6136364 | D6: =MEDIAN('Raw Data'!D15:D59) -> 4 | E6: =_xlfn.MODE.SNGL('Raw Data'!D15:D59) -> 5 | F6: =_xlfn.STDEV.S('Raw Data'!D15:D59) -> 1.2798239 | G6: =MIN('Raw Data'!D15:D59) -> 1 | H6: =MAX('Raw Data'!D15:D59) -> 5
A7: Q4: I feel like I learn just as much online as I would in a real classroom. | B7: =COUNT('Raw Data'!E15:E59) -> 45 | C7: =AVERAGE('Raw Data'!E15:E59) -> 3.1111111 | D7: =MEDIAN('Raw Data'!E15:E59) -> 3 | E7: =_xlfn.MODE.SNGL('Raw Data'!E15:E59) -> 4 | F7: =_xlfn.STDEV.S('Raw Data'!E15:E59) -> 1.2472191 | G7: =MIN('Raw Data'!E15:E59) -> 1 | H7: =MAX('Raw Data'!E15:E59) -> 5
A8: Q5: I would recommend online learning to other students. | B8: =COUNT('Raw Data'!F15:F59) -> 44 | C8: =AVERAGE('Raw Data'!F15:F59) -> 4 | D8: =MEDIAN('Raw Data'!F15:F59) -> 4 | E8: =_xlfn.MODE.SNGL('Raw Data'!F15:F59) -> 5 | F8: =_xlfn.STDEV.S('Raw Data'!F15:F59) -> 1.2007749 | G8: =MIN('Raw Data'!F15:F59) -> 1 | H8: =MAX('Raw Data'!F15:F59) -> 5
A9: Overall Composite Satisfaction | B9: =COUNT('Raw Data'!G15:G59) -> 45 | C9: =AVERAGE('Raw Data'!G15:G59) -> 3.7388889 | D9: =MEDIAN('Raw Data'!G15:G59) -> 3.8 | F9: =_xlfn.STDEV.S('Raw Data'!G15:G59) -> 0.56315758

Sheet Frequency Distribution
A1: Frequency Distribution by Question
A3: Question | B3: Strongly Disagree | C3: Disagree | D3: Neither Agree nor Disagree | E3: Agree | F3: Strongly Agree
A4: Q1 | B4: =COUNTIF('Raw Data'!B15:B59,1) -> 2 | C4: =COUNTIF('Raw Data'!B15:B59,2) -> 5 | D4: =COUNTIF('Raw Data'!B15:B59,3) -> 9 | E4: =COUNTIF('Raw Data'!B15:B59,4) -> 17 | F4: =COUNTIF('Raw Data'!B15:B59,5) -> 12
A5: Q2 | B5: =COUNTIF('Raw Data'!C15:C59,1) -> 1 | C5: =COUNTIF('Raw Data'!C15:C59,2) -> 2 | D5: =COUNTIF('Raw Data'!C15:C59,3) -> 5 | E5: =COUNTIF('Raw Data'!C15:C59,4) -> 14 | F5: =COUNTIF('Raw Data'!C15:C59,5) -> 23
A6: Q3 | B6: =COUNTIF('Raw Data'!D15:D59,1) -> 3 | C6: =COUNTIF('Raw Data'!D15:D59,2) -> 7 | D6: =COUNTIF('Raw Data'!D15:D59,3) -> 8 | E6: =COUNTIF('Raw Data'!D15:D59,4) -> 12 | F6: =COUNTIF('Raw Data'!D15:D59,5) -> 14
A7: Q4 | B7: =COUNTIF('Raw Data'!E15:E59,1) -> 5 | C7: =COUNTIF('Raw Data'!E15:E59,2) -> 11 | D7: =COUNTIF('Raw Data'!E15:E59,3) -> 9 | E7: =COUNTIF('Raw Data'!E15:E59,4) -> 14 | F7: =COUNTIF('Raw Data'!E15:E59,5) -> 6
A8: Q5 | B8: =COUNTIF('Raw Data'!F15:F59,1) -> 2 | C8: =COUNTIF('Raw Data'!F15:F59,2) -> 4 | D8: =COUNTIF('Raw Data'!F15:F59,3) -> 7 | E8: =COUNTIF('Raw Data'!F15:F59,4) -> 10 | F8: =COUNTIF('Raw Data'!F15:F59,5) -> 21
A10: Percent of Valid Responses
A11: Question | B11: Strongly Disagree | C11: Disagree | D11: Neither Agree nor Disagree | E11: Agree | F11: Strongly Agree
A12: Q1 | B12: =B4/SUM($B4:$F4) -> 0.044444444 | C12: =C4/SUM($B4:$F4) -> 0.11111111 | D12: =D4/SUM($B4:$F4) -> 0.2 | E12: =E4/SUM($B4:$F4) -> 0.37777778 | F12: =F4/SUM($B4:$F4) -> 0.26666667
A13: Q2 | B13: =B5/SUM($B5:$F5) -> 0.022222222 | C13: =C5/SUM($B5:$F5) -> 0.044444444 | D13: =D5/SUM($B5:$F5) -> 0.11111111 | E13: =E5/SUM($B5:$F5) -> 0.31111111 | F13: =F5/SUM($B5:$F5) -> 0.51111111
A14: Q3 | B14: =B6/SUM($B6:$F6) -> 0.068181818 | C14: =C6/SUM($B6:$F6) -> 0.15909091 | D14: =D6/SUM($B6:$F6) -> 0.18181818 | E14: =E6/SUM($B6:$F6) -> 0.27272727 | F14: =F6/SUM($B6:$F6) -> 0.31818182
A15: Q4 | B15: =B7/SUM($B7:$F7) -> 0.11111111 | C15: =C7/SUM($B7:$F7) -> 0.24444444 | D15: =D7/SUM($B7:$F7) -> 0.2 | E15: =E7/SUM($B7:$F7) -> 0.31111111 | F15: =F7/SUM($B7:$F7) -> 0.13333333
A16: Q5 | B16: =B8/SUM($B8:$F8) -> 0.045454545 | C16: =C8/SUM($B8:$F8) -> 0.090909091 | D16: =D8/SUM($B8:$F8) -> 0.15909091 | E16: =E8/SUM($B8:$F8) -> 0.22727273 | F16: =F8/SUM($B8:$F8) -> 0.47727273
A18: % Agree or Strongly Agree (Top-2-Box)
A19: Question | B19: % Agree/Strongly Agree
A20: Q1: I am pleased with my whole experience with online learning. | B20: =E12+F12 -> 0.64444444 | C20: Q1
A21: Q2: Online classes allow me to balance my education and other obligations. | B21: =E13+F13 -> 0.82222222 | C21: Q2
A22: Q3: I feel engaged and involved in my online classes. | B22: =E14+F14 -> 0.59090909 | C22: Q3
A23: Q4: I feel like I learn just as much online as I would in a real classroom. | B23: =E15+F15 -> 0.44444444 | C23: Q4
A24: Q5: I would recommend online learning to other students. | B24: =E16+F16 -> 0.70454545 | C24: Q5

Sheet Charts
A1: Charts

Sheet Key Findings
A1: Key Findings & Analysis
A3: Survey Objective: | B3: Assess student satisfaction with online learning across five dimensions: overall experience, flexibility/balance, engagement, perceived learning, and likelihood to recommend.
A6: Snapshot
A7: Question | B7: Mean | C7: % Agree/Strongly Agree
A8: Q1: I am pleased with my whole experience with online learning. | B8: ='Descriptive Stats'!C4 -> 3.7111111 | C8: ='Frequency Distribution'!B20 -> 0.64444444
A9: Q2: Online classes allow me to balance my education and other obligations. | B9: ='Descriptive Stats'!C5 -> 4.2444444 | C9: ='Frequency Distribution'!B21 -> 0.82222222
A10: Q3: I feel engaged and involved in my online classes. | B10: ='Descriptive Stats'!C6 -> 3.6136364 | C10: ='Frequency Distribution'!B22 -> 0.59090909
A11: Q4: I feel like I learn just as much online as I would in a real classroom. | B11: ='Descriptive Stats'!C7 -> 3.1111111 | C11: ='Frequency Distribution'!B23 -> 0.44444444
A12: Q5: I would recommend online learning to other students. | B12: ='Descriptive Stats'!C8 -> 4 | C12: ='Frequency Distribution'!B24 -> 0.70454545
A15: Narrative Analysis
A16: Strongest result — Flexibility (Q2):
A17: Q2 has the highest mean and the highest top-2-box agreement, indicating that the ability to balance online coursework with other obligations is this group's clearest benefit of online learning.
A19: Weakest result — Perceived Learning (Q4):
A20: Q4 has the lowest mean and the lowest top-2-box agreement, and the widest spread of opinion (highest disagreement), suggesting students are least convinced they learn as much online as they would in a face-to-face classroom. This is the item most worth addressing.
A22: Engagement (Q3) is moderate:
A23: Responses to Q3 are more spread across the scale than Q2 or Q5, suggesting engagement is inconsistent across students rather than uniformly high or low — a candidate for follow-up questions on what drives engagement (e.g., discussion format, instructor presence).
A25: Overall satisfaction and advocacy track together:
A26: Q1 (overall experience) and Q5 (would recommend) show similar, fairly strong agreement levels, suggesting overall satisfaction is closely tied to willingness to recommend the format to peers.
A28: Data quality:
A29: Only 2 of 225 total responses (45 respondents x 5 items) were missing, both handled via pairwise deletion as documented on the Data Cleaning sheet; this had negligible effect on the results.
A31: Recommendations
... A34: • Target engagement strategies (Q3) at students in the 'neither agree nor disagree' band, since this group is likely persuadable with small interventions (e.g., more interactive activities).
