Workbook

Sheet Sheet1
A1: city | B1: year | C1: wage | D1: unemployment | E1: population | F1: low_skill_share | G1: manuf_share
A2: Miami | B2: 1975 | C2: 390 | D2: 6.5 | E2: 1.8 | F2: 0.42 | G2: 0.18
A3: Miami | B3: 1976 | C3: 395 | D3: 6.2 | E3: 1.85 | F3: 0.41 | G3: 0.17
A4: Miami | B4: 1977 | C4: 398 | D4: 6 | E4: 1.9 | F4: 0.41 | G4: 0.17
A5: Miami | B5: 1978 | C5: 402 | D5: 5.8 | E5: 1.95 | F5: 0.4 | G5: 0.16
A6: Miami | B6: 1979 | C6: 405 | D6: 5.6 | E6: 2 | F6: 0.4 | G6: 0.16
A7: Miami | B7: 1980 | C7: 400 | D7: 7.5 | E7: 2.1 | F7: 0.43 | G7: 0.15
A8: Miami | B8: 1981 | C8: 392 | D8: 8 | E8: 2.2 | F8: 0.44 | G8: 0.14
A9: Miami | B9: 1982 | C9: 385 | D9: 8.5 | E9: 2.3 | F9: 0.45 | G9: 0.13
A10: Miami | B10: 1983 | C10: 388 | D10: 8.2 | E10: 2.35 | F10: 0.45 | G10: 0.13
A11: Miami | B11: 1984 | C11: 390 | D11: 7.8 | E11: 2.4 | F11: 0.44 | G11: 0.13
A13: Atlanta | B13: 1975 | C13: 380 | D13: 6 | E13: 2.5 | F13: 0.4 | G13: 0.2
A14: Atlanta | B14: 1976 | C14: 385 | D14: 5.8 | E14: 2.55 | F14: 0.4 | G14: 0.19
... A66: LosAngeles | B66: 1984 | C66: 455 | D66: 8 | E66: 6.4 | F66: 0.43 | G66: 0.17

Sheet Q1
A1: City | B1: Avg Wage Trend (Slope) | C1: Avg Unemployment | D1: Avg Population | E1: Avg Low Skill Share | F1: Avg Manuf Share
A2: Miami | B2: =SLOPE(Sheet1!C2:C11,Sheet1!B2:B11) -> -0.9030303 | C2: =AVERAGE(Sheet1!D2:D11) -> 7.01 | D2: =AVERAGE(Sheet1!E2:E11) -> 2.085 | E2: =AVERAGE(Sheet1!F2:F11) -> 0.425 | F2: =AVERAGE(Sheet1!G2:G11) -> 0.152
A3: Atlanta | B3: =SLOPE(Sheet1!C13:C22,Sheet1!B13:B22) -> 3.5575758 | C3: =AVERAGE(Sheet1!D13:D22) -> 6.34 | D3: =AVERAGE(Sheet1!E13:E22) -> 2.725 | E3: =AVERAGE(Sheet1!F13:F22) -> 0.394 | F3: =AVERAGE(Sheet1!G13:G22) -> 0.176
A4: Houston | B4: =SLOPE(Sheet1!C24:C33,Sheet1!B24:B33) -> 4.2909091 | C4: =AVERAGE(Sheet1!D24:D33) -> 6 | D4: =AVERAGE(Sheet1!E24:E33) -> 3.25 | E4: =AVERAGE(Sheet1!F24:F33) -> 0.404 | F4: =AVERAGE(Sheet1!G24:G33) -> 0.226
A5: Tampa | B5: =SLOPE(Sheet1!C35:C44,Sheet1!B35:B44) -> 2.630303 | C5: =AVERAGE(Sheet1!D35:D44) -> 6.71 | D5: =AVERAGE(Sheet1!E35:E44) -> 1.725 | E5: =AVERAGE(Sheet1!F35:F44) -> 0.414 | F5: =AVERAGE(Sheet1!G35:G44) -> 0.166
A6: Dallas | B6: =SLOPE(Sheet1!C46:C55,Sheet1!B46:B55) -> 3.2242424 | C6: =AVERAGE(Sheet1!D46:D55) -> 6.15 | D6: =AVERAGE(Sheet1!E46:E55) -> 3.05 | E6: =AVERAGE(Sheet1!F46:F55) -> 0.384 | F6: =AVERAGE(Sheet1!G46:G55) -> 0.206
A7: LosAngeles | B7: =SLOPE(Sheet1!C57:C66,Sheet1!B57:B66) -> 3.9272727 | C7: =AVERAGE(Sheet1!D57:D66) -> 7.3 | D7: =AVERAGE(Sheet1!E57:E66) -> 5.95 | E7: =AVERAGE(Sheet1!F57:F66) -> 0.424 | F7: =AVERAGE(Sheet1!G57:G66) -> 0.188

Sheet Q2
A1: city | B1: year | C1: wage | D1: unemployment | E1: population | F1: low_skill_share | G1: manuf_share
A2: Miami | B2: 1975 | C2: 390 | D2: 6.5 | E2: 1.8 | F2: 0.42 | G2: 0.18
A3: Miami | B3: 1976 | C3: 395 | D3: 6.2 | E3: 1.85 | F3: 0.41 | G3: 0.17
A4: Miami | B4: 1977 | C4: 398 | D4: 6 | E4: 1.9 | F4: 0.41 | G4: 0.17
A5: Miami | B5: 1978 | C5: 402 | D5: 5.8 | E5: 1.95 | F5: 0.4 | G5: 0.16
A6: Miami | B6: 1979 | C6: 405 | D6: 5.6 | E6: 2 | F6: 0.4 | G6: 0.16
A7: Miami | B7: 1980 | C7: 400 | D7: 7.5 | E7: 2.1 | F7: 0.43 | G7: 0.15
A8: Miami | B8: 1981 | C8: 392 | D8: 8 | E8: 2.2 | F8: 0.44 | G8: 0.14
A9: Miami | B9: 1982 | C9: 385 | D9: 8.5 | E9: 2.3 | F9: 0.45 | G9: 0.13
A10: Miami | B10: 1983 | C10: 388 | D10: 8.2 | E10: 2.35 | F10: 0.45 | G10: 0.13
A11: Miami | B11: 1984 | C11: 390 | D11: 7.8 | E11: 2.4 | F11: 0.44 | G11: 0.13
A12: Atlanta | B12: 1975 | C12: 380 | D12: 6 | E12: 2.5 | F12: 0.4 | G12: 0.2
A13: Atlanta | B13: 1976 | C13: 385 | D13: 5.8 | E13: 2.55 | F13: 0.4 | G13: 0.19
... A61: LosAngeles | B61: 1984 | C61: 455 | D61: 8 | E61: 6.4 | F61: 0.43 | G61: 0.17
A63: Year | B63: Miami | C63: Atlanta | D63: Houston | E63: Tampa | F63: Dallas | G63: LosAngeles
A64: 1975 | B64: =SUMIFS($C$2:$C$61, $A$2:$A$61,B63, $B$2:$B$61,$A$64) -> 390 | C64: =SUMIFS($C$2:$C$61, $A$2:$A$61,C63, $B$2:$B$61,$A$64) -> 380 | D64: =SUMIFS($C$2:$C$61, $A$2:$A$61,D63, $B$2:$B$61,$A$64) -> 395 | E64: =SUMIFS($C$2:$C$61, $A$2:$A$61,E63, $B$2:$B$61,$A$64) -> 385 | F64: =SUMIFS($C$2:$C$61, $A$2:$A$61,F63, $B$2:$B$61,$A$64) -> 400 | G64: =SUMIFS($C$2:$C$61, $A$2:$A$61,G63, $B$2:$B$61,$A$64) -> 420
A65: 1976 | B65: =SUMIFS($C$2:$C$61, $A$2:$A$61,B63, $B$2:$B$61,$A$65) -> 395 | C65: =SUMIFS($C$2:$C$61, $A$2:$A$61,C63, $B$2:$B$61,$A$65) -> 385 | D65: =SUMIFS($C$2:$C$61, $A$2:$A$61,D63, $B$2:$B$61,$A$65) -> 400 | E65: =SUMIFS($C$2:$C$61, $A$2:$A$61,E63, $B$2:$B$61,$A$65) -> 390 | F65: =SUMIFS($C$2:$C$61, $A$2:$A$61,F63, $B$2:$B$61,$A$65) -> 405 | G65: =SUMIFS($C$2:$C$61, $A$2:$A$61,G63, $B$2:$B$61,$A$65) -> 425
A66: 1977 | B66: =SUMIFS($C$2:$C$61, $A$2:$A$61,B63, $B$2:$B$61,$A$66) -> 398 | C66: =SUMIFS($C$2:$C$61, $A$2:$A$61,C63, $B$2:$B$61,$A$66) -> 390 | D66: =SUMIFS($C$2:$C$61, $A$2:$A$61,D63, $B$2:$B$61,$A$66) -> 405 | E66: =SUMIFS($C$2:$C$61, $A$2:$A$61,E63, $B$2:$B$61,$A$66) -> 395 | F66: =SUMIFS($C$2:$C$61, $A$2:$A$61,F63, $B$2:$B$61,$A$66) -> 410 | G66: =SUMIFS($C$2:$C$61, $A$2:$A$61,G63, $B$2:$B$61,$A$66) -> 430
A67: 1978 | B67: =SUMIFS($C$2:$C$61, $A$2:$A$61,B63, $B$2:$B$61,$A$67) -> 402 | C67: =SUMIFS($C$2:$C$61, $A$2:$A$61,C63, $B$2:$B$61,$A$67) -> 395 | D67: =SUMIFS($C$2:$C$61, $A$2:$A$61,D63, $B$2:$B$61,$A$67) -> 410 | E67: =SUMIFS($C$2:$C$61, $A$2:$A$61,E63, $B$2:$B$61,$A$67) -> 398 | F67: =SUMIFS($C$2:$C$61, $A$2:$A$61,F63, $B$2:$B$61,$A$67) -> 415 | G67: =SUMIFS($C$2:$C$61, $A$2:$A$61,G63, $B$2:$B$61,$A$67) -> 435
A68: 1979 | B68: =SUMIFS($C$2:$C$61, $A$2:$A$61,B63, $B$2:$B$61,$A$68) -> 405 | C68: =SUMIFS($C$2:$C$61, $A$2:$A$61,C63, $B$2:$B$61,$A$68) -> 398 | D68: =SUMIFS($C$2:$C$61, $A$2:$A$61,D63, $B$2:$B$61,$A$68) -> 415 | E68: =SUMIFS($C$2:$C$61, $A$2:$A$61,E63, $B$2:$B$61,$A$68) -> 400 | F68: =SUMIFS($C$2:$C$61, $A$2:$A$61,F63, $B$2:$B$61,$A$68) -> 418 | G68: =SUMIFS($C$2:$C$61, $A$2:$A$61,G63, $B$2:$B$61,$A$68) -> 440
A69: 1980 | B69: =SUMIFS($C$2:$C$61, $A$2:$A$61,B63, $B$2:$B$61,$A$69) -> 400 | C69: =SUMIFS($C$2:$C$61, $A$2:$A$61,C63, $B$2:$B$61,$A$69) -> 402 | D69: =SUMIFS($C$2:$C$61, $A$2:$A$61,D63, $B$2:$B$61,$A$69) -> 420 | E69: =SUMIFS($C$2:$C$61, $A$2:$A$61,E63, $B$2:$B$61,$A$69) -> 402 | F69: =SUMIFS($C$2:$C$61, $A$2:$A$61,F63, $B$2:$B$61,$A$69) -> 420 | G69: =SUMIFS($C$2:$C$61, $A$2:$A$61,G63, $B$2:$B$61,$A$69) -> 445
A70: 1981 | B70: =SUMIFS($C$2:$C$61, $A$2:$A$61,B63, $B$2:$B$61,$A$70) -> 392 | C70: =SUMIFS($C$2:$C$61, $A$2:$A$61,C63, $B$2:$B$61,$A$70) -> 405 | D70: =SUMIFS($C$2:$C$61, $A$2:$A$61,D63, $B$2:$B$61,$A$70) -> 425 | E70: =SUMIFS($C$2:$C$61, $A$2:$A$61,E63, $B$2:$B$61,$A$70) -> 405 | F70: =SUMIFS($C$2:$C$61, $A$2:$A$61,F63, $B$2:$B$61,$A$70) -> 423 | G70: =SUMIFS($C$2:$C$61, $A$2:$A$61,G63, $B$2:$B$61,$A$70) -> 448
A71: 1982 | B71: =SUMIFS($C$2:$C$61, $A$2:$A$61,B63, $B$2:$B$61,$A$71) -> 385 | C71: =SUMIFS($C$2:$C$61, $A$2:$A$61,C63, $B$2:$B$61,$A$71) -> 408 | D71: =SUMIFS($C$2:$C$61, $A$2:$A$61,D63, $B$2:$B$61,$A$71) -> 428 | E71: =SUMIFS($C$2:$C$61, $A$2:$A$61,E63, $B$2:$B$61,$A$71) -> 407 | F71: =SUMIFS($C$2:$C$61, $A$2:$A$61,F63, $B$2:$B$61,$A$71) -> 425 | G71: =SUMIFS($C$2:$C$61, $A$2:$A$61,G63, $B$2:$B$61,$A$71) -> 450
A72: 1983 | B72: =SUMIFS($C$2:$C$61, $A$2:$A$61,B63, $B$2:$B$61,$A$72) -> 388 | C72: =SUMIFS($C$2:$C$61, $A$2:$A$61,C63, $B$2:$B$61,$A$72) -> 410 | D72: =SUMIFS($C$2:$C$61, $A$2:$A$61,D63, $B$2:$B$61,$A$72) -> 430 | E72: =SUMIFS($C$2:$C$61, $A$2:$A$61,E63, $B$2:$B$61,$A$72) -> 408 | F72: =SUMIFS($C$2:$C$61, $A$2:$A$61,F63, $B$2:$B$61,$A$72) -> 428 | G72: =SUMIFS($C$2:$C$61, $A$2:$A$61,G63, $B$2:$B$61,$A$72) -> 452
A73: 1984 | B73: =SUMIFS($C$2:$C$61, $A$2:$A$61,B63, $B$2:$B$61,$A$73) -> 390 | C73: =SUMIFS($C$2:$C$61, $A$2:$A$61,C63, $B$2:$B$61,$A$73) -> 412 | D73: =SUMIFS($C$2:$C$61, $A$2:$A$61,D63, $B$2:$B$61,$A$73) -> 432 | E73: =SUMIFS($C$2:$C$61, $A$2:$A$61,E63, $B$2:$B$61,$A$73) -> 410 | F73: =SUMIFS($C$2:$C$61, $A$2:$A$61,F63, $B$2:$B$61,$A$73) -> 430 | G73: =SUMIFS($C$2:$C$61, $A$2:$A$61,G63, $B$2:$B$61,$A$73) -> 455

Sheet Q3
A1: city | B1: year | C1: wage | D1: unemployment | E1: population | F1: low_skill_share | G1: manuf_share
A2: Miami | B2: 1975 | C2: 390 | D2: 6.5 | E2: 1.8 | F2: 0.42 | G2: 0.18
A3: Miami | B3: 1976 | C3: 395 | D3: 6.2 | E3: 1.85 | F3: 0.41 | G3: 0.17
A4: Miami | B4: 1977 | C4: 398 | D4: 6 | E4: 1.9 | F4: 0.41 | G4: 0.17
A5: Miami | B5: 1978 | C5: 402 | D5: 5.8 | E5: 1.95 | F5: 0.4 | G5: 0.16
A6: Miami | B6: 1979 | C6: 405 | D6: 5.6 | E6: 2 | F6: 0.4 | G6: 0.16
A7: Miami | B7: 1980 | C7: 400 | D7: 7.5 | E7: 2.1 | F7: 0.43 | G7: 0.15
A8: Miami | B8: 1981 | C8: 392 | D8: 8 | E8: 2.2 | F8: 0.44 | G8: 0.14
A9: Miami | B9: 1982 | C9: 385 | D9: 8.5 | E9: 2.3 | F9: 0.45 | G9: 0.13
A10: Miami | B10: 1983 | C10: 388 | D10: 8.2 | E10: 2.35 | F10: 0.45 | G10: 0.13
A11: Miami | B11: 1984 | C11: 390 | D11: 7.8 | E11: 2.4 | F11: 0.44 | G11: 0.13
A12: Atlanta | B12: 1975 | C12: 380 | D12: 6 | E12: 2.5 | F12: 0.4 | G12: 0.2
A13: Atlanta | B13: 1976 | C13: 385 | D13: 5.8 | E13: 2.55 | F13: 0.4 | G13: 0.19
... A61: LosAngeles | B61: 1984 | C61: 455 | D61: 8 | E61: 6.4 | F61: 0.43 | G61: 0.17
A63: Donor | B63: Atlanta | C63: Houston | D63: Tampa | E63: Dallas | F63: LosAngeles
A64: Weight | B64: 0 | C64: 0 | D64: 0.87913907 | E64: 0 | F64: 0.12086093
A66: Sum of Weights | B66: =SUM(B64:F64) -> 1
A67: Miami Predictor Averages (Pre-Treatment: 1975–1979)
A68: Miami Predictors (1975-79)
A69: Unemployment | B69: =AVERAGE(D2:D6) -> 6.02
A70: Population | B70: =AVERAGE(E2:E6) -> 1.9
A71: Low Skill Share | B71: =AVERAGE(F2:F6) -> 0.408
A72: Manuf Share | B72: =AVERAGE(G2:G6) -> 0.168
A73: Donor Predictor Averages (Pre-Treatment: 1975–1979)
A74: Donor Predictors | B74: Atlanta | C74: Houston | D74: Tampa | E74: Dallas | F74: LosAngeles
A75: Unemployment | B75: =AVERAGE(D12:D16) -> 5.6 | C75: =AVERAGE(D22:D26) -> 5.16 | D75: =AVERAGE(D32:D36) -> 5.84 | E75: =AVERAGE(D42:D46) -> 5.36 | F75: =AVERAGE(D52:D56) -> 6.4
A76: Population | B76: =AVERAGE(E12:E16) -> 2.6 | C76: =AVERAGE(E22:E26) -> 3.1 | D76: =AVERAGE(E32:E36) -> 1.6 | E76: =AVERAGE(E42:E46) -> 2.9 | F76: =AVERAGE(E52:E56) -> 5.7
A77: Low Skill Share | B77: =AVERAGE(F12:F16) -> 0.392 | C77: =AVERAGE(F22:F26) -> 0.402 | D77: =AVERAGE(F32:F36) -> 0.412 | E77: =AVERAGE(F42:F46) -> 0.382 | F77: =AVERAGE(F52:F56) -> 0.422
A78: Manuf Share | B78: =AVERAGE(G12:G16) -> 0.188 | C78: =AVERAGE(G22:G26) -> 0.238 | D78: =AVERAGE(G32:G36) -> 0.178 | E78: =AVERAGE(G42:G46) -> 0.218 | F78: =AVERAGE(G52:G56) -> 0.202
A79: Synthetic Miami Predictors (Weighted Averages)
A80: Synthetic Miami Predictors
A81: Unemployment | B81: =SUMPRODUCT($B$64:$F$64, B75:F75) -> 5.9076821
A82: Population | B82: =SUMPRODUCT($B$64:$F$64, B76:F76) -> 2.0955298
A83: Low Skill Share | B83: =SUMPRODUCT($B$64:$F$64, B77:F77) -> 0.41320861
A84: Manuf Share | B84: =SUMPRODUCT($B$64:$F$64, B78:F78) -> 0.18090066
A85: Predictor Fit (Squared Differences)
A86: Predictor Fit
A87: Unemployment Diff² | B87: =(B69-B81)^2 -> 0.012615306
A88: Population Diff² | B88: =(B70-B82)^2 -> 0.038231906
A89: Low Skill Share Diff² | B89: =(B71-B83)^2 -> 2.7129611e-05
...

Sheet Q4
A1: Year | B1: Miami Wage | C1: Synthetic Wage | D1: Squared Diff
A2: 1980 | B2: ='Q3'!B112 -> 400 | C2: ='Q3'!C112 -> 407.19702 | D2: ='Q3'!D112 -> 51.797096
A3: 1981 | B3: ='Q3'!B113 -> 392 | C3: ='Q3'!C113 -> 410.19702 | D3: ='Q3'!D113 -> 331.13153
A4: 1982 | B4: ='Q3'!B114 -> 385 | C4: ='Q3'!C114 -> 412.19702 | D4: ='Q3'!D114 -> 739.67789
A5: 1983 | B5: ='Q3'!B115 -> 388 | C5: ='Q3'!C115 -> 413.31788 | D5: ='Q3'!D115 -> 640.99509
A6: 1984 | B6: ='Q3'!B116 -> 390 | C6: ='Q3'!C116 -> 415.43874 | D6: ='Q3'!D116 -> 647.12958

Sheet Q5
A1: Year | B1: Miami Wage | C1: Houston Wage | D1: Difference
A2: 1980 | B2: ='Q3'!B112 -> 400 | C2: ='Q3'!C99 -> 420 | D2: =B2-C2 -> -20
A3: 1981 | B3: ='Q3'!B113 -> 392 | C3: ='Q3'!C100 -> 425 | D3: =B3-C3 -> -33
A4: 1982 | B4: ='Q3'!B114 -> 385 | C4: ='Q3'!C101 -> 428 | D4: =B4-C4 -> -43
A5: 1983 | B5: ='Q3'!B115 -> 388 | C5: ='Q3'!C102 -> 430 | D5: =B5-C5 -> -42
A6: 1984 | B6: ='Q3'!B116 -> 390 | C6: ='Q3'!C103 -> 432 | D6: =B6-C6 -> -42

Sheet Q7
A1: Donor | B1: Atlanta | C1: Houston | D1: Dallas | E1: LosAngeles
A2: Weight | B2: 0.7910706 | C2: 0 | D2: 0 | E2: 0.2089294
A4: Sum of weights | B4: =SUM(B2:E2) -> 1
A6: Miami Predictors (1975-79)
A7: Unemployment | B7: ='Q1'!C2 -> 7.01
A8: Population | B8: ='Q1'!D2 -> 2.085
A9: Low Skill Share | B9: ='Q1'!E2 -> 0.425
A10: Manuf Share | B10: ='Q1'!F2 -> 0.152
A12: Donor Predictor Averages
A13: Donor Predictors | B13: Atlanta | C13: Houston | D13: Dallas | E13: LosAngeles
A14: Unemployment | B14: ='Q1'!C3 -> 6.34 | C14: ='Q1'!C4 -> 6 | D14: ='Q1'!C6 -> 6.15 | E14: ='Q1'!C7 -> 7.3
A15: Population | B15: ='Q1'!D3 -> 2.725 | C15: ='Q1'!D4 -> 3.25 | D15: ='Q1'!D6 -> 3.05 | E15: ='Q1'!D7 -> 5.95
A16: Low Skill Share | B16: ='Q1'!E3 -> 0.394 | C16: ='Q1'!E4 -> 0.404 | D16: ='Q1'!E6 -> 0.384 | E16: ='Q1'!E7 -> 0.424
A17: Manuf Share | B17: ='Q1'!F3 -> 0.176 | C17: ='Q1'!F4 -> 0.226 | D17: ='Q1'!F6 -> 0.206 | E17: ='Q1'!F7 -> 0.188
A19: Synthetic Miami Predictors
A20: Unemployment | B20: =SUMPRODUCT($B$2:$E$2, B14:E14) -> 6.5405722
A21: Population | B21: =SUMPRODUCT($B$2:$E$2, B15:E15) -> 3.3987973
A22: Low Skill Share | B22: =SUMPRODUCT($B$2:$E$2, B16:E16) -> 0.40026788
A23: Manuf Share | B23: =SUMPRODUCT($B$2:$E$2, B17:E17) -> 0.17850715
A26: Predictor Fit
A27: Unemployment Diff² | B27: =(B7-B21)^2 -> 13.040785
A28: Population Diff² | B28: =(B8-B22)^2 -> 2.8383223
A29: Low Skill Share Diff² | B29: =(B9-B23)^2 -> 0.060758724
A30: Manuf Share Diff² | B30: =(B10-B26)^2 -> 0.023104
A31: Sum of Squared Diffs | B31: =SUM(B27:B30) -> 15.96297
A33: Donor Wages Helper Table
A34: Year | B34: Atlanta | C34: Houston | D34: Dallas | E34: LosAngeles
A35: 1975 | B35: 380 | C35: 395 | D35: 400 | E35: 420
A36: 1976 | B36: 385 | C36: 400 | D36: 405 | E36: 425
A37: 1977 | B37: 390 | C37: 405 | D37: 410 | E37: 430
A38: 1978 | B38: 395 | C38: 410 | D38: 415 | E38: 435
A39: 1979 | B39: 398 | C39: 415 | D39: 418 | E39: 440
A40: 1980 | B40: 402 | C40: 420 | D40: 420 | E40: 445
A41: 1981 | B41: 405 | C41: 425 | D41: 423 | E41: 448
A42: 1982 | B42: 408 | C42: 428 | D42: 425 | E42: 450
A43: 1983 | B43: 410 | C43: 430 | D43: 428 | E43: 452
A44: 1984 | B44: 412 | C44: 432 | D44: 430 | E44: 455
A46: Wage Paths and Fit
A47: Year | B47: Miami Wage | C47: Synthetic Wage | D47: Squared Diff
A48: 1975 | B48: 390 | C48: =SUMPRODUCT($B$2:$E$2, B35:E35) -> 388.35718 | D48: =(B48-C48)^2 -> 2.6988702
...
